Workbook

Sheet Sheet1
D2: 2023 | H2: 2024 | L2: 2025 | P2: 2026 | T2: 2027
B3: Advertising Sales | D3: Q1 | E3: Q2 | F3: Q3 | G3: Q4 | H3: Q1 | I3: Q2 | J3: Q3 | K3: Q4 | L3: Q1 | M3: Q2 | N3: Q3 | O3: Q4 | P3: Q1 | Q3: Q2E | R3: Q3E | S3: Q4E | T3: Q1E | U3: Q2E | V3: Q3E | W3: Q4E
B4: Google | D4: 54548 | E4: 58143 | F4: 59647 | G4: 65517 | H4: 61659 | I4: 64616 | J4: 65854 | K4: 72461 | L4: 66885 | M4: 71340 | N4: 74182 | O4: 82284 | P4: 77253 | Q4: 81152 | R4: 83423 | S4: 91876 | T4: 87149 | U4: 90982 | V4: 92946 | W4: 99046
B5: % growth | H5: =(H4-D4)/D4 -> 0.13036225 | I5: =(I4-E4)/E4 -> 0.11132896 | J5: =(J4-F4)/F4 -> 0.10406223 | K5: =(K4-G4)/G4 -> 0.10598776 | L5: =(L4-H4)/H4 -> 0.084756483 | M5: =(M4-I4)/I4 -> 0.10406091 | N5: =(N4-J4)/J4 -> 0.12646157 | O5: =(O4-K4)/K4 -> 0.13556258 | ... W5: =(W4-S4)/S4 -> 0.078039967
B6: % of total | D6: =D4/D$22 -> 0.59189653 | E6: =E4/E$22 -> 0.57955225 | F6: =F4/F$22 -> 0.5661794 | G6: =G4/G$22 -> 0.55113268 | H6: =H4/H$22 -> 0.56506717 | I6: =I4/I$22 -> 0.5584016 | J6: =J4/J$22 -> 0.5484634 | K6: =K4/K$22 -> 0.5307254 | ... W6: =W4/W$22 -> 0.46534114
B9: Meta | D9: 28101 | E9: 31498 | F9: 33643 | G9: 38706 | H9: 35635 | I9: 38329 | J9: 39885 | K9: 46783 | L9: 41392 | M9: 46563 | N9: 50082 | O9: 58137 | P9: 55024 | Q9: 58884 | R9: 61577 | S9: 70913 | T9: 65449 | U9: 69629 | V9: 72291 | W9: 83809
B10: % growth | H10: =(H9-D9)/D9 -> 0.26810434 | I10: =(I9-E9)/E9 -> 0.21687091 | J10: =(J9-F9)/F9 -> 0.18553637 | K10: =(K9-G9)/G9 -> 0.20867566 | L10: =(L9-H9)/H9 -> 0.16155465 | M10: =(M9-I9)/I9 -> 0.21482428 | N10: =(N9-J9)/J9 -> 0.25566002 | O10: =(O9-K9)/K9 -> 0.242695 | ... W10: =(W9-S9)/S9 -> 0.18185664
B11: % of total | D11: =D9/D$22 -> 0.30492198 | E11: =E9/E$22 -> 0.31396276 | F11: =F9/F$22 -> 0.31934504 | G11: =G9/G$22 -> 0.32559705 | H11: =H9/H$22 -> 0.32657307 | I11: =I9/I$22 -> 0.33123336 | J11: =J9/J$22 -> 0.33218123 | K11: =K9/K$22 -> 0.34265227 | ... W11: =W9/W$22 -> 0.39375417
B14: Amazon | D14: 9509 | E14: 10683 | F14: 12060 | G14: 14654 | H14: 11824 | I14: 12771 | J14: 14331 | K14: 17288 | L14: 13921 | M14: 15694 | N14: 17703 | O14: 21317 | P14: 17243 | Q14: 19257 | R14: 20934 | S14: 25450 | T14: 20098 | U14: 22870 | V14: 24486 | W14: 29991
B15: % growth | H15: =(H14-D14)/D14 -> 0.24345357 | I15: =(I14-E14)/E14 -> 0.19545072 | J15: =(J14-F14)/F14 -> 0.18830846 | K15: =(K14-G14)/G14 -> 0.17974614 | L15: =(L14-H14)/H14 -> 0.17735115 | M15: =(M14-I14)/I14 -> 0.22887793 | N15: =(N14-J14)/J14 -> 0.23529412 | O15: =(O14-K14)/K14 -> 0.23305183 | ... W15: =(W14-S14)/S14 -> 0.17842829
B16: % of total | D16: =D14/D$22 -> 0.10318149 | E16: =E14/E$22 -> 0.10648499 | F16: =F14/F$22 -> 0.11447556 | G16: =G14/G$22 -> 0.12327027 | H16: =H14/H$22 -> 0.10835976 | I16: =I14/I$22 -> 0.11036503 | J16: =J14/J$22 -> 0.11935538 | K16: =K14/K$22 -> 0.12662233 | ... W16: =W14/W$22 -> 0.14090469
B18: AppLovin | D18: 354.758 | E18: 406.063 | F18: 504.452 | G18: 576.489 | H18: 678.37 | I18: 711.015 | J18: 835.186 | K18: 999.487 | L18: 1158.97 | M18: 1258.8 | N18: 1405 | O18: 1657.9 | P18: 1785.39 | Q18: 1916.26 | R18: 2061.08 | S18: 2321.72 | T18: 2368.9 | U18: 2487.34
B19: % growth | H19: =(H18-D18)/D18 -> 0.91220494 | I19: =(I18-E18)/E18 -> 0.75099677 | J19: =(J18-F18)/F18 -> 0.65563027 | K19: =(K18-G18)/G18 -> 0.73374861 | L19: =(L18-H18)/H18 -> 0.70846293 | M19: =(M18-I18)/I18 -> 0.77042678 | N19: =(N18-J18)/J18 -> 0.68226 | O19: =(O18-K18)/K18 -> 0.65875094 | ... W19: =(W18-S18)/S18 -> -1
B20: % of total | D20: =D18/D$22 -> 0.0038494542 | E20: =E18/E$22 -> 0.004047516 | F20: =F18/F$22 -> 0.0047883436 | G20: =G18/G$22 -> 0.0048494578 | H20: =H18/H$22 -> 0.0062168478 | I20: =I18/I$22 -> 0.006144483 | J20: =J18/J$22 -> 0.0069558258 | K20: =K18/K$22 -> 0.0073205329 | ... W20: =W18/W$22 -> 0
B22: Total | D22: =SUM(D4+D9+D14) -> 92158 | E22: =SUM(E4+E9+E14) -> 100324 | F22: =SUM(F4+F9+F14) -> 105350 | G22: =SUM(G4+G9+G14) -> 118877 | H22: =SUM(H4+H9+H14) -> 109118 | I22: =SUM(I4+I9+I14) -> 115716 | J22: =SUM(J4+J9+J14) -> 120070 | K22: =SUM(K4+K9+K14) -> 136532 | ... W22: =SUM(W4+W9+W14) -> 212846
B23: % growth | H23: =(H22-D22)/D22 -> 0.18403177 | I23: =(I22-E22)/E22 -> 0.15342291 | J23: =(J22-F22)/F22 -> 0.13972473 | K23: =(K22-G22)/G22 -> 0.14851485 | L23: =(L22-H22)/H22 -> 0.11987023 | M23: =(M22-I22)/I22 -> 0.15452487 | N23: =(N22-J22)/J22 -> 0.18236862 | O23: =(O22-K22)/K22 -> 0.18461606 | ... W23: =(W22-S22)/S22 -> 0.13072211
B25: Google/Meta | D25: =D4/D9 -> 1.9411409 | E25: =E4/E9 -> 1.8459267 | F25: =F4/F9 -> 1.7729394 | G25: =G4/G9 -> 1.6926833 | H25: =H4/H9 -> 1.7302933 | I25: =I4/I9 -> 1.6858254 | J25: =J4/J9 -> 1.6510969 | K25: =K4/K9 -> 1.5488746 | ... W25: =W4/W9 -> 1.1818062
B26: Google/Amazon | D26: =D4/D14 -> 5.7364602 | E26: =E4/E14 -> 5.4425723 | F26: =F4/F14 -> 4.9458541 | G26: =G4/G14 -> 4.4709294 | H26: =H4/H14 -> 5.2147327 | I26: =I4/I14 -> 5.0595881 | J26: =J4/J14 -> 4.5952132 | K26: =K4/K14 -> 4.1914044 | ... W26: =W4/W14 -> 3.3025241
B27: Meta/Google | D27: =D9/D4 -> 0.51516096 | E27: =E9/E4 -> 0.54173331 | F27: =F9/F4 -> 0.56403507 | G27: =G9/G4 -> 0.59077797 | H27: =H9/H4 -> 0.57793672 | I27: =I9/I4 -> 0.59318126 | J27: =J9/J4 -> 0.60565797 | K27: =K9/K4 -> 0.64563006 | ... W27: =W9/W4 -> 0.84616239
B28: Meta/Amazon | D28: =D9/D14 -> 2.9552003 | E28: =E9/E14 -> 2.9484227 | F28: =F9/F14 -> 2.7896352 | G28: =G9/G14 -> 2.6413266 | H28: =H9/H14 -> 3.0137855 | I28: =I9/I14 -> 3.0012528 | J28: =J9/J14 -> 2.7831275 | K28: =K9/K14 -> 2.7060967 | ... W28: =W9/W14 -> 2.7944717
B29: Amazon/Google | D29: =D14/D4 -> 0.17432353 | E29: =E14/E4 -> 0.18373665 | F29: =F14/F4 -> 0.20218955 | G29: =G14/G4 -> 0.22366714 | H29: =H14/H4 -> 0.19176438 | I29: =I14/I4 -> 0.19764455 | J29: =J14/J4 -> 0.21761776 | K29: =K14/K4 -> 0.23858351 | ... W29: =W14/W4 -> 0.3027987
B30: Amazon/Meta | D30: =D14/D9 -> 0.33838653 | E30: =E14/E9 -> 0.33916439 | F30: =F14/F9 -> 0.35846982 | G30: =G14/G9 -> 0.37859763 | H30: =H14/H9 -> 0.33180862 | I30: =I14/I9 -> 0.33319419 | J30: =J14/J9 -> 0.35930801 | K30: =K14/K9 -> 0.36953594 | ... W30: =W14/W9 -> 0.3578494

Sheet Ad Sales Charts
X3: Quarterly Sales ($mm)
X4: Metric | Y4: 2023 Q1 | Z4: 2023 Q2 | AA4: 2023 Q3 | AB4: 2023 Q4 | AC4: 2024 Q1 | AD4: 2024 Q2 | AE4: 2024 Q3 | AF4: 2024 Q4 | AG4: 2025 Q1 | AH4: 2025 Q2 | AI4: 2025 Q3 | AJ4: 2025 Q4 | AK4: 2026 Q1
X5: Google | Y5: =Sheet1!D4 -> 54548 | Z5: =Sheet1!E4 -> 58143 | AA5: =Sheet1!F4 -> 59647 | AB5: =Sheet1!G4 -> 65517 | AC5: =Sheet1!H4 -> 61659 | AD5: =Sheet1!I4 -> 64616 | AE5: =Sheet1!J4 -> 65854 | AF5: =Sheet1!K4 -> 72461 | ... AK5: =Sheet1!P4 -> 77253
X6: Meta | Y6: =Sheet1!D9 -> 28101 | Z6: =Sheet1!E9 -> 31498 | AA6: =Sheet1!F9 -> 33643 | AB6: =Sheet1!G9 -> 38706 | AC6: =Sheet1!H9 -> 35635 | AD6: =Sheet1!I9 -> 38329 | AE6: =Sheet1!J9 -> 39885 | AF6: =Sheet1!K9 -> 46783 | ... AK6: =Sheet1!P9 -> 55024
X7: Amazon | Y7: =Sheet1!D14 -> 9509 | Z7: =Sheet1!E14 -> 10683 | AA7: =Sheet1!F14 -> 12060 | AB7: =Sheet1!G14 -> 14654 | AC7: =Sheet1!H14 -> 11824 | AD7: =Sheet1!I14 -> 12771 | AE7: =Sheet1!J14 -> 14331 | AF7: =Sheet1!K14 -> 17288 | ... AK7: =Sheet1!P14 -> 17243
X8: Total | Y8: =Sheet1!D22 -> 92158 | Z8: =Sheet1!E22 -> 100324 | AA8: =Sheet1!F22 -> 105350 | AB8: =Sheet1!G22 -> 118877 | AC8: =Sheet1!H22 -> 109118 | AD8: =Sheet1!I22 -> 115716 | AE8: =Sheet1!J22 -> 120070 | AF8: =Sheet1!K22 -> 136532 | ... AK8: =Sheet1!P22 -> 149520
X10: YoY Growth (%)
X11: Metric | Y11: 2024 Q1 | Z11: 2024 Q2 | AA11: 2024 Q3 | AB11: 2024 Q4 | AC11: 2025 Q1 | AD11: 2025 Q2 | AE11: 2025 Q3 | AF11: 2025 Q4 | AG11: 2026 Q1
X12: Google | Y12: =Sheet1!H5 -> 0.13036225 | Z12: =Sheet1!I5 -> 0.11132896 | AA12: =Sheet1!J5 -> 0.10406223 | AB12: =Sheet1!K5 -> 0.10598776 | AC12: =Sheet1!L5 -> 0.084756483 | AD12: =Sheet1!M5 -> 0.10406091 | AE12: =Sheet1!N5 -> 0.12646157 | AF12: =Sheet1!O5 -> 0.13556258 | AG12: =Sheet1!P5 -> 0.15501233
X13: Meta | Y13: =Sheet1!H10 -> 0.26810434 | Z13: =Sheet1!I10 -> 0.21687091 | AA13: =Sheet1!J10 -> 0.18553637 | AB13: =Sheet1!K10 -> 0.20867566 | AC13: =Sheet1!L10 -> 0.16155465 | AD13: =Sheet1!M10 -> 0.21482428 | AE13: =Sheet1!N10 -> 0.25566002 | AF13: =Sheet1!O10 -> 0.242695 | AG13: =Sheet1!P10 -> 0.329339
X14: Amazon | Y14: =Sheet1!H15 -> 0.24345357 | Z14: =Sheet1!I15 -> 0.19545072 | AA14: =Sheet1!J15 -> 0.18830846 | AB14: =Sheet1!K15 -> 0.17974614 | AC14: =Sheet1!L15 -> 0.17735115 | AD14: =Sheet1!M15 -> 0.22887793 | AE14: =Sheet1!N15 -> 0.23529412 | AF14: =Sheet1!O15 -> 0.23305183 | AG14: =Sheet1!P15 -> 0.23863228
X15: Total | Y15: =Sheet1!H23 -> 0.18403177 | Z15: =Sheet1!I23 -> 0.15342291 | AA15: =Sheet1!J23 -> 0.13972473 | AB15: =Sheet1!K23 -> 0.14851485 | AC15: =Sheet1!L23 -> 0.11987023 | AD15: =Sheet1!M23 -> 0.15452487 | AE15: =Sheet1!N23 -> 0.18236862 | AF15: =Sheet1!O23 -> 0.18461606 | AG15: =Sheet1!P23 -> 0.22358795
X17: % of Total Sales
X18: Metric | Y18: 2023 Q1 | Z18: 2023 Q2 | AA18: 2023 Q3 | AB18: 2023 Q4 | AC18: 2024 Q1 | AD18: 2024 Q2 | AE18: 2024 Q3 | AF18: 2024 Q4 | AG18: 2025 Q1 | AH18: 2025 Q2 | AI18: 2025 Q3 | AJ18: 2025 Q4 | AK18: 2026 Q1
X19: Google | Y19: =Sheet1!D6 -> 0.59189653 | Z19: =Sheet1!E6 -> 0.57955225 | AA19: =Sheet1!F6 -> 0.5661794 | AB19: =Sheet1!G6 -> 0.55113268 | AC19: =Sheet1!H6 -> 0.56506717 | AD19: =Sheet1!I6 -> 0.5584016 | AE19: =Sheet1!J6 -> 0.5484634 | AF19: =Sheet1!K6 -> 0.5307254 | ... AK19: =Sheet1!P6 -> 0.51667335
X20: Meta | Y20: =Sheet1!D11 -> 0.30492198 | Z20: =Sheet1!E11 -> 0.31396276 | AA20: =Sheet1!F11 -> 0.31934504 | AB20: =Sheet1!G11 -> 0.32559705 | AC20: =Sheet1!H11 -> 0.32657307 | AD20: =Sheet1!I11 -> 0.33123336 | AE20: =Sheet1!J11 -> 0.33218123 | AF20: =Sheet1!K11 -> 0.34265227 | ... AK20: =Sheet1!P11 -> 0.36800428
X21: Amazon | Y21: =Sheet1!D16 -> 0.10318149 | Z21: =Sheet1!E16 -> 0.10648499 | AA21: =Sheet1!F16 -> 0.11447556 | AB21: =Sheet1!G16 -> 0.12327027 | AC21: =Sheet1!H16 -> 0.10835976 | AD21: =Sheet1!I16 -> 0.11036503 | AE21: =Sheet1!J16 -> 0.11935538 | AF21: =Sheet1!K16 -> 0.12662233 | ... AK21: =Sheet1!P16 -> 0.11532236
X23: Scale Ratios - Core Peer Set
X24: Metric | Y24: 2023 Q1 | Z24: 2023 Q2 | AA24: 2023 Q3 | AB24: 2023 Q4 | AC24: 2024 Q1 | AD24: 2024 Q2 | AE24: 2024 Q3 | AF24: 2024 Q4 | AG24: 2025 Q1 | AH24: 2025 Q2 | AI24: 2025 Q3 | AJ24: 2025 Q4 | AK24: 2026 Q1
X25: Google/Meta | Y25: =Sheet1!D25 -> 1.9411409 | Z25: =Sheet1!E25 -> 1.8459267 | AA25: =Sheet1!F25 -> 1.7729394 | AB25: =Sheet1!G25 -> 1.6926833 | AC25: =Sheet1!H25 -> 1.7302933 | AD25: =Sheet1!I25 -> 1.6858254 | AE25: =Sheet1!J25 -> 1.6510969 | AF25: =Sheet1!K25 -> 1.5488746 | ... AK25: =Sheet1!P25 -> 1.4039874
X26: Google/Amazon | Y26: =Sheet1!D26 -> 5.7364602 | Z26: =Sheet1!E26 -> 5.4425723 | AA26: =Sheet1!F26 -> 4.9458541 | AB26: =Sheet1!G26 -> 4.4709294 | AC26: =Sheet1!H26 -> 5.2147327 | AD26: =Sheet1!I26 -> 5.0595881 | AE26: =Sheet1!J26 -> 4.5952132 | AF26: =Sheet1!K26 -> 4.1914044 | ... AK26: =Sheet1!P26 -> 4.4802529
X27: Meta/Amazon | Y27: =Sheet1!D28 -> 2.9552003 | Z27: =Sheet1!E28 -> 2.9484227 | AA27: =Sheet1!F28 -> 2.7896352 | AB27: =Sheet1!G28 -> 2.6413266 | AC27: =Sheet1!H28 -> 3.0137855 | AD27: =Sheet1!I28 -> 3.0012528 | AE27: =Sheet1!J28 -> 2.7831275 | AF27: =Sheet1!K28 -> 2.7060967 | ... AK27: =Sheet1!P28 -> 3.191092
X29: Scale Ratios - Amazon Relative Scale
X30: Metric | Y30: 2023 Q1 | Z30: 2023 Q2 | AA30: 2023 Q3 | AB30: 2023 Q4 | AC30: 2024 Q1 | AD30: 2024 Q2 | AE30: 2024 Q3 | AF30: 2024 Q4 | AG30: 2025 Q1 | AH30: 2025 Q2 | AI30: 2025 Q3 | AJ30: 2025 Q4 | AK30: 2026 Q1
X31: Amazon/Google | Y31: =Sheet1!D29 -> 0.17432353 | Z31: =Sheet1!E29 -> 0.18373665 | AA31: =Sheet1!F29 -> 0.20218955 | AB31: =Sheet1!G29 -> 0.22366714 | AC31: =Sheet1!H29 -> 0.19176438 | AD31: =Sheet1!I29 -> 0.19764455 | AE31: =Sheet1!J29 -> 0.21761776 | AF31: =Sheet1!K29 -> 0.23858351 | ... AK31: =Sheet1!P29 -> 0.22320169
X32: Amazon/Meta | Y32: =Sheet1!D30 -> 0.33838653 | Z32: =Sheet1!E30 -> 0.33916439 | AA32: =Sheet1!F30 -> 0.35846982 | AB32: =Sheet1!G30 -> 0.37859763 | AC32: =Sheet1!H30 -> 0.33180862 | AD32: =Sheet1!I30 -> 0.33319419 | AE32: =Sheet1!J30 -> 0.35930801 | AF32: =Sheet1!K30 -> 0.36953594 | ... AK32: =Sheet1!P30 -> 0.31337235
X33: Meta/Google | Y33: =Sheet1!D27 -> 0.51516096 | Z33: =Sheet1!E27 -> 0.54173331 | AA33: =Sheet1!F27 -> 0.56403507 | AB33: =Sheet1!G27 -> 0.59077797 | AC33: =Sheet1!H27 -> 0.57793672 | AD33: =Sheet1!I27 -> 0.59318126 | AE33: =Sheet1!J27 -> 0.60565797 | AF33: =Sheet1!K27 -> 0.64563006 | ... AK33: =Sheet1!P27 -> 0.71225713
X35: Latest Actual Sales (2026 Q1)
X36: Company | Y36: 2026 Q1
X37: Google | Y37: =Sheet1!P4 -> 77253
X38: Meta | Y38: =Sheet1!P9 -> 55024
X39: Amazon | Y39: =Sheet1!P14 -> 17243
X41: Latest % of Total (2026 Q1)
X42: Company | Y42: 2026 Q1
X43: Google | Y43: =Sheet1!P6 -> 0.51667335
X44: Meta | Y44: =Sheet1!P11 -> 0.36800428
X45: Amazon | Y45: =Sheet1!P16 -> 0.11532236
X47: Metric | Y47: Google | Z47: Meta | AA47: Amazon
X48: 2026 Q1 Sales | Y48: =Sheet1!P4 -> 77253 | Z48: =Sheet1!P9 -> 55024 | AA48: =Sheet1!P14 -> 17243
X50: Metric | Y50: Google | Z50: Meta | AA50: Amazon
...
