Workbook

Sheet Main
R2: all values in millions except per share numbers
B4: Company Overview
B6: Price | G6: Key Stats | M6: Valuation | R6: Notes
B7: Ticker | E7: ETN | G7: Employees | I7: 94443 | M7: PV of FCF | P7: =SUM(J91:R91) -> 42995.515 | R7: WACC | U7: 0.0915
B8: Implied Share Price | E8: =P12/P11 -> 334.00838 | G8: Founded | I8: 1911 | M8: Terminal Value | P8: =R86*(1+U8)/(U7-U8) -> 174844.82 | R8: TGR | U8: 0.03
B9: Current Share Price | E9: 351.42 | G9: CEO | I9: Paulo Ruiz | M9: PV of Terminal Value | P9: =P8*R90 -> 83071.294
B10: Implied Upside / (Downside) | G10: Headquarters | I10: Dublin, Ireland | M10: Net Debt | P10: =-328-327+761+8802+568 -> 9476 | R10: WACC
G11: Primary Industry | M11: Shares Outstanding | P11: 390.31 | R11: Market Cap
B12: Last Updated | E12: 46064 | G12: Fiscal Year End | M12: Implied Market Cap | P12: =P7+P9+4300 -> 130366.81 | R12: % of Equity
R13: Cost of Equity | U13: =U14+U15*(U17) -> 0.092542
R14: Risk Free Rate | U14: 0.0428
B15: Key Statistics | E15: 2021 | F15: =E15+1 -> 2022 | G15: =F15+1 -> 2023 | H15: =G15+1 -> 2024 | I15: =H15+1 -> 2025 | J15: 2026E | K15: 2027E | M15: Financial Ratios | R15: Beta | U15: 1.19
M16: PV of FCF | P16: =SUM(J99:N99) -> 0
B17: Stock Price | M17: Market Cap | R17: Market Risk Premium | U17: 0.0418
B18: shares outstanding diluted | M18: Enterprise Value | R18: Debt
M19: P/E (LTM) | P19: =E9/12.06 -> 29.139303 | R19: % of Debt
B20: Market Cap | M20: P/E (NTM) | P20: =E9/13.49 -> 26.050408 | R20: Cost of Debt
B21: Cash | M21: EV/S (LTM) | P21: =E9/(I27/P11) -> 4.9937285 | R21: Tax Rate
B22: Debt | M22: EV/EBIT (LTM) | P22: =E8/(I42/P11) -> 23.660038 | R22: Total
B23: Enterprise Value | R23: WACC
B25: Income Statement | E25: 2021 | F25: =E25+1 -> 2022 | G25: =F25+1 -> 2023 | H25: =G25+1 -> 2024 | I25: =H25+1 -> 2025 | J25: 2026E | K25: 2027E | L25: 2028E | M25: 2029E | N25: 2030E
B27: Revenue | E27: 19628 | F27: 20752 | G27: 23196 | H27: 24878 | I27: 27467 | J27: 30011 | K27: 32665 | L27: 36875 | M27: 39180 | N27: =M27*1.1 -> 43098
B28: % growth
B30: COGS
B31: % of sales | I31: 0.537
B33: Gross Income
B34: % of sales
B36: SG&A
B37: % of sales | I37: 0.134
B39: R&D
B40: % of sales
B42: EBIT | E42: 3706 | F42: 4196 | G42: 3978 | H42: 4870 | I42: 5510 | J42: =Segments!L80 -> 7252.387 | K42: =Segments!M80 -> 8055.5737 | L42: =Segments!N80 -> 8841.7612 | M42: =Segments!O80 -> 9741.8671 | N42: =Segments!P80 -> 10688.807
B43: % of sales
B45: Taxes
B46: Tax rate
B48: Cash Flow Items | E48: 2021 | F48: =E48+1 -> 2022 | G48: =F48+1 -> 2023 | H48: =G48+1 -> 2024 | I48: =H48+1 -> 2025 | J48: 2026E | K48: 2027E | L48: 2028E | M48: 2029E | N48: 2030E
B50: D&A | E50: 929 | F50: 956 | G50: 926 | H50: 924 | I50: 992 | J50: =J27*$I$51 -> 1050.385 | K50: =K27*$I$51 -> 1143.275 | L50: =L27*$I$51 -> 1290.625 | M50: =M27*$I$51 -> 1371.3 | N50: =N27*$I$51 -> 1508.43
B51: % of sales | E51: =E50/E27 -> 0.047330344 | F51: =F50/F27 -> 0.046067849 | G51: =G50/G27 -> 0.039920676 | H51: =H50/H27 -> 0.037141249 | I51: 0.035 | J51: =J50/J27 -> 0.035 | K51: =K50/K27 -> 0.035 | L51: =L50/L27 -> 0.035 | M51: =M50/M27 -> 0.035 | N51: =N50/N27 -> 0.035
B52: % of capex | E52: =E50/E54 -> 1.6156522 | F52: =F50/F54 -> 1.5986622 | G52: =G50/G54 -> 1.2232497 | H52: =H50/H54 -> 1.1435644 | I52: =I50/I54 -> 30523.077 | J52: =J50/J54 -> 1.0769231 | K52: =K50/K54 -> 1.0769231 | L52: =L50/L54 -> 1.0769231 | ... N52: =N50/N54 -> 1.0769231
B54: CapEx | E54: 575 | F54: 598 | G54: 757 | H54: 808 | I54: 0.0325 | J54: =J27*$I$54 -> 975.3575 | K54: =K27*$I$54 -> 1061.6125 | L54: =L27*$I$54 -> 1198.4375 | M54: =M27*$I$54 -> 1273.35 | N54: =N27*$I$54 -> 1400.685
...

Sheet Segments
A4: x | B4: Electrical Americas | G4: 2021 | H4: 2022 | I4: 2023 | J4: 2024 | K4: 2025 | L4: 2026E | M4: 2027E | N4: 2028E | O4: 2029E | P4: 2030E | Q4: Notes
B5: ELECTRICAL AMERICAS
B6: Data Center & Community | G6: =G15*0.45 -> 3258.9 | H6: =H15*0.47 -> 3993.59 | I6: =I15*0.5 -> 5049 | J6: =J15*0.52 -> 5946.72 | K6: =K15*0.55 -> 7347.175 | L6: =K6*1.22 -> 8963.5535 | M6: =L6*1.18 -> 10576.993 | N6: =M6*1.15 -> 12163.542 | O6: =N6*1.12 -> 13623.167 | P6: =O6*1.1 -> 14985.484 | Q6: Data centers, housing starts
B7: % YoY Growth | H7: =(H6-G6)/G6 -> 0.2254411 | I7: =(I6-H6)/H6 -> 0.264276 | J7: =(J6-I6)/I6 -> 0.17780154 | K7: =(K6-J6)/J6 -> 0.23550041 | L7: =(L6-K6)/K6 -> 0.22 | M7: =(M6-L6)/L6 -> 0.18 | N7: =(N6-M6)/M6 -> 0.15 | O7: =(O6-N6)/N6 -> 0.12 | P7: =(P6-O6)/O6 -> 0.1
B9: Utility & Industrial | G9: =G15*0.35 -> 2534.7 | H9: =H15*0.35 -> 2973.95 | I9: =I15*0.35 -> 3534.3 | J9: =J15*0.36 -> 4116.96 | K9: =K15*0.37 -> 4942.645 | L9: =K9*1.11 -> 5486.3359 | M9: =L9*1.1 -> 6034.9695 | N9: =M9*1.108 -> 6686.7463 | O9: =N9*1.07 -> 7154.8185 | P9: =O9*1.06 -> 7584.1076
B10: % YoY Growth | H10: =(H9-G9)/G9 -> 0.17329467 | I10: =(I9-H9)/H9 -> 0.18841944 | J10: =(J9-I9)/I9 -> 0.16485867 | K10: =(K9-J9)/J9 -> 0.20055696 | L10: =(L9-K9)/K9 -> 0.11 | M10: =(M9-L9)/L9 -> 0.1 | N10: =(N9-M9)/M9 -> 0.108 | O10: =(O9-N9)/N9 -> 0.07 | P10: =(P9-O9)/O9 -> 0.06
B12: Residential | G12: =G15*0.2 -> 1448.4 | H12: =H15*0.18 -> 1529.46 | I12: =I15*0.15 -> 1514.7 | J12: =J15*0.12 -> 1372.32 | K12: =K15*0.08 -> 1068.68 | L12: =K12*0.98 -> 1047.3064 | M12: =L12*1.03 -> 1078.7256 | N12: =M12*1.05 -> 1132.6619 | O12: =N12*1.05 -> 1189.295 | P12: =O12*1.05 -> 1248.7597 | Q12: Grid modernization, renewables
B13: % YoY Growth | H13: =(H12-G12)/G12 -> 0.055965203 | I13: =(I12-H12)/H12 -> -0.0096504649 | J13: =(J12-I12)/I12 -> -0.093998812 | K13: =(K12-J12)/J12 -> -0.22126035 | L13: =(L12-K12)/K12 -> -0.02 | M13: =(M12-L12)/L12 -> 0.03 | N13: =(N12-M12)/M12 -> 0.05 | O13: =(O12-N12)/N12 -> 0.05 | P13: =(P12-O12)/O12 -> 0.05
B15: Total Electrical Americas | G15: 7242 | H15: 8497 | I15: 10098 | J15: 11436 | K15: 13358.5 | L15: 15025.9 | M15: 16619.5 | N15: 18145 | O15: =N15*1.085 -> 19687.325 | P15: =O15*1.08 -> 21262.311
B16: % YoY Growth | H16: =(H15-G15)/G15 -> 0.17329467 | I16: =(I15-H15)/H15 -> 0.18841944 | J16: =(J15-I15)/I15 -> 0.13250149 | K16: =(K15-J15)/J15 -> 0.16810948 | L16: =(L15-K15)/K15 -> 0.1248194 | M16: =(M15-L15)/L15 -> 0.10605688 | N16: =(N15-M15)/M15 -> 0.091789765 | O16: =(O15-N15)/N15 -> 0.085 | P16: =(P15-O15)/O15 -> 0.08
B18: Operating Income | G18: 1495 | H18: 1912 | I18: 2676 | J18: 3454 | K18: 3985.89 | L18: 4512.41 | M18: 5088.5 | N18: =N15*0.31 -> 5624.95 | O18: =O15*0.313 -> 6162.1327 | P18: =P15*0.315 -> 6697.628
B19: Operating Margin % | G19: =G18/G15 -> 0.20643469 | H19: =H18/H15 -> 0.2250206 | I19: =I18/I15 -> 0.26500297 | J19: =J18/J15 -> 0.30202868 | K19: =K18/K15 -> 0.29837856 | L19: =L18/L15 -> 0.3003088 | M19: =M18/M15 -> 0.30617648 | N19: =N18/N15 -> 0.31 | ... P19: =P18/P15 -> 0.315
B20: Key Drivers:
B21: • Data center growth rate | G21: - | H21: - | I21: - | J21: - | K21: - | L21: 25-30% | M21: 20-25% | N21: 15-20% | O21: 12-15% | P21: 10-12% | Q21: AI infrastructure demand
B22: • Grid modernization spending | G22: - | H22: - | I22: - | J22: - | K22: - | L22: 15-18% | M22: 12-15% | N22: 10-12% | O22: 8-10% | P22: 7-9% | Q22: IRA/infrastructure bill impact
A23: x | B23: Electrical Global | G23: 2021 | H23: 2022 | I23: 2023 | J23: 2024 | K23: 2025 | L23: 2026E | M23: 2027E | N23: 2028E | O23: 2029E | P23: 2030E
B25: Europe | G25: 2758 | H25: 2924 | I25: 3042 | J25: 3124 | K25: 3390 | L25: =G25*1.058 -> 2917.964 | M25: =L25*1.11 -> 3238.94 | N25: =M25*1.125 -> 3643.8075 | O25: =N25*1.1 -> 4008.1883 | P25: =O25*1.085 -> 4348.8843 | Q25: Electrification trends, EV charging
B26: Asia Pacific | G26: 1379 | H26: 1462 | I26: 1521 | J26: 1562 | K26: 1695 | L26: =G26*1.058 -> 1458.982 | M26: =L26*1.055 -> 1539.226 | N26: =M26*1.08 -> 1662.3641 | O26: =N26*1.115 -> 1853.536 | P26: =O26*1.12 -> 2075.9603 | Q26: China manufacturing, India growth
B27: Rest of World | G27: 1379 | H27: 1462 | I27: 1521 | J27: 1562 | K27: 1695 | L27: =G27*1.058 -> 1458.982 | M27: =L27*1.055 -> 1539.226 | N27: =M27*1.07 -> 1646.9718 | O27: =N27*1.095 -> 1803.4342 | P27: =O27*1.105 -> 1992.7947 | Q27: Emerging markets infrastructure
B28: Total Electrical Global | G28: =SUM(G25:G27) -> 5516 | H28: =SUM(H25:H27) -> 5848 | I28: =SUM(I25:I27) -> 6084 | J28: =SUM(J25:J27) -> 6248 | K28: =SUM(K25:K27) -> 6780 | L28: =SUM(L25:L27) -> 5835.928 | M28: =SUM(M25:M27) -> 6317.3921 | N28: =SUM(N25:N27) -> 6953.1435 | ... P28: =SUM(P25:P27) -> 8417.6393
B29: % YoY Growth | H29: =(H28-G28)/G28 -> 0.060188542 | I29: =(I28-H28)/H28 -> 0.040355677 | J29: =(J28-I28)/I28 -> 0.02695595 | K29: =(K28-J28)/J28 -> 0.085147247 | L29: =(L28-K28)/K28 -> -0.13924366 | M29: =(M28-L28)/L28 -> 0.0825 | N29: =(N28-M28)/M28 -> 0.1006351 | O29: =(O28-N28)/N28 -> 0.10240188 | P29: =(P28-O28)/O28 -> 0.098168996
B31: Operating Income | G31: 1034 | H31: 1134 | I31: 1176 | J31: 1150 | K31: 1318 | L31: =G31*1.08 -> 1116.72 | M31: =L31*1.083 -> 1209.4078 | N31: =M31*1.115 -> 1348.4897 | O31: =N31*1.12 -> 1510.3084 | P31: =O31*1.115 -> 1683.9939
B32: Operating Margin % | G32: =G31/G28 -> 0.18745468 | H32: =H31/H28 -> 0.19391245 | I32: =I31/I28 -> 0.19329389 | J32: =J31/J28 -> 0.1840589 | K32: =K31/K28 -> 0.19439528 | L32: =L31/L28 -> 0.1913526 | M32: =M31/M28 -> 0.19144099 | N32: =N31/N28 -> 0.19393957 | ... P32: =P31/P28 -> 0.20005536
B33: Key Drivers:
B34: • Asia manufacturing PMI | G34: - | H34: - | I34: - | J34: - | K34: - | L34: 52-54 | M34: 53-55 | N34: 54-56 | O34: 55-57 | P34: 56-58 | Q34: Industrial capex recovery
A36: x | B36: Vehicle | G36: 2021 | H36: 2022 | I36: 2023 | J36: 2024 | K36: 2025 | L36: 2026E | M36: 2027E | N36: 2028E | O36: 2029E | P36: 2030E
B37: ELECTRICAL AMERICAS
B38: Light Vehicle | G38: 1547 | H38: 1698 | I38: 1779 | J38: 1674 | K38: 1506 | L38: =G38*0.95 -> 1469.65 | M38: =L38*1.015 -> 1491.6947 | N38: =M38*1.045 -> 1558.821 | O38: =N38*1.065 -> 1660.1444 | P38: =O38*1.065 -> 1768.0538 | Q38: ICE powertrain decline
B39: Commercial Vehicle | G39: 1032 | H39: 1132 | I39: 1186 | J39: 1116 | K39: 1004 | L39: =G39*0.95 -> 980.4 | M39: =L39*1.015 -> 995.106 | N39: =M39*1.045 -> 1039.8858 | O39: =N39*1.065 -> 1107.4783 | P39: =O39*1.065 -> 1179.4644 | Q39: Freight cycle sensitivity
B40: Total Vehicle | G40: =SUM(G38:G39) -> 2579 | H40: =SUM(H38:H39) -> 2830 | I40: =SUM(I38:I39) -> 2965 | J40: =SUM(J38:J39) -> 2790 | K40: =SUM(K38:K39) -> 2510 | L40: =SUM(L38:L39) -> 2450.05 | M40: =SUM(M38:M39) -> 2486.8007 | N40: =SUM(N38:N39) -> 2598.7068 | ... P40: =SUM(P38:P39) -> 2947.5182
B41: % YoY Growth | H41: =(H40-G40)/G40 -> 0.097324544 | I41: =(I40-H40)/H40 -> 0.04770318 | J41: =(J40-I40)/I40 -> -0.059021922 | K41: =(K40-J40)/J40 -> -0.10035842 | L41: =(L40-K40)/K40 -> -0.023884462 | M41: =(M40-L40)/L40 -> 0.015 | N41: =(N40-M40)/M40 -> 0.045 | O41: =(O40-N40)/N40 -> 0.065 | P41: =(P40-O40)/O40 -> 0.065
B43: Operating Income | G43: 449 | H43: 453 | I43: 482 | J43: 503 | K43: 408 | L43: =G43*1.013 -> 454.837 | M43: =L43*1.09 -> 495.77233 | N43: =M43*1.09 -> 540.39184 | O43: =N43*1.117 -> 603.61768 | P43: =O43*1.12 -> 676.05181
B44: Operating Margin % | G44: =G43/G40 -> 0.17409849 | H44: =H43/H40 -> 0.16007067 | I44: =I43/I40 -> 0.16256324 | J44: =J43/J40 -> 0.18028674 | K44: =K43/K40 -> 0.1625498 | L44: =L43/L40 -> 0.18564397 | M44: =M43/M40 -> 0.1993615 | N44: =N43/N40 -> 0.20794645 | ... P44: =P43/P40 -> 0.22936306
B45: Key Drivers:
B46: • ICE penetration decline rate | G46: - | H46: - | I46: - | J46: - | K46: - | L46: 5-7% | M46: 3-5% | N46: 2-4% | O46: 1-3% | P46: 1-3% | Q46: EV transition impact
B47: • Content per vehicle premium | G47: - | H47: - | I47: - | J47: - | K47: - | L47: $180-220 | M47: $200-240 | N47: $220-260 | O47: $240-280 | P47: $260-300 | Q47: Complexity offset to volume
A50: x | B50: E-Mobility | G50: 2021 | H50: 2022 | I50: 2023 | J50: 2024 | K50: 2025 | L50: 2026E | M50: 2027E | N50: 2028E | O50: 2029E | P50: 2030E
B51: ELECTRICAL AMERICAS
B52: EV Powertrain Components | G52: 172 | H52: 269 | I52: 318 | J52: 331 | K52: 314 | L52: =G52*1.075 -> 184.9 | M52: =L52*1.125 -> 208.0125 | N52: =M52*1.19 -> 247.53487 | O52: =N52*1.26 -> 311.89394 | P52: =O52*1.28 -> 399.22425 | Q52: Inverters, motors, breakers
B53: Charging Infrastructure | G53: 171 | H53: 269 | I53: 318 | J53: 331 | K53: 314 | L53: =G53*1.075 -> 183.825 | M53: =L53*1.075 -> 197.61187 | N53: =M53*1.115 -> 220.33724 | O53: =N53*1.145 -> 252.28614 | P53: =O53*1.175 -> 296.43622 | Q53: DC fast charging expansion
...

Sheet Extras
