Workbook

Sheet Main
R2: all values in millions except per share numbers
A4: x | B4: Company Overview
B6: Price | G6: Key Stats | M6: Valuation | R6: Notes | W6: Gordon Growth Method | AA6: Bear Case | AC6: Value | AD6: P/EBIT | AF6: Bull Case | AH6: Value | AI6: P/EBIT
B7: Ticker | E7: FLR | G7: Employees | I7: 22995 | M7: PV of FCF | P7: =SUM(J108:N108) -> 0 | R7: WACC | U7: 0.0875 | W7: FCF Value | Y7: =SUM(J108:N108)+SUM(Y21:AD21) -> 0
B8: Implied Share Price | G8: Founded | M8: Terminal Value | P8: =(N85*U8) -> 0 | R8: EV/EBIT Multiple | U8: 20 | W8: Terminal Value | Y8: =AD21*(1+0.035)/($U$7-0.035) -> 0
B9: Current Share Price | E9: =Extras!H3 -> 52.99 | G9: CEO | I9: James R. Breuer | M9: PV of Terminal Value | P9: =-(PV(U7,4.5,0,P8)) -> 0 | W9: Net Debt | Y9: =P10 -> 0
B10: Implied Upside / (Downside) | E10: =E8/E9-1 -> -1 | G10: Headquarters | I10: 1912 | M10: Net Debt | P10: =J22-J21 -> 0 | R10: WACC | W10: Total | Y10: =Y7+Y8+Y9 -> 0
B11: IRR | E11: =(K17/E9)^(1/2)-1 -> -1 | G11: Primary Industry | I11: Infrastructure Construction | M11: Strategic Investment (OpenAI) | P11: =500000*0.27 -> 135000 | R11: Market Cap | W11: Share Price | Y11: =Y10/P12 -> 0 | AA11: Share Price | AC11: =SUM(AC7:AC10)/$P$12 -> 0 | AD11: =AVERAGE(AD7:AD9) -> #DIV/0! | AF11: Share Price | AH11: =SUM(AH7:AH10)/$P$12 -> 0 | AI11: =AVERAGE(AI7:AI9) -> #DIV/0!
B12: Last Updated | E12: 46147 | G12: Fiscal Year End | I12: 46387 | M12: Shares Outstanding | P12: 160.26 | R12: % of Equity
M13: Implied Market Cap | P13: =P9+P7-P10+P11 -> 135000 | R13: Cost of Equity | U13: =U14+(U15*U17) -> 0 | W13: 10 Year DCF | Y13: 2031 | Z13: =Y13+1 -> 2032 | AA13: =Z13+1 -> 2033 | AB13: =AA13+1 -> 2034 | AC13: =AB13+1 -> 2035 | AD13: =AC13+1 -> 2036 | AG13: Bear | AH13: Base | AI13: Bull
R14: Risk Free Rate | W14: Revenue | Y14: =N82*1.12 -> 0 | Z14: =Y14*1.1 -> 0 | AA14: =Z14*1.08 -> 0 | AB14: =AA14*1.07 -> 0 | AC14: =AB14*1.06 -> 0 | AD14: =AC14*1.05 -> 0 | AF14: Price | AG14: =AC11 -> 0 | AH14: =E8 -> 0 | AI14: =AH11 -> 0
A15: x | B15: Key Statistics | E15: 2021 | F15: =E15+1 -> 2022 | G15: =F15+1 -> 2023 | H15: =G15+1 -> 2024 | I15: =H15+1 -> 2025 | J15: 2026E | K15: 2027E | M15: Financial Ratios | R15: Beta | W15: % growth | Y15: =(Y14-N82)/N82 -> #DIV/0! | Z15: =(Z14-Y14)/Y14 -> #DIV/0! | AA15: =(AA14-Z14)/Z14 -> #DIV/0! | AB15: =(AB14-AA14)/AA14 -> #DIV/0! | AC15: =(AC14-AB14)/AB14 -> #DIV/0! | AD15: =(AD14-AC14)/AC14 -> #DIV/0! | AF15: Chance | AG15: 0.25 | AH15: 0.6 | AI15: 0.15
M16: PV of FCF | P16: =SUM(J109:N109) -> 0
B17: Stock Price | M17: Market Cap | P17: =E9*P12 -> 8492.1774 | R17: Market Risk Premium | AF17: Weighted | AG17: =AG14*AG15 -> 0 | AH17: =AH14*AH15 -> 0 | AI17: =AI14*AI15 -> 0
B18: shares outstanding diluted | M18: Enterprise Value | P18: =P17+P10 -> 8492.1774 | R18: Debt | W18: Free Cash Flow | Y18: =Y14*0.28 -> 0 | Z18: =Z14*0.28 -> 0 | AA18: =AA14*0.28 -> 0 | AB18: =AB14*0.28 -> 0 | AC18: =AC14*0.28 -> 0 | AD18: =AD14*0.28 -> 0
M19: P/E (LTM) | P19: =$P$17/119262 -> 0.071206062 | R19: % of Debt | W19: % of sales | Y19: =Y18/Y14 -> #DIV/0! | Z19: =Z18/Z14 -> #DIV/0! | AA19: =AA18/AA14 -> #DIV/0! | AB19: =AB18/AB14 -> #DIV/0! | AC19: =AC18/AC14 -> #DIV/0! | AD19: =AD18/AD14 -> #DIV/0! | AF19: Total | AG19: =AG17+AH17+AI17 -> 0
B20: Market Cap | M20: P/E (NTM) | P20: =$P$17/129705 -> 0.065473015 | R20: Cost of Debt | AF20: Upside | AG20: =AG19/$E$9-1 -> -1
B21: Cash | M21: P/S (LTM) | P21: =$P$17/305453 -> 0.027801912 | R21: Tax Rate | W21: Present Value of FCF | Y21: =Y18/(1+$U$7)^4.25 -> 0 | Z21: =Z18/(1+$U$7)^4.25 -> 0 | AA21: =AA18/(1+$U$7)^4.25 -> 0 | AB21: =AB18/(1+$U$7)^4.25 -> 0 | AC21: =AC18/(1+$U$7)^4.25 -> 0 | AD21: =AD18/(1+$U$7)^4.25 -> 0
B22: Debt | M22: EV/EBITDA (LTM) | P22: =P18/175259 -> 0.048455015 | R22: Total
B23: Enterprise Value | R23: WACC | U23: =(U12*U13)+(U19*U20*(1-U21)) -> 0
A25: x | B25: Income Statement | E25: 2021 | F25: =E25+1 -> 2022 | G25: =F25+1 -> 2023 | H25: =G25+1 -> 2024 | I25: =H25+1 -> 2025 | J25: 2026E | K25: 2027E | L25: 2028E | M25: 2029E | N25: 2030E
B27: Revenue | E27: =Segments!E6 -> 14156 | F27: =Segments!F6 -> 13744 | G27: =Segments!G6 -> 15474 | H27: =Segments!H6 -> 16315 | I27: =Segments!I6 -> 15503
B28: % growth
B30: COGS
B31: % of sales
B33: Gross Income
B34: % of sales
B36: SG&A
B37: % of sales
B39: R&D
B40: % of sales
B42: EBIT
B43: % of sales
B45: Taxes
... B52: % of sales
A54: x | B54: Cash Flow Items | E54: 2021 | F54: =E54+1 -> 2022 | G54: =F54+1 -> 2023 | H54: =G54+1 -> 2024 | I54: =H54+1 -> 2025 | J54: 2026E | K54: 2027E | L54: 2028E | M54: 2029E | N54: 2030E
B56: D&A
B57: % of sales
B58: % of capex
B60: CapEx
...

Sheet Segments
B2: Product Segments | M2: all values in millions except per share numbers
A4: x | B4: Sales | E4: 2021 | F4: =E4+1 -> 2022 | G4: =F4+1 -> 2023 | H4: =G4+1 -> 2024 | I4: =H4+1 -> 2025 | J4: 2026E | K4: 2027E | L4: 2028E | M4: 2029E | N4: 2030E
B6: Total | E6: =SUM(E9,E13,E17,E21) -> 14156 | F6: 13744 | G6: 15474 | H6: 16315 | I6: 15503 | J6: =SUM(J9,J13,J17,J21) -> 16000.64 | K6: =SUM(K9,K13,K17,K21) -> 17479.271 | L6: =SUM(L9,L13,L17,L21) -> 18926.813
B7: % growth | F7: =(F6-E6)/E6 -> -0.029104267 | G7: =(G6-F6)/F6 -> 0.12587311 | H7: =(H6-G6)/G6 -> 0.054349231 | I7: =(I6-H6)/H6 -> -0.04977015 | J7: =(J6-I6)/I6 -> 0.032099594 | K7: =(K6-J6)/J6 -> 0.092410754 | L7: =(L6-K6)/K6 -> 0.082814794
B9: Energy Solutions | E9: 4956 | F9: 5872 | G9: 6307 | H9: 5976 | I9: 3554 | J9: =I9*0.96 -> 3411.84 | K9: =J9*1.18 -> 4025.9712 | L9: =K9*1.2 -> 4831.1654
B10: % of total | E10: =E9/E$6 -> 0.3500989 | F10: =F9/F$6 -> 0.42724098 | G10: =G9/G$6 -> 0.40758692 | H10: =H9/H$6 -> 0.36628869 | I10: =I9/I$6 -> 0.22924595 | J10: =J9/J$6 -> 0.21323147 | K10: =K9/K$6 -> 0.23032832 | L10: =L9/L$6 -> 0.25525509
B11: % growth | F11: =(F9-E9)/E9 -> 0.18482647 | G11: =(G9-F9)/F9 -> 0.074080381 | H11: =(H9-G9)/G9 -> -0.05248137 | I11: =(I9-H9)/H9 -> -0.40528782 | J11: =(J9-I9)/I9 -> -0.04 | K11: =(K9-J9)/J9 -> 0.18 | L11: =(L9-K9)/K9 -> 0.2
B13: Urban Solutions | E13: 4416 | F13: 3921 | G13: 5262 | H13: 7239 | I13: 9200 | J13: =I13*1.1 -> 10120 | K13: =J13*1.08 -> 10929.6 | L13: =K13*1.05 -> 11476.08
B14: % of total | E14: =E13/E$6 -> 0.31195253 | F14: =F13/F$6 -> 0.28528813 | G14: =G13/G$6 -> 0.34005428 | H14: =H13/H$6 -> 0.44370211 | I14: =I13/I$6 -> 0.59343353 | J14: =J13/J$6 -> 0.6324747 | K14: =K13/K$6 -> 0.62528923 | L14: =L13/L$6 -> 0.60633979
B15: % growth | F15: =(F13-E13)/E13 -> -0.11209239 | G15: =(G13-F13)/F13 -> 0.34200459 | H15: =(H13-G13)/G13 -> 0.37571266 | I15: =(I13-H13)/H13 -> 0.27089377 | J15: =(J13-I13)/I13 -> 0.1 | K15: =(K13-J13)/J13 -> 0.08 | L15: =(L13-K13)/K13 -> 0.05
B17: Mission Solutions | E17: 3063 | F17: 2289 | G17: 2655 | H17: 2594 | I17: 2720 | J17: =I17*0.9 -> 2448 | K17: =J17*1.025 -> 2509.2 | L17: =K17*1.04 -> 2609.568
B18: % of total | E18: =E17/E$6 -> 0.21637468 | F18: =F17/F$6 -> 0.1665454 | G18: =G17/G$6 -> 0.17157813 | H18: =H17/H$6 -> 0.15899479 | I18: =I17/I$6 -> 0.17544991 | J18: =J17/J$6 -> 0.15299388 | K18: =K17/K$6 -> 0.1435529 | L18: =L17/L$6 -> 0.13787678
B19: % growth | F19: =(F17-E17)/E17 -> -0.25269344 | G19: =(G17-F17)/F17 -> 0.15989515 | H19: =(H17-G17)/G17 -> -0.022975518 | I19: =(I17-H17)/H17 -> 0.048573631 | J19: =(J17-I17)/I17 -> -0.1 | K19: =(K17-J17)/J17 -> 0.025 | L19: =(L17-K17)/K17 -> 0.04
B21: Other | E21: 1721 | F21: 1662 | G21: 1250 | H21: 506 | I21: 29 | J21: 20.8 | K21: 14.5 | L21: 10
B22: % of total | F22: =F21/F$6 -> 0.12092549 | G22: =G21/G$6 -> 0.080780664 | H22: =H21/H$6 -> 0.031014404 | I22: =I21/I$6 -> 0.0018706057 | J22: =J21/J$6 -> 0.001299948 | K22: =K21/K$6 -> 0.00082955404 | L22: =L21/L$6 -> 0.00052835096
A24: x | B24: Order Received Value | E24: 2021 | F24: =E24+1 -> 2022 | G24: =F24+1 -> 2023 | H24: =G24+1 -> 2024 | I24: =H24+1 -> 2025 | J24: 2026E | K24: 2027E | L24: 2028E | M24: 2029E | N24: 2030E
B26: Total | E26: =SUM(E29,E33,E37,E41) -> 9970 | F26: =SUM(F29,F33,F37,F41) -> 19815 | G26: =SUM(G29,G33,G37,G41) -> 19528 | H26: =SUM(H29,H33,H37,H41) -> 15123 | I26: =SUM(I29,I33,I37,I41) -> 11956 | J26: =SUM(J29,J33,J37,J41) -> 17258 | K26: =SUM(K29,K33,K37,K41) -> 19165.7
B27: % growth | F27: =(F26-E26)/E26 -> 0.98746239 | G27: =(G26-F26)/F26 -> -0.014483977 | H27: =(H26-G26)/G26 -> -0.22557354 | I27: =(I26-H26)/H26 -> -0.20941612 | J27: =(J26-I26)/I26 -> 0.44345935 | K27: =(K26-J26)/J26 -> 0.11054004
B29: Energy Solutions | E29: 3313 | F29: 6511 | G29: 6871 | H29: 3246 | I29: 1421 | J29: 6157.1 | K29: 5743.3
B30: % of total | E30: =E29/E$26 -> 0.33229689 | F30: =F29/F$26 -> 0.32858945 | G30: =G29/G$26 -> 0.35185375 | H30: =H29/H$26 -> 0.21463995 | I30: =I29/I$26 -> 0.11885246 | J30: =J29/J$26 -> 0.35676788 | K30: =K29/K$26 -> 0.29966555
B31: % growth | F31: =(F29-E29)/E29 -> 0.96528826 | G31: =(G29-F29)/F29 -> 0.055291046 | H31: =(H29-G29)/G29 -> -0.52757968 | I31: =(I29-H29)/H29 -> -0.56223044 | J31: =(J29-I29)/I29 -> 3.3329346 | K31: =(K29-J29)/J29 -> -0.067206964
B33: Urban Solutions | E33: 2721 | F33: 6799 | G33: 10141 | H33: 9493 | I33: 8688 | J33: 8613.9 | K33: 9948
B34: % of total | E34: =E33/E$26 -> 0.27291876 | F34: =F33/F$26 -> 0.3431239 | G34: =G33/G$26 -> 0.51930561 | H34: =H33/H$26 -> 0.62771937 | I34: =I33/I$26 -> 0.72666444 | J34: =J33/J$26 -> 0.49912504 | K34: =K33/K$26 -> 0.51905227
B35: % growth | F35: =(F33-E33)/E33 -> 1.4987137 | G35: =(G33-F33)/F33 -> 0.49154287 | H35: =(H33-G33)/G33 -> -0.063899024 | I35: =(I33-H33)/H33 -> -0.084799326 | J35: =(J33-I33)/I33 -> -0.0085290055 | K35: =(K33-J33)/J33 -> 0.15487758
B37: Mission Solutions | E37: 2718 | F37: 5347 | G37: 1055 | H37: 1910 | I37: 1847 | J37: 2487 | K37: 3474.4
B38: % of total | E38: =E37/E$26 -> 0.27261785 | F38: =F37/F$26 -> 0.26984608 | G38: =G37/G$26 -> 0.05402499 | H38: =H37/H$26 -> 0.12629769 | I38: =I37/I$26 -> 0.1544831 | J38: =J37/J$26 -> 0.14410708 | K38: =K37/K$26 -> 0.18128219
B39: % growth | F39: =(F37-E37)/E37 -> 0.96725533 | G39: =(G37-F37)/F37 -> -0.8026931 | H39: =(H37-G37)/G37 -> 0.81042654 | I39: =(I37-H37)/H37 -> -0.032984293 | J39: =(J37-I37)/I37 -> 0.34650785 | K39: =(K37-J37)/J37 -> 0.39702453
B41: Other | E41: 1218 | F41: 1158 | G41: 1461 | H41: 474 | I41: 0 | J41: 0 | K41: 0
B42: % of total | E42: =E41/E$26 -> 0.1221665 | F42: =F41/F$26 -> 0.058440575 | G42: =G41/G$26 -> 0.074815649 | H42: =H41/H$26 -> 0.031342988 | I42: =I41/I$26 -> 0 | J42: =J41/J$26 -> 0 | K42: =K41/K$26 -> 0
A44: x | B44: Order Backlog Value | E44: 2021 | F44: =E44+1 -> 2022 | G44: =F44+1 -> 2023 | H44: =G44+1 -> 2024 | I44: =H44+1 -> 2025 | J44: 2026E | K44: 2027E | L44: 2028E | M44: 2029E | N44: 2030E
B46: Total | E46: =SUM(E49,E53,E57,E61) -> 20800 | F46: =SUM(F49,F53,F57,F61) -> 26049 | G46: =SUM(G49,G53,G57,G61) -> 29441 | H46: =SUM(H49,H53,H57,H61) -> 28484 | I46: =SUM(I49,I53,I57,I61) -> 25536 | J46: =SUM(J49,J53,J57,J61) -> 26304.5 | K46: =SUM(K49,K53,K57,K61) -> 28533.6
B47: % growth | F47: =(F46-E46)/E46 -> 0.25235577 | G47: =(G46-F46)/F46 -> 0.13021613 | H47: =(H46-G46)/G46 -> -0.032505689 | I47: =(I46-H46)/H46 -> -0.1034967 | J47: =(J46-I46)/I46 -> 0.030094768 | K47: =(K46-J46)/J46 -> 0.084742154
B49: Energy Solutions | E49: 9324 | F49: 9134 | G49: 9722 | H49: 7605 | I49: 4601 | J49: 6504.1 | K49: 7573.6
B50: % of total | E50: =E49/E$46 -> 0.44826923 | F50: =F49/F$46 -> 0.35064686 | G50: =G49/G$46 -> 0.33021976 | H50: =H49/H$46 -> 0.266992 | I50: =I49/I$46 -> 0.18017701 | J50: =J49/J$46 -> 0.24726188 | K50: =K49/K$46 -> 0.26542743
B51: % growth | F51: =(F49-E49)/E49 -> -0.02037752 | G51: =(G49-F49)/F49 -> 0.064374863 | H51: =(H49-G49)/G49 -> -0.21775355 | I51: =(I49-H49)/H49 -> -0.39500329 | J51: =(J49-I49)/I49 -> 0.41362747 | K51: =(K49-J49)/J49 -> 0.16443474
B53: Urban Solutions | E53: 7048 | F53: 9900 | G53: 14848 | H53: 17749 | I53: 18746 | J53: 17613.4 | K53: 17894.3
B54: % of total | E54: =E53/E$46 -> 0.33884615 | F54: =F53/F$46 -> 0.38005298 | G54: =G53/G$46 -> 0.5043307 | H54: =H53/H$46 -> 0.62312175 | I54: =I53/I$46 -> 0.73410088 | J54: =J53/J$46 -> 0.66959646 | K54: =K53/K$46 -> 0.62713082
B55: % growth | F55: =(F53-E53)/E53 -> 0.4046538 | G55: =(G53-F53)/F53 -> 0.49979798 | H55: =(H53-G53)/G53 -> 0.19537985 | I55: =(I53-H53)/H53 -> 0.056172179 | J55: =(J53-I53)/I53 -> -0.060418223 | K55: =(K53-J53)/J53 -> 0.015948085
B57: Mission Solutions | E57: 2562 | F57: 5666 | G57: 3945 | H57: 2727 | I57: 2189 | J57: 2187 | K57: 3065.7
B58: % of total | E58: =E57/E$46 -> 0.12317308 | F58: =F57/F$46 -> 0.21751315 | G58: =G57/G$46 -> 0.13399681 | H58: =H57/H$46 -> 0.095737958 | I58: =I57/I$46 -> 0.085722118 | J58: =J57/J$46 -> 0.083141668 | K58: =K57/K$46 -> 0.10744175
...

Sheet Quarterly Segments
H2: Sep '24 | I2: Dec '24 | J2: Mar '25 | K2: Jun '25 | L2: Sep '25 | M2: Dec '25 | N2: Mar '26 | O2: Jun '26E | P2: Sep '26E | Q2: Dec '26E | R2: Mar '27E | S2: Jun '27E
H3: FY 25 | L3: FY 26 | P3: FY 27
A4: x | B4: Quarterly Product Segments | H4: Q1 | I4: Q2 | J4: Q3 | K4: Q4 | L4: Q1 | M4: Q2 | N4: Q3 | O4: Q4 | P4: Q1 | Q4: Q2 | R4: Q3 | S4: Q4

Sheet Extras
G3: #VALUE! | H3: {=_FV(G3,"Price")} -> 52.99
