Workbook

Sheet Main
A4: x | B4: Company Overview | W4: 10 Year DCF | Y4: 2032 | Z4: =Y4+1 -> 2033 | AA4: =Z4+1 -> 2034 | AB4: =AA4+1 -> 2035 | AC4: =AB4+1 -> 2036
B6: Price | G6: Key Stats | M6: Valuation | R6: Notes | W6: Revenue | Y6: =P96*1.11 -> 160392.58 | Z6: =Y6*1.1 -> 176431.84 | AA6: =Z6*1.09 -> 192310.71 | AB6: =AA6*1.08 -> 207695.56 | AC6: =AB6*1.07 -> 222234.25
B7: Ticker | E7: INTC | G7: Employees | I7: 85100 | M7: PV of FCF | P7: =SUM(K108:P108) -> 67691.076 | R7: WACC | U7: 0.105 | W7: % growth | Y7: 0.095 | Z7: 0.09 | AA7: 0.085 | AB7: =(AB6-AA6)/AA6 -> 0.08 | AC7: =(AC6-AB6)/AB6 -> 0.07
B8: Implied Share Price | E8: =AVERAGE((P13/P12),(T23)) -> 93.304565 | G8: Founded | I8: 1968 | M8: Terminal Value | P8: =(P49*U8) -> 779654.26 | R8: EV/EBITDA Multiple | U8: 12
B9: Current Share Price | E9: =Extras!N3 -> 123 | G9: CEO | I9: Lip-Bu Tan | M9: PV of Terminal Value | P9: =-(PV(U7,(DATE(2031,12,31)-$E$12)/365,0,P8)) -> 443057.08 | R9: TGR | U9: 0.03
B10: Implied Upside / (Downside) | E10: =E8/E9-1 -> -0.2414263 | G10: Headquarters | I10: Santa Clara, California | M10: Net Debt | P10: =-32789+43027+2004 -> 12242 | W10: Free Cash Flow | Y10: =Y6*0.22 -> 35286.368 | Z10: =Z6*0.23 -> 40579.323 | AA10: =AA6*0.24 -> 46154.569 | AB10: =AB6*0.25 -> 51923.891 | AC10: =AC6*0.25 -> 55558.563
B11: IRR | E11: =(K17/E9)^(1/2)-1 -> -0.043046169 | G11: Primary Industry | I11: Semiconductors | M11: Strategic Investments | P11: =6000+4300 -> 10300 | W11: % of sales | Y11: =P106+0.003 -> 0.24961501 | Z11: =Y11+0.0004 -> 0.25001501 | AA11: =Z11 -> 0.25001501 | AB11: =AA11+0.0004 -> 0.25041501 | AC11: =AB11+0.0004 -> 0.25081501
B12: Last Updated | E12: 46147 | G12: Fiscal Year End | I12: 46387 | M12: Shares Outstanding | P12: 5026
M13: Implied Market Cap | P13: =P9+P7-P10+P11 -> 508806.16 | R13: Share Price | U13: =P13/P12 -> 101.23481 | W13: Present Value of FCF | Y13: =Y10/(1+$U$7)^((DATE(2032,7,1)-$E$12)/365) -> 19073.221 | Z13: =Z10/(1+$U$7)^((DATE(2033,7,1)-$E$12)/365) -> 19849.959 | AA13: =AA10/(1+$U$7)^((DATE(2034,7,1)-$E$12)/365) -> 20431.829 | AB13: =AB10/(1+$U$7)^((DATE(2035,7,1)-$E$12)/365) -> 20801.635 | AC13: =AC10/(1+$U$7)^((DATE(2036,7,1)-$E$12)/365) -> 20137.251
A15: x | B15: Key Statistics | E15: 2021 | F15: =E15+1 -> 2022 | G15: =F15+1 -> 2023 | H15: =G15+1 -> 2024 | I15: =H15+1 -> 2025 | J15: 2026E | K15: 2027E | M15: Financial Ratios | R15: Gordon Growth Method | W15: Probability Weighted | Z15: 46165
M16: PV of FCF | P16: =SUM(J111:N111) -> 0
B17: Stock Price | E17: 51.5 | F17: 26.43 | G17: 50.25 | H17: 20.05 | I17: 36.9 | J17: =AVERAGE($U$13*(1+$U$7)-K105/J18,$T$23*(1+$U$7)-K105/J18) -> 102.74639 | K17: =AVERAGE($U$13*(1+$U$7)^2-(K105/J18)*(1+$U$7)-L105/K18,$T$23*(1+$U$7)^2-(K105/J18)*(1+$U$7)-L105/K18) -> 112.63856 | M17: Market Cap | P17: =E9*P12 -> 618198 | R17: FCF Value | T17: =SUM(K108:P108)+SUM((Y13:AC13)) -> 167984.97 | W17: Bear | X17: 63 | Y17: 0.2 | Z17: 58
B18: shares outstanding | E18: 4059 | F18: 4108 | G18: 4190 | H18: 4280 | I18: 4530 | J18: =K70 -> 5237 | K18: =L70 -> 5446.48 | M18: Enterprise Value | P18: =P17+P10 -> 630440 | R18: Terminal Value | T18: =(AC10*(1+U9)/($U$7-U9))/(1+$U$7)^((DATE(2036,12,31)-$E$12)/365) -> 263048.36 | W18: Base | X18: 103 | Y18: 0.55 | Z18: 93
M19: P/E (LTM) | P19: =$P$17/J67 -> -2315.3483 | R19: Net Debt | T19: =P10 -> 12242 | W19: Bull | X19: 273 | Y19: 0.25 | Z19: 248
B20: Market Cap | E20: =E18*E17 -> 209038.5 | F20: =F18*F17 -> 108574.44 | G20: =G18*G17 -> 210547.5 | H20: =H18*H17 -> 85814 | I20: =I18*I17 -> 167157 | J20: =J17*J18 -> 538082.85 | K20: =K17*K18 -> 613483.65 | M20: P/E (NTM) | P20: =$P$17/K67 -> 177.86086 | R20: Strategic Investments | T20: =P11 -> 10300
B21: Cash | E21: 29253 | F21: 28338 | G21: 25034 | H21: 22062 | I21: 37416 | J21: 30859 | K21: 45000 | M21: EV/EBITDA (LTM) | P21: =P18/(J46+J78) -> 66.418036 | R21: Total | T21: =T17+T18-T19+T20 -> 429091.33 | W21: Total | X21: =SUMPRODUCT(X17:X19,Y17:Y19) -> 137.5 | Z21: =SUMPRODUCT(Z17:Z19,Y17:Y19) -> 124.75
B22: Debt | E22: =33510+4591 -> 38101 | F22: =37684+4367 -> 42051 | G22: =46978+2288 -> 49266 | H22: =46282+3729 -> 50011 | I22: =44086+2499 -> 46585 | J22: =42509+2066 -> 44575 | K22: =J22*1.01 -> 45020.75 | M22: EV/EBITDA (NTM) | P22: =P18/(K46+K78) -> 40.805206 | W22: Current | X22: =E9 -> 123
B23: Enterprise Value | E23: =E20-E21+E22 -> 217886.5 | F23: =F20-F21+F22 -> 122287.44 | G23: =G20-G21+G22 -> 234779.5 | H23: =H20-H21+H22 -> 113763 | I23: =I20-I21+I22 -> 176326 | J23: =J20-J21+J22 -> 551798.85 | K23: =K20-K21+K22 -> 613504.4 | M23: EV/EBIT (LTM) | P23: =P18/J46 -> -284.75158 | R23: Share Price | T23: =T21/P12 -> 85.37432 | W23: Upside | X23: =(X21-X22)/X22 -> 0.11788618
A26: x | B26: Income Statement ($M) | E26: 2020 | F26: 2021 | G26: 2022 | H26: 2023 | I26: 2024 | J26: 2025 | K26: 2026E | L26: 2027E | M26: 2028E | N26: 2029E | O26: 2030E | P26: 2031E | R26: $ mm, except per share | U26: 2026E | V26: 2027E | W26: 2028E | X26: 2029E | Y26: 2030E | Z26: 2031E
B28: Revenue | E28: 77867 | F28: 79024 | G28: 63054 | H28: 54228 | I28: 53101 | J28: 52853 | K28: =Segments!I20 -> 58495.857 | L28: =Segments!J20 -> 74214.818 | M28: =Segments!K20 -> 92740.819 | N28: =Segments!L20 -> 114902.73 | O28: =Segments!M20 -> 131644.53 | P28: =Segments!N20 -> 144497.82 | R28: =B28 -> Revenue | U28: =K28 -> 58495.857 | V28: =L28 -> 74214.818 | W28: =M28 -> 92740.819 | X28: =N28 -> 114902.73 | Y28: =O28 -> 131644.53 | Z28: =P28 -> 144497.82
B29: % growth | F29: =(F28-E28)/E28 -> 0.014858669 | G29: =(G28-F28)/F28 -> -0.2020905 | H29: =(H28-G28)/G28 -> -0.13997526 | I29: =(I28-H28)/H28 -> -0.020782622 | J29: =(J28-I28)/I28 -> -0.0046703452 | K29: =(K28-J28)/J28 -> 0.10676513 | L29: =(L28-K28)/K28 -> 0.2687192 | M29: =(M28-L28)/L28 -> 0.24962671 | ... P29: =(P28-O28)/O28 -> 0.097636347 | R29: Revenue Growth | U29: =K29 -> 0.10676513 | V29: =L29 -> 0.2687192 | W29: =M29 -> 0.24962671 | X29: =N29 -> 0.23896606 | Y29: =O29 -> 0.14570415 | Z29: =P29 -> 0.097636347
R30: =B34 -> Gross Profit | U30: =K34 -> 22228.426 | V30: =L34 -> 30799.149 | W30: =M34 -> 44051.889 | X30: =N34 -> 58600.39 | Y30: =O34 -> 70429.824 | Z30: =P34 -> 79473.802
B31: COGS | E31: 34255 | F31: 35209 | G31: 36188 | H31: 32517 | I31: 35756 | J31: 34478 | K31: =K28*0.62 -> 36267.432 | L31: =L28*0.585 -> 43415.668 | M31: =M28*0.525 -> 48688.93 | N31: =N28*0.49 -> 56302.336 | O31: =O28*0.465 -> 61214.707 | P31: =P28*0.45 -> 65024.02 | R31: Gross Margin | U31: =K35 -> 0.38 | V31: =L35 -> 0.415 | W31: =M35 -> 0.475 | X31: =N35 -> 0.51 | Y31: =O35 -> 0.535 | Z31: =P35 -> 0.55
B32: % of sales | E32: =E31/E28 -> 0.43991678 | F32: =F31/F28 -> 0.44554819 | G32: =G31/G28 -> 0.57392077 | H32: =H31/H28 -> 0.59963487 | I32: =I31/I28 -> 0.67335832 | J32: =J31/J28 -> 0.65233762 | K32: =K31/K28 -> 0.62 | L32: =L31/L28 -> 0.585 | ... P32: =P31/P28 -> 0.45 | R32: EBITDA | U32: =K49 -> 15449.989 | V32: =L49 -> 21720.518 | W32: =M49 -> 31100.006 | X32: =N49 -> 44484.956 | Y32: =O49 -> 56181.4 | Z32: =P49 -> 64971.189
R33: EBITDA Margin | U33: =K50 -> 0.26412109 | V33: =L50 -> 0.29267091 | W33: =M50 -> 0.33534323 | X33: =N50 -> 0.38715318 | Y33: =O50 -> 0.42676592 | Z33: =P50 -> 0.44963438
B34: Gross Profit | E34: =E28-E31 -> 43612 | F34: =F28-F31 -> 43815 | G34: =G28-G31 -> 26866 | H34: =H28-H31 -> 21711 | I34: =I28-I31 -> 17345 | J34: =J28-J31 -> 18375 | K34: =K28-K31 -> 22228.426 | L34: =L28-L31 -> 30799.149 | ... P34: =P28-P31 -> 79473.802 | R34: Operating Income | U34: =K46 -> 3657.2246 | V34: =L46 -> 7827.5043 | W34: =M46 -> 16029.623 | X34: =N46 -> 29317.796 | Y34: =O46 -> 40384.056 | Z34: =P46 -> 49365.424
B35: % of sales | E35: =E34/E28 -> 0.56008322 | F35: =F34/F28 -> 0.55445181 | G35: =G34/G28 -> 0.42607923 | H35: =H34/H28 -> 0.40036513 | I35: =I34/I28 -> 0.32664168 | J35: =J34/J28 -> 0.34766238 | K35: =K34/K28 -> 0.38 | L35: =L34/L28 -> 0.415 | ... P35: =P34/P28 -> 0.55 | R35: EBIT Margin | U35: =K47 -> 0.062521086 | V35: =L47 -> 0.10547091 | W35: =M47 -> 0.17284323 | X35: =N47 -> 0.25515318 | Y35: =O47 -> 0.30676592 | Z35: =P47 -> 0.34163438
R36: =B67 -> Net Income | U36: =K67 -> 3475.7394 | V36: =L67 -> 7108.8182 | W36: =M67 -> 14187.825 | X36: =N67 -> 25558.675 | Y36: =O67 -> 34843.503 | Z36: =P67 -> 41960.61
B37: Research & Development | E37: 13556 | F37: 15190 | G37: 17528 | H37: 16046 | I37: 16546 | J37: 13774 | K37: =K34-K40-N(K43)-K46 -> 13482.062 | L37: =L34-N(L43)-L46-L40 -> 18251.583 | M37: =M34-N(M43)-M46-M40 -> 22439.269 | N37: =N34-N(N43)-N46-N40 -> 22756.119 | O37: =O34-N(O43)-O46-O40 -> 23015.95 | P37: =P34-N(P43)-P46-P40 -> 22883.487 | R37: Net Margin | U37: =K68 -> 0.059418556 | V37: =L68 -> 0.095787046 | W37: =M68 -> 0.15298361 | X37: =N68 -> 0.2224375 | Y37: =O68 -> 0.2646787 | Z37: =P68 -> 0.29038922
B38: % of sales | E38: =E37/E$28 -> 0.17409172 | F38: =F37/F$28 -> 0.19222009 | G38: =G37/G$28 -> 0.27798395 | H38: =H37/H$28 -> 0.2958988 | I38: =I37/I$28 -> 0.31159489 | J38: =J37/J$28 -> 0.26060962 | K38: =K37/K$28 -> 0.23047891 | L38: =L37/L$28 -> 0.24592909 | ... P38: =P37/P$28 -> 0.15836562 | R38: Shares Outstanding | U38: =K70 -> 5237 | V38: =L70 -> 5446.48 | W38: =M70 -> 5555.4096 | X38: =N70 -> 5666.5178 | Y38: =O70 -> 5779.8481 | Z38: =P70 -> 5895.4451
R39: EPS | U39: =K73 -> 0.66368902 | V39: =L73 -> 1.3052133 | W39: =M73 -> 2.5538756 | X39: =N73 -> 4.510473 | Y39: =O73 -> 6.028446 | Z39: =P73 -> 7.1174626
B40: SG&A | E40: 6180 | F40: 6543 | G40: 7002 | H40: 5634 | I40: 5507 | J40: 4624 | K40: =K28*K41 -> 3919.2225 | L40: =L28*L41 -> 4720.0624 | M40: =M28*M41 -> 5582.9973 | N40: =N28*N41 -> 6526.4748 | O40: =O28*O41 -> 7029.8179 | P40: =P28*P41 -> 7224.8911 | R40: EPS Growth | U40: N/A | V40: =L74 -> 0.96660374 | W40: =M74 -> 0.95667299 | X40: =N74 -> 0.76612868 | Y40: =O74 -> 0.3365441 | Z40: =P74 -> 0.18064632
B41: % of sales | E41: =E40/E$28 -> 0.079366099 | F41: =F40/F$28 -> 0.082797631 | G41: =G40/G$28 -> 0.11104767 | H41: =H40/H$28 -> 0.10389467 | I41: =I40/I$28 -> 0.10370803 | J41: =J40/J$28 -> 0.087487938 | K41: 0.067 | L41: =$K$41+($P$41-$K$41)*(COLUMNS($K$41:L41)-1)/(COLUMNS($K$41:$P$41)-1) -> 0.0636 | M41: =$K$41+($P$41-$K$41)*(COLUMNS($K$41:M41)-1)/(COLUMNS($K$41:$P$41)-1) -> 0.0602 | N41: =$K$41+($P$41-$K$41)*(COLUMNS($K$41:N41)-1)/(COLUMNS($K$41:$P$41)-1) -> 0.0568 | O41: =$K$41+($P$41-$K$41)*(COLUMNS($K$41:O41)-1)/(COLUMNS($K$41:$P$41)-1) -> 0.0534 | P41: 0.05 | R41: Free Cash Flow | U41: =K105 -> 1859.9427 | V41: =L105 -> 4881.154 | W41: =M105 -> 9482.0986 | X41: =N105 -> 19127.583 | Y41: =O105 -> 28210.333 | Z41: =P105 -> 35635.331
R42: FCF Margin | U42: =K106 -> 0.031796144 | V42: =L106 -> 0.065770612 | W42: =M106 -> 0.10224299 | X42: =N106 -> 0.16646762 | Y42: =O106 -> 0.21429172 | Z42: =P106 -> 0.24661501
B43: Restructuring and Other Changes | E43: 198 | F43: 2626 | G43: 2 | H43: -62 | I43: 6970 | J43: 2191 | K43: =K28*0.02 -> 1169.9171 | L43: 0 | M43: 0 | N43: 0 | O43: 0 | P43: 0 | R43: CapEx | U43: =K81 -> 16378.84 | V43: =L81 -> 19295.853 | W43: =M81 -> 23185.205 | X43: =N81 -> 25278.6 | Y43: =O81 -> 26328.906 | Z43: =P81 -> 26009.608
B44: % of sales | E44: =E43/E$28 -> 0.0025427973 | F44: =F43/F$28 -> 0.033230411 | G44: =G43/G$28 -> 3.1718844e-05 | H44: =H43/H$28 -> -0.0011433208 | I44: =I43/I$28 -> 0.1312593 | J44: =J43/J$28 -> 0.0414546 | K44: =K43/K$28 -> 0.02 | L44: =L43/L$28 -> 0 | ... P44: =P43/P$28 -> 0 | R44: CapEx % of Sales | U44: =K103 -> 0.28 | V44: =L103 -> 0.26 | W44: =M103 -> 0.25 | X44: =N103 -> 0.22 | Y44: =O103 -> 0.2 | Z44: =P103 -> 0.18
B46: Operating Income (EBIT) | E46: =E34-E37-E40-E43 -> 23678 | F46: =F34-F37-F40-F43 -> 19456 | G46: =G34-G37-G40-G43 -> 2334 | H46: =H34-H37-H40-H43 -> 93 | I46: =I34-I37-I40-I43 -> -11678 | J46: =J34-J37-J40-J43 -> -2214 | K46: =Segments!I57 -> 3657.2246 | L46: =Segments!J57 -> 7827.5043 | M46: =Segments!K57 -> 16029.623 | N46: =Segments!L57 -> 29317.796 | O46: =Segments!M57 -> 40384.056 | P46: =Segments!N57 -> 49365.424
B47: % of sales | E47: =E46/E$28 -> 0.3040826 | F47: =F46/F$28 -> 0.24620368 | G47: =G46/G$28 -> 0.037015891 | H47: =H46/H$28 -> 0.0017149812 | I47: =I46/I$28 -> -0.21992053 | J47: =J46/J$28 -> -0.04188977 | K47: =K46/K$28 -> 0.062521086 | L47: =L46/L$28 -> 0.10547091 | ... P47: =P46/P$28 -> 0.34163438
B49: EBITDA | E49: =E46+E78 -> 35917 | F49: =F46+F78 -> 31248 | G49: =G46+G78 -> 15369 | H49: =H46+H78 -> 9695 | I49: =I46+I78 -> -299 | J49: =J46+J78 -> 9492 | K49: =K46+K78 -> 15449.989 | L49: =L46+L78 -> 21720.518 | ... P49: =P46+P78 -> 64971.189
B50: % of sales | E50: =E49/E$28 -> 0.46126087 | F50: =F49/F$28 -> 0.39542417 | G50: =G49/G$28 -> 0.24374346 | H50: =H49/H$28 -> 0.17878218 | I50: =I49/I$28 -> -0.0056307791 | J50: =J49/J$28 -> 0.17959245 | K50: =K49/K$28 -> 0.26412109 | L50: =L49/L$28 -> 0.29267091 | ... P50: =P49/P$28 -> 0.44963438
...

Sheet Segments
K2: all values in millions except per share numbers
A4: x | B4: Levers | D4: 2026 | E4: 2031 | I4: 2026 | J4: 2031
B6: GPU/XPU Units | D6: 13 | E6: 50 | G6: Usable Capacity % | I6: 0.5 | J6: 0.85 | L6: ASIC Probability 2028 | N6: 0.2
B7: CPU Attach | D7: 0.25 | E7: 1 | G7: Foundry Rev / Wafer | I7: 22 | J7: 28 | L7: ASIC Probability 2031 | N7: 0.4
B8: Intel AI Share | D8: 0.35 | E8: 0.3 | G8: Internal Foundry Rev | I8: 18500 | J8: 25000
B9: AI CPU ASP | D9: 2000 | E9: 3000 | G9: EMIB / Packaging Rev | I9: 2000 | J9: 12000
B10: Good Dies / Wafer Eq. | D10: 80 | E10: 130 | G10: TeraFab Gross Rev | I10: 0 | J10: 8000
B12: TeraFab Probability | D12: 0.4 | E12: 0.4 | G12: Foundry Margin | I12: -0.4 | J12: 0.25
B13: ZAM Gross Rev (2029) | D13: 500 | E13: 5000 | G13: CCG Growth | I13: -0.01 | J13: 0.03
B14: HBM/ZAM Probability | D14: 0.2 | E14: 0.2 | G14: Non-AI DCAI Growth | I14: 0.05 | J14: 0.03
B15: CCG Margin | D15: 0.3 | E15: 0.35 | G15: ASIC Rev/Wafer (2028) | I15: 50 | J15: 100
B16: DCAI Margin | D16: 0.3 | E16: 0.35 | G16: ASIC Margin | I16: 0.1 | J16: 0.35
A18: x | B18: Product Segments ($M) | F18: 2023 | G18: 2024 | H18: 2025 | I18: 2026E | J18: 2027E | K18: 2028E | L18: 2029E | M18: 2030E | N18: 2031E
B20: Revenue | F20: =SUM(F23+F38+F50+F53) -> 54228 | G20: =SUM(G23+G38+G50+G53) -> 53101 | H20: =SUM(H23+H38+H50+H53) -> 52853 | I20: =I23+I38+I50+I53 -> 58495.857 | J20: =J23+J38+J50+J53 -> 74214.818 | K20: =K23+K38+K50+K53 -> 92740.819 | L20: =L23+L38+L50+L53 -> 114902.73 | M20: =M23+M38+M50+M53 -> 131644.53 | N20: =N23+N38+N50+N53 -> 144497.82
B21: % growth | F21: =(F20-63054)/63054 -> -0.13997526 | G21: =(G20-F20)/F20 -> -0.020782622 | H21: =(H20-G20)/G20 -> -0.0046703452 | I21: =(I20-H20)/H20 -> 0.10676513 | J21: =(J20-I20)/I20 -> 0.2687192 | K21: =(K20-J20)/J20 -> 0.24962671 | L21: =(L20-K20)/K20 -> 0.23896606 | M21: =(M20-L20)/L20 -> 0.14570415 | N21: =(N20-M20)/M20 -> 0.097636347
B23: Intel Products | F23: =F26+F29 -> 48285 | G23: =G26+G29 -> 49471 | H23: =H26+H29 -> 49147 | I23: =I26+I29 -> 51945.67 | J23: =J26+J29 -> 57862.134 | K23: =K26+K29 -> 67527.819 | L23: =L26+L29 -> 81405.333 | M23: =M26+M29 -> 92866.935 | N23: =N26+N29 -> 101976.39
B24: % growth | G24: =(G23-F23)/F23 -> 0.024562494 | H24: =(H23-G23)/G23 -> -0.0065492915 | I24: =(I23-H23)/H23 -> 0.05694488 | J24: =(J23-I23)/I23 -> 0.11389715 | K24: =(K23-J23)/J23 -> 0.16704681 | L24: =(L23-K23)/K23 -> 0.20550811 | M24: =(M23-L23)/L23 -> 0.1407967 | N24: =(N23-M23)/M23 -> 0.098091496
B26: Client Computing | F26: 32305 | G26: 33346 | H26: 32228 | I26: =H26*(1+I112) -> 31905.72 | J26: =I26*(1+J112) -> 31905.72 | K26: =J26*(1+K112) -> 32224.777 | L26: =K26*(1+L112) -> 32869.273 | M26: =L26*(1+M112) -> 33723.874 | N26: =M26*(1+N112) -> 34735.59
B27: % growth | G27: =(G26-F26)/F26 -> 0.032224114 | H27: =(H26-G26)/G26 -> -0.03352726 | I27: =(I26-H26)/H26 -> -0.01 | J27: =(J26-I26)/I26 -> 0 | K27: =(K26-J26)/J26 -> 0.01 | L27: =(L26-K26)/K26 -> 0.02 | M27: =(M26-L26)/L26 -> 0.026 | N27: =(N26-M26)/M26 -> 0.03
B29: DCAI | F29: 15980 | G29: 16125 | H29: 16919 | I29: =I148+I180+I123*I124 -> 20039.95 | J29: =J148+J180+J123*J124 -> 25956.414 | K29: =K148+K180+K123*K124 -> 35303.041 | L29: =L148+L180+L123*L124 -> 48536.06 | M29: =M148+M180+M123*M124 -> 59143.061 | N29: =N148+N180+N123*N124 -> 67240.801
B30: % growth | G30: =(G29-F29)/F29 -> 0.0090738423 | H30: =(H29-G29)/G29 -> 0.04924031 | I30: =(I29-H29)/H29 -> 0.18446421 | J30: =(J29-I29)/I29 -> 0.29523346 | K30: =(K29-J29)/J29 -> 0.36008933 | L30: =(L29-K29)/K29 -> 0.37484075 | M30: =(M29-L29)/L29 -> 0.21853856 | N30: =(N29-M29)/M29 -> 0.13691784
B32: AI Data Center | I32: =I29-I35 -> 2275 | J32: =J29-J35 -> 7392.041 | K32: =K29-K35 -> 15996.094 | L32: =L29-L35 -> 28553.369 | M32: =M29-M35 -> 38520.924 | N32: =N29-N35 -> 46000
B33: % growth | J33: =(J32-I32)/I32 -> 2.2492488 | K33: =(K32-J32)/J32 -> 1.1639617 | L33: =(L32-K32)/K32 -> 0.78502137 | M33: =(M32-L32)/L32 -> 0.34908506 | N33: =(N32-M32)/M32 -> 0.1941562
B35: Traditional Data Center | I35: =I180 -> 17764.95 | J35: =J180 -> 18564.373 | K35: =K180 -> 19306.948 | L35: =L180 -> 19982.691 | M35: =M180 -> 20622.137 | N35: =N180 -> 21240.801
B36: % growth | J36: =(J35-I35)/I35 -> 0.045 | K36: =(K35-J35)/J35 -> 0.04 | L36: =(L35-K35)/K35 -> 0.035 | M36: =(M35-L35)/L35 -> 0.032 | N36: =(N35-M35)/M35 -> 0.03
B38: Intel Foundry | F38: 18504 | G38: 17317 | H38: 17826 | I38: =I118+I44 -> 21487.188 | J38: =J118+J44 -> 32914.684 | K38: =K118+K44 -> 43400 | L38: =L118+L44 -> 53309.394 | M38: =M118+M44 -> 59564.596 | N38: =N118+N44 -> 63958.431
B39: % growth | G39: =(G38-F38)/F38 -> -0.064148292 | H39: =(H38-G38)/G38 -> 0.029393082 | I39: =(I38-H38)/H38 -> 0.20538469 | J39: =(J38-I38)/I38 -> 0.5318284 | K39: =(K38-J38)/J38 -> 0.31856043 | L39: =(L38-K38)/K38 -> 0.22832704 | M39: =(M38-L38)/L38 -> 0.11733772 | N39: =(N38-M38)/M38 -> 0.073765874
B41: Internal Foundry | F41: =F38-F44 -> 18024 | G41: =G38-G44 -> 17288 | H41: =H38-H44 -> 17683 | I41: =I118 -> 18500 | J41: =J118 -> 20125 | K41: =K118 -> 21750 | L41: =L118 -> 23375 | M41: =M118 -> 24350 | N41: =N118 -> 25000
B42: % growth | G42: =(G41-F41)/F41 -> -0.040834443 | H42: =(H41-G41)/G41 -> 0.022848218 | I42: =(I41-H41)/H41 -> 0.046202567 | J42: =(J41-I41)/I41 -> 0.087837838 | K42: =(K41-J41)/J41 -> 0.080745342 | L42: =(L41-K41)/K41 -> 0.074712644 | M42: =(M41-L41)/L41 -> 0.04171123 | N42: =(N41-M41)/M41 -> 0.026694045
B44: External Foundry | F44: =F38+F53 -> 480 | G44: =G38+G53 -> 29 | H44: =H38+H53 -> 143 | I44: =I174*12*I116+I117+I121*I122 -> 2987.1875 | J44: =J174*12*J116+J117+J121*J122 -> 12789.684 | K44: =K174*12*K116+K117+K121*K122 -> 21650 | L44: =L174*12*L116+L117+L121*L122 -> 29934.394 | M44: =M174*12*M116+M117+M121*M122 -> 35214.596 | N44: =N174*12*N116+N117+N121*N122 -> 38958.431
B45: % growth | G45: =(G44-F44)/F44 -> -0.93958333 | H45: =(H44-G44)/G44 -> 3.9310345 | I45: =(I44-H44)/H44 -> 19.889423 | J45: =(J44-I44)/I44 -> 3.2815136 | K45: =(K44-J44)/J44 -> 0.69277051 | L45: =(L44-K44)/K44 -> 0.38265097 | M45: =(M44-L44)/L44 -> 0.17639251 | N45: =(N44-M44)/M44 -> 0.10631485
B47: ASIC Silicon | K47: =K125*K126 -> 366.75 | L47: =L125*L126 -> 1569.1197 | M47: =M125*M126 -> 2849.6344 | N47: =N125*N126 -> 4615.3846
B48: % growth | L48: =(L47-K47)/K47 -> 3.278445 | M48: =(M47-L47)/L47 -> 0.816072 | N48: =(N47-M47)/M47 -> 0.61964098
B50: Other | F50: 5463 | G50: 3601 | H50: 3563 | I50: =H50 -> 3563 | J50: =I50 -> 3563 | K50: =J50 -> 3563 | L50: =K50 -> 3563 | M50: =L50 -> 3563 | N50: =M50 -> 3563
B51: % growth | G51: =(G50-F50)/F50 -> -0.34083837 | H51: =(H50-G50)/G50 -> -0.010552624 | I51: =(I50-H50)/H50 -> 0 | J51: =(J50-I50)/I50 -> 0 | K51: =(K50-J50)/J50 -> 0 | L51: =(L50-K50)/K50 -> 0 | M51: =(M50-L50)/L50 -> 0 | N51: =(N50-M50)/M50 -> 0
B53: Inter Segment Eliminations | F53: -18024 | G53: -17288 | H53: -17683 | I53: =-I118 -> -18500 | J53: =-J118 -> -20125 | K53: =-K118 -> -21750 | L53: =-L118 -> -23375 | M53: =-M118 -> -24350 | N53: =-N118 -> -25000
A55: x | B55: Operating Income by Segment | F55: 2023 | G55: 2024 | H55: 2025 | I55: 2026E | J55: 2027E | K55: 2028E | L55: 2029E | M55: 2030E | N55: 2031E
B57: Operating Income | F57: =SUM(F60,F69,F75,F78,F82) -> 93 | G57: =SUM(G60,G69,G75,G78,G82) -> -11678 | H57: =SUM(H60,H69,H75,H78,H82) -> -2214 | I57: =I80+I82 -> 3657.2246 | J57: =J80+J82 -> 7827.5043 | K57: =K80+K82 -> 16029.623 | L57: =L80+L82 -> 29317.796 | M57: =M80+M82 -> 40384.056 | N57: =N80+N82 -> 49365.424
B58: % of sales | F58: =F57/F20 -> 0.0017149812 | G58: =G57/G20 -> -0.21992053 | H58: =H57/H20 -> -0.04188977 | I58: =I57/I20 -> 0.062521086 | J58: =J57/J20 -> 0.10547091 | K58: =K57/K20 -> 0.17284323 | L58: =L57/L20 -> 0.25515318 | M58: =M57/M20 -> 0.30676592 | N58: =N57/N20 -> 0.34163438
B60: Intel Products | F60: =F63+F66 -> 11073 | G60: =G63+G66 -> 13008 | H60: =H63+H66 -> 12739 | I60: =I63+I66 -> 15583.701 | J60: =J63+J66 -> 18081.917 | K60: =K63+K66 -> 21946.541 | L60: =L63+L66 -> 27474.3 | M60: =M63+M66 -> 32039.092 | N60: =N63+N66 -> 35691.737
...

Sheet Extras
G2: Management Team
G3: Lip Bu Tan | M3: #VALUE! | N3: {=_FV(M3,"Price")} -> 123
G11: Years | H11: =2031-2026 -> 5 | J11: Year | L11: 2031
G12: EPS | H12: =Main!P73 -> 7.1174626 | J12: Shares | L12: =Main!P70 -> 5895.4451
G13: Multiple | H13: 20 | J13: Market Cap | L13: =L15*L12 -> 1049015.3
G14: Price | H14: =H12*H13 -> 142.34925 | J14: Multiple | L14: 25
G15: WACC | H15: 0.105 | J15: Share Price | L15: =H12*25 -> 177.93657
G16: PV Today | H16: =H14/(1+H15)^H11 -> 86.40598
H18: Multiple
H19: 12 | I19: 15 | J19: 18 | K19: 20 | L19: 23 | M19: 25 | N19: 28 | O19: 30 | P19: 35 | Q19: 40
F20: Discount Rate | G20: =G21-0.01 -> 0.075 | H20: =($H$12*H$19)/(1+$G20)^$H$11 -> 59.49276 | I20: =($H$12*I$19)/(1+$G20)^$H$11 -> 74.36595 | J20: =($H$12*J$19)/(1+$G20)^$H$11 -> 89.239141 | K20: =($H$12*K$19)/(1+$G20)^$H$11 -> 99.154601 | L20: =($H$12*L$19)/(1+$G20)^$H$11 -> 114.02779 | M20: =($H$12*M$19)/(1+$G20)^$H$11 -> 123.94325 | N20: =($H$12*N$19)/(1+$G20)^$H$11 -> 138.81644 | O20: =($H$12*O$19)/(1+$G20)^$H$11 -> 148.7319 | ... Q20: =($H$12*Q$19)/(1+$G20)^$H$11 -> 198.3092
G21: =G22-0.01 -> 0.085 | H21: =($H$12*H$19)/(1+$G21)^$H$11 -> 56.801231 | I21: =($H$12*I$19)/(1+$G21)^$H$11 -> 71.001539 | J21: =($H$12*J$19)/(1+$G21)^$H$11 -> 85.201847 | K21: =($H$12*K$19)/(1+$G21)^$H$11 -> 94.668719 | L21: =($H$12*L$19)/(1+$G21)^$H$11 -> 108.86903 | M21: =($H$12*M$19)/(1+$G21)^$H$11 -> 118.3359 | N21: =($H$12*N$19)/(1+$G21)^$H$11 -> 132.53621 | O21: =($H$12*O$19)/(1+$G21)^$H$11 -> 142.00308 | ... Q21: =($H$12*Q$19)/(1+$G21)^$H$11 -> 189.33744
G22: =G23-0.01 -> 0.095 | H22: =($H$12*H$19)/(1+$G22)^$H$11 -> 54.25451 | I22: =($H$12*I$19)/(1+$G22)^$H$11 -> 67.818137 | J22: =($H$12*J$19)/(1+$G22)^$H$11 -> 81.381765 | K22: =($H$12*K$19)/(1+$G22)^$H$11 -> 90.424183 | L22: =($H$12*L$19)/(1+$G22)^$H$11 -> 103.98781 | M22: =($H$12*M$19)/(1+$G22)^$H$11 -> 113.03023 | N22: =($H$12*N$19)/(1+$G22)^$H$11 -> 126.59386 | O22: =($H$12*O$19)/(1+$G22)^$H$11 -> 135.63627 | ... Q22: =($H$12*Q$19)/(1+$G22)^$H$11 -> 180.84837
G23: 0.105 | H23: =($H$12*H$19)/(1+$G23)^$H$11 -> 51.843588 | I23: =($H$12*I$19)/(1+$G23)^$H$11 -> 64.804485 | J23: =($H$12*J$19)/(1+$G23)^$H$11 -> 77.765382 | K23: =($H$12*K$19)/(1+$G23)^$H$11 -> 86.40598 | L23: =($H$12*L$19)/(1+$G23)^$H$11 -> 99.366877 | M23: =($H$12*M$19)/(1+$G23)^$H$11 -> 108.00748 | N23: =($H$12*N$19)/(1+$G23)^$H$11 -> 120.96837 | O23: =($H$12*O$19)/(1+$G23)^$H$11 -> 129.60897 | ... Q23: =($H$12*Q$19)/(1+$G23)^$H$11 -> 172.81196
G24: =G23+0.01 -> 0.115 | H24: =($H$12*H$19)/(1+$G24)^$H$11 -> 49.560092 | I24: =($H$12*I$19)/(1+$G24)^$H$11 -> 61.950115 | J24: =($H$12*J$19)/(1+$G24)^$H$11 -> 74.340138 | K24: =($H$12*K$19)/(1+$G24)^$H$11 -> 82.600153 | L24: =($H$12*L$19)/(1+$G24)^$H$11 -> 94.990176 | M24: =($H$12*M$19)/(1+$G24)^$H$11 -> 103.25019 | N24: =($H$12*N$19)/(1+$G24)^$H$11 -> 115.64021 | O24: =($H$12*O$19)/(1+$G24)^$H$11 -> 123.90023 | ... Q24: =($H$12*Q$19)/(1+$G24)^$H$11 -> 165.20031
G25: =G24+0.01 -> 0.125 | H25: =($H$12*H$19)/(1+$G25)^$H$11 -> 47.396233 | I25: =($H$12*I$19)/(1+$G25)^$H$11 -> 59.245292 | J25: =($H$12*J$19)/(1+$G25)^$H$11 -> 71.09435 | K25: =($H$12*K$19)/(1+$G25)^$H$11 -> 78.993722 | L25: =($H$12*L$19)/(1+$G25)^$H$11 -> 90.842781 | M25: =($H$12*M$19)/(1+$G25)^$H$11 -> 98.742153 | N25: =($H$12*N$19)/(1+$G25)^$H$11 -> 110.59121 | O25: =($H$12*O$19)/(1+$G25)^$H$11 -> 118.49058 | ... Q25: =($H$12*Q$19)/(1+$G25)^$H$11 -> 157.98744
G26: =G25+0.01 -> 0.135 | H26: =($H$12*H$19)/(1+$G26)^$H$11 -> 45.344763 | I26: =($H$12*I$19)/(1+$G26)^$H$11 -> 56.680953 | J26: =($H$12*J$19)/(1+$G26)^$H$11 -> 68.017144 | K26: =($H$12*K$19)/(1+$G26)^$H$11 -> 75.574604 | L26: =($H$12*L$19)/(1+$G26)^$H$11 -> 86.910795 | M26: =($H$12*M$19)/(1+$G26)^$H$11 -> 94.468256 | N26: =($H$12*N$19)/(1+$G26)^$H$11 -> 105.80445 | O26: =($H$12*O$19)/(1+$G26)^$H$11 -> 113.36191 | ... Q26: =($H$12*Q$19)/(1+$G26)^$H$11 -> 151.14921

Sheet Quarterly Segments
H2: Sep '24 | I2: Dec '24 | J2: Mar '25 | K2: Jun '25 | L2: Sep '25 | M2: Dec '25 | N2: Mar '26E | O2: Jun '26E | P2: Sep '26E | Q2: Dec '26E | R2: Mar '27E
H3: FY 25 | L3: FY 26 | P3: FY 27
B4: Quarterly Product Segments | H4: Q1 | I4: Q2 | J4: Q3 | K4: Q4 | L4: Q1 | M4: Q2 | N4: Q3 | O4: Q4 | P4: Q1 | Q4: Q2 | R4: Q3
