Workbook

Sheet DCF Model
B2: Date: | D2: 46085 | F2: Discount Rate: | H2: 0.12 | J2: Energization per month: | M2: 50
B4: PV of CF per MW | D4: 3.66 | F4: PV of CF per MW (+10% Revenue) | J4: 8.44 | L4: PV of CF per MW with 3% Corp SG&A | P4: 1.93 | R4: BC PV of CF per MW est | U4: =15 -> 15
B5: TV Per CF | D5: 4.14 | F5: PV of CF per MW (+10% Revenue) | J5: 4.61 | L5: PV of TV per MW with 3% Corp SG&A | P5: 3.92 | R5: BC PV of CF Difference | U5: =(160*U4)-(160*D4) -> 1814.4
B7: KPI's | E7: 2026 | F7: 2027 | G7: 2028 | H7: 2029 | I7: 2030 | J7: 2031 | L7: Cash Flows (+10% Revenue) | O7: 2026 | P7: 2027 | Q7: 2028 | R7: 2029 | S7: 2030 | T7: 2031
B8: Prince George | E8: 50 | F8: 50 | G8: 50 | H8: 50 | I8: 50 | J8: 50 | L8: Levered Cash Flow | O8: =E17*$J$4 -> 1941.2 | P8: =(F17-E17)*$J$4 -> 5844.7 | Q8: =(G17-F17)*$J$4 -> 11183 | R8: =(H17-G17)*$J$4 -> 10655.5 | S8: =(I17-H17)*$J$4 -> 5908 | T8: =(J17-I17)*$J$4 -> 2532
B9: Mackenzie | E9: 80 | F9: 80 | G9: 80 | H9: 80 | I9: 80 | J9: 80 | L9: PV of Cash Flow | O9: =O8/((1+$H$2)^(O$7-YEAR($D$2)+0.5)) -> 1834.2616 | P9: =P8/((1+$H$2)^(P$7-YEAR($D$2)+0.5)) -> 4931.0021 | Q9: =Q8/((1+$H$2)^(Q$7-YEAR($D$2)+0.5)) -> 8423.9013 | R9: =R8/((1+$H$2)^(R$7-YEAR($D$2)+0.5)) -> 7166.5602 | S9: =S8/((1+$H$2)^(S$7-YEAR($D$2)+0.5)) -> 3547.8021 | T9: =T8/((1+$H$2)^(T$7-YEAR($D$2)+0.5)) -> 1357.5773
B10: Canal Flats | E10: 30 | F10: 30 | G10: 30 | H10: 30 | I10: 30 | J10: 30
B11: Childress | E11: 300 | F11: 525 | G11: 750 | H11: 750 | I11: 750 | J11: 750 | L11: Terminal Value | O11: =E17*$J$5 -> 1060.3 | P11: =(F17-E17)*$J$5 -> 3192.425 | Q11: =(G17-F17)*$J$5 -> 6108.25 | R11: =(H17-G17)*$J$5 -> 5820.125 | S11: =(I17-H17)*$J$5 -> 3227 | T11: =(J17-I17)*$J$5 -> 1383 | X11: 40.31 | Y11: =(O18-X11)/X11 -> 0.096921472
B12: Sweetwater 1 | E12: 0 | F12: =E12+(M2*12) -> 600 | G12: =F12+(M2*12) -> 1200 | H12: =G12+200 -> 1400 | I12: =H12 -> 1400 | J12: =I12 -> 1400 | L12: PV of Terminal Value | O12: =O11/((1+$H$2)^(O$7-YEAR($D$2)+0.5)) -> 1001.8893 | P12: =P11/((1+$H$2)^(P$7-YEAR($D$2)+0.5)) -> 2693.3554 | Q12: =Q11/((1+$H$2)^(Q$7-YEAR($D$2)+0.5)) -> 4601.2067 | R12: =R11/((1+$H$2)^(R$7-YEAR($D$2)+0.5)) -> 3914.4363 | S12: =S11/((1+$H$2)^(S$7-YEAR($D$2)+0.5)) -> 1937.8398 | T12: =T11/((1+$H$2)^(T$7-YEAR($D$2)+0.5)) -> 741.52032 | X12: =(E30-X11)/X11 -> -0.3261574
B13: Sweetwater 2 | E13: 0 | F13: =M2*2 -> 100 | G13: =F13+500 -> 600 | H13: =G13 -> 600 | I13: =H13 -> 600 | J13: =I13 -> 600
B14: Oklahoma | E14: 0 | F14: 0 | G14: =M2*8 -> 400 | H14: =G14+(M2*12) -> 1000 | I14: =H14+(M2*12) -> 1600 | J14: =I14 -> 1600 | L14: PV of Cash Flows | O14: =SUM(O9:T9)+U5 -> 29075.505
B15: Total Active MW | E15: =SUM(E8:E14) -> 460 | F15: =SUM(F8:F14) -> 1385 | G15: =SUM(G8:G14) -> 3110 | H15: =SUM(H8:H14) -> 3910 | I15: =SUM(I8:I14) -> 4510 | J15: =SUM(J8:J14) -> 4510 | L15: PV of Terminal Value | O15: =SUM(O12:T12) -> 14890.248 | X15: =(O31-X11)/X11 -> -0.48330097
B16: New MW added | E16: =E15 -> 460 | F16: =F15-E15 -> 925 | G16: =G15-F15 -> 1725 | H16: =H15-G15 -> 800 | I16: =I15-H15 -> 600 | J16: =J15-I15 -> 0 | L16: Implied Market Cap | O16: =O14+O15 -> 43965.753
B17: Weighted Average MW | E17: =SUM(E8:E14)/2 -> 230 | F17: =E15+((F15-E15)/2) -> 922.5 | G17: =F15+((G15-F15)/2) -> 2247.5 | H17: =G15+((H15-G15)/2) -> 3510 | I17: =H15+((I15-H15)/2) -> 4210 | J17: =I15+((J15-I15)/2) -> 4510 | L17: Share Count with 3x Dilution | O17: =331.44*3 -> 994.32
L18: Implied Share Price | O18: =O16/O17 -> 44.216905
B19: Cash Flows | E19: 2026 | F19: 2027 | G19: 2028 | H19: 2029 | I19: 2030 | J19: 2031
B20: Levered Cash Flow | E20: =E17*$D$4 -> 841.8 | F20: =(F17-E17)*$D$4 -> 2534.55 | G20: =(G17-F17)*$D$4 -> 4849.5 | H20: =(H17-G17)*$D$4 -> 4620.75 | I20: =(I17-H17)*$D$4 -> 2562 | J20: =(J17-I17)*$D$4 -> 1098 | L20: Cash Flows with Corp SG&A | O20: 2026 | P20: 2027 | Q20: 2028 | R20: 2029 | S20: 2030 | T20: 2031
B21: PV of Cash Flow | E21: =E20/((1+$H$2)^(E$7-YEAR($D$2)+0.5)) -> 795.42623 | F21: =F20/((1+$H$2)^(F$7-YEAR($D$2)+0.5)) -> 2138.3256 | G21: =G20/((1+$H$2)^(G$7-YEAR($D$2)+0.5)) -> 3653.0188 | H21: =H20/((1+$H$2)^(H$7-YEAR($D$2)+0.5)) -> 3107.7737 | I21: =I20/((1+$H$2)^(I$7-YEAR($D$2)+0.5)) -> 1538.5019 | J21: =J20/((1+$H$2)^(J$7-YEAR($D$2)+0.5)) -> 588.71244 | L21: Levered Cash Flow | O21: =E17*$P$4 -> 443.9 | P21: =(F17-E17)*$P$4 -> 1336.525 | Q21: =(G17-F17)*$P$4 -> 2557.25 | R21: =(H17-G17)*$P$4 -> 2436.625 | S21: =(I17-H17)*$P$4 -> 1351 | T21: =(J17-I17)*$P$4 -> 579
L22: PV of Cash Flow | O22: =O21/((1+$H$2)^(O$20-YEAR($D$2)+0.5)) -> 419.44607 | P22: =P21/((1+$H$2)^(P$20-YEAR($D$2)+0.5)) -> 1127.587 | Q22: =Q21/((1+$H$2)^(Q$20-YEAR($D$2)+0.5)) -> 1926.3187 | R22: =R21/((1+$H$2)^(R$20-YEAR($D$2)+0.5)) -> 1638.7987 | S22: =S21/((1+$H$2)^(S$20-YEAR($D$2)+0.5)) -> 811.2865 | T22: =T21/((1+$H$2)^(T$20-YEAR($D$2)+0.5)) -> 310.44126
B23: Terminal Value | E23: =E17*$D$5 -> 952.2 | F23: =(F17-E17)*$D$5 -> 2866.95 | G23: =(G17-F17)*$D$5 -> 5485.5 | H23: =(H17-G17)*$D$5 -> 5226.75 | I23: =(I17-H17)*$D$5 -> 2898 | J23: =(J17-I17)*$D$5 -> 1242
B24: PV of Terminal Value | E24: =E23/((1+$H$2)^(E$7-YEAR($D$2)+0.5)) -> 899.74443 | F24: =F23/((1+$H$2)^(F$7-YEAR($D$2)+0.5)) -> 2418.7617 | G24: =G23/((1+$H$2)^(G$7-YEAR($D$2)+0.5)) -> 4132.1032 | H24: =H23/((1+$H$2)^(H$7-YEAR($D$2)+0.5)) -> 3515.3506 | I24: =I23/((1+$H$2)^(I$7-YEAR($D$2)+0.5)) -> 1740.2726 | J24: =J23/((1+$H$2)^(J$7-YEAR($D$2)+0.5)) -> 665.92063 | L24: Terminal Value | O24: =E17*$P$5 -> 901.6 | P24: =(F17-E17)*$P$5 -> 2714.6 | Q24: =(G17-F17)*$P$5 -> 5194 | R24: =(H17-G17)*$P$5 -> 4949 | S24: =(I17-H17)*$P$5 -> 2744 | T24: =(J17-I17)*$P$5 -> 1176
L25: PV of Terminal Value | O25: =O24/((1+$H$2)^(O$20-YEAR($D$2)+0.5)) -> 851.93192 | P25: =P24/((1+$H$2)^(P$20-YEAR($D$2)+0.5)) -> 2290.2285 | Q25: =Q24/((1+$H$2)^(Q$20-YEAR($D$2)+0.5)) -> 3912.5229 | R25: =R24/((1+$H$2)^(R$20-YEAR($D$2)+0.5)) -> 3328.5446 | S25: =S24/((1+$H$2)^(S$20-YEAR($D$2)+0.5)) -> 1647.7943 | T25: =T24/((1+$H$2)^(T$20-YEAR($D$2)+0.5)) -> 630.53355
B26: PV of Cash Flows | E26: =SUM(E21:J21)+U5 -> 13636.159
B27: PV of Terminal Value | E27: =SUM(E24:J24) -> 13372.153 | L27: PV of Cash Flows | O27: =SUM(O22:T22)+U5 -> 8048.2782
B28: Implied Market Cap | E28: =E26+E27 -> 27008.312 | L28: PV of Terminal Value | O28: =SUM(O25:T25) -> 12661.556
B29: Share Count with 3x Dilution | E29: =331.44*3 -> 994.32 | L29: Implied Market Cap | O29: =O27+O28 -> 20709.834
B30: Implied Share Price | E30: =E28/E29 -> 27.162595 | L30: Share Count with 3x Dilution | O30: =331.44*3 -> 994.32
L31: Implied Share Price | O31: =O29/O30 -> 20.828138
B33: Stock Price Sensitivity Table
I34: Dilution
D35: 1 | E35: 1.25 | F35: 1.5 | G35: 1.75 | H35: 2 | I35: 2.5 | J35: 3 | K35: 4 | L35: 5 | M35: 10 | N35: 12.5 | O35: 15
B36: Terminal Growth Rate | C36: 0.01 | D36: =($E$26+$E$27*(1+$C36)*($H$2-0.025)/(1.025*($H$2-$C36)))/('Deal Economics long'!$AF$20*D$35) -> 75.476199 | E36: =($E$26+$E$27*(1+$C36)*($H$2-0.025)/(1.025*($H$2-$C36)))/('Deal Economics long'!$AF$20*E$35) -> 60.380959 | F36: =($E$26+$E$27*(1+$C36)*($H$2-0.025)/(1.025*($H$2-$C36)))/('Deal Economics long'!$AF$20*F$35) -> 50.317466 | G36: =($E$26+$E$27*(1+$C36)*($H$2-0.025)/(1.025*($H$2-$C36)))/('Deal Economics long'!$AF$20*G$35) -> 43.129257 | H36: =($E$26+$E$27*(1+$C36)*($H$2-0.025)/(1.025*($H$2-$C36)))/('Deal Economics long'!$AF$20*H$35) -> 37.738099 | I36: =($E$26+$E$27*(1+$C36)*($H$2-0.025)/(1.025*($H$2-$C36)))/('Deal Economics long'!$AF$20*I$35) -> 30.19048 | J36: =($E$26+$E$27*(1+$C36)*($H$2-0.025)/(1.025*($H$2-$C36)))/('Deal Economics long'!$AF$20*J$35) -> 25.158733 | K36: =($E$26+$E$27*(1+$C36)*($H$2-0.025)/(1.025*($H$2-$C36)))/('Deal Economics long'!$AF$20*K$35) -> 18.86905 | ... O36: =($E$26+$E$27*(1+$C36)*($H$2-0.025)/(1.025*($H$2-$C36)))/('Deal Economics long'!$AF$20*O$35) -> 5.0317466
C37: 0.015 | D37: =($E$26+$E$27*(1+$C37)*($H$2-0.025)/(1.025*($H$2-$C37)))/('Deal Economics long'!$AF$20*D$35) -> 77.289217 | E37: =($E$26+$E$27*(1+$C37)*($H$2-0.025)/(1.025*($H$2-$C37)))/('Deal Economics long'!$AF$20*E$35) -> 61.831374 | F37: =($E$26+$E$27*(1+$C37)*($H$2-0.025)/(1.025*($H$2-$C37)))/('Deal Economics long'!$AF$20*F$35) -> 51.526145 | G37: =($E$26+$E$27*(1+$C37)*($H$2-0.025)/(1.025*($H$2-$C37)))/('Deal Economics long'!$AF$20*G$35) -> 44.165267 | H37: =($E$26+$E$27*(1+$C37)*($H$2-0.025)/(1.025*($H$2-$C37)))/('Deal Economics long'!$AF$20*H$35) -> 38.644609 | I37: =($E$26+$E$27*(1+$C37)*($H$2-0.025)/(1.025*($H$2-$C37)))/('Deal Economics long'!$AF$20*I$35) -> 30.915687 | J37: =($E$26+$E$27*(1+$C37)*($H$2-0.025)/(1.025*($H$2-$C37)))/('Deal Economics long'!$AF$20*J$35) -> 25.763072 | K37: =($E$26+$E$27*(1+$C37)*($H$2-0.025)/(1.025*($H$2-$C37)))/('Deal Economics long'!$AF$20*K$35) -> 19.322304 | ... O37: =($E$26+$E$27*(1+$C37)*($H$2-0.025)/(1.025*($H$2-$C37)))/('Deal Economics long'!$AF$20*O$35) -> 5.1526145
C38: 0.02 | D38: =($E$26+$E$27*(1+$C38)*($H$2-0.025)/(1.025*($H$2-$C38)))/('Deal Economics long'!$AF$20*D$35) -> 79.283538 | E38: =($E$26+$E$27*(1+$C38)*($H$2-0.025)/(1.025*($H$2-$C38)))/('Deal Economics long'!$AF$20*E$35) -> 63.42683 | F38: =($E$26+$E$27*(1+$C38)*($H$2-0.025)/(1.025*($H$2-$C38)))/('Deal Economics long'!$AF$20*F$35) -> 52.855692 | G38: =($E$26+$E$27*(1+$C38)*($H$2-0.025)/(1.025*($H$2-$C38)))/('Deal Economics long'!$AF$20*G$35) -> 45.304879 | H38: =($E$26+$E$27*(1+$C38)*($H$2-0.025)/(1.025*($H$2-$C38)))/('Deal Economics long'!$AF$20*H$35) -> 39.641769 | I38: =($E$26+$E$27*(1+$C38)*($H$2-0.025)/(1.025*($H$2-$C38)))/('Deal Economics long'!$AF$20*I$35) -> 31.713415 | J38: =($E$26+$E$27*(1+$C38)*($H$2-0.025)/(1.025*($H$2-$C38)))/('Deal Economics long'!$AF$20*J$35) -> 26.427846 | K38: =($E$26+$E$27*(1+$C38)*($H$2-0.025)/(1.025*($H$2-$C38)))/('Deal Economics long'!$AF$20*K$35) -> 19.820884 | ... O38: =($E$26+$E$27*(1+$C38)*($H$2-0.025)/(1.025*($H$2-$C38)))/('Deal Economics long'!$AF$20*O$35) -> 5.2855692
C39: 0.025 | D39: =($E$26+$E$27*(1+$C39)*($H$2-0.025)/(1.025*($H$2-$C39)))/('Deal Economics long'!$AF$20*D$35) -> 81.487786 | E39: =($E$26+$E$27*(1+$C39)*($H$2-0.025)/(1.025*($H$2-$C39)))/('Deal Economics long'!$AF$20*E$35) -> 65.190229 | F39: =($E$26+$E$27*(1+$C39)*($H$2-0.025)/(1.025*($H$2-$C39)))/('Deal Economics long'!$AF$20*F$35) -> 54.325191 | G39: =($E$26+$E$27*(1+$C39)*($H$2-0.025)/(1.025*($H$2-$C39)))/('Deal Economics long'!$AF$20*G$35) -> 46.564449 | H39: =($E$26+$E$27*(1+$C39)*($H$2-0.025)/(1.025*($H$2-$C39)))/('Deal Economics long'!$AF$20*H$35) -> 40.743893 | I39: =($E$26+$E$27*(1+$C39)*($H$2-0.025)/(1.025*($H$2-$C39)))/('Deal Economics long'!$AF$20*I$35) -> 32.595114 | J39: =($E$26+$E$27*(1+$C39)*($H$2-0.025)/(1.025*($H$2-$C39)))/('Deal Economics long'!$AF$20*J$35) -> 27.162595 | K39: =($E$26+$E$27*(1+$C39)*($H$2-0.025)/(1.025*($H$2-$C39)))/('Deal Economics long'!$AF$20*K$35) -> 20.371947 | ... O39: =($E$26+$E$27*(1+$C39)*($H$2-0.025)/(1.025*($H$2-$C39)))/('Deal Economics long'!$AF$20*O$35) -> 5.4325191
C40: 0.03 | D40: =($E$26+$E$27*(1+$C40)*($H$2-0.025)/(1.025*($H$2-$C40)))/('Deal Economics long'!$AF$20*D$35) -> 83.936951 | E40: =($E$26+$E$27*(1+$C40)*($H$2-0.025)/(1.025*($H$2-$C40)))/('Deal Economics long'!$AF$20*E$35) -> 67.149561 | F40: =($E$26+$E$27*(1+$C40)*($H$2-0.025)/(1.025*($H$2-$C40)))/('Deal Economics long'!$AF$20*F$35) -> 55.957968 | G40: =($E$26+$E$27*(1+$C40)*($H$2-0.025)/(1.025*($H$2-$C40)))/('Deal Economics long'!$AF$20*G$35) -> 47.963972 | H40: =($E$26+$E$27*(1+$C40)*($H$2-0.025)/(1.025*($H$2-$C40)))/('Deal Economics long'!$AF$20*H$35) -> 41.968476 | I40: =($E$26+$E$27*(1+$C40)*($H$2-0.025)/(1.025*($H$2-$C40)))/('Deal Economics long'!$AF$20*I$35) -> 33.574781 | J40: =($E$26+$E$27*(1+$C40)*($H$2-0.025)/(1.025*($H$2-$C40)))/('Deal Economics long'!$AF$20*J$35) -> 27.978984 | K40: =($E$26+$E$27*(1+$C40)*($H$2-0.025)/(1.025*($H$2-$C40)))/('Deal Economics long'!$AF$20*K$35) -> 20.984238 | ... O40: =($E$26+$E$27*(1+$C40)*($H$2-0.025)/(1.025*($H$2-$C40)))/('Deal Economics long'!$AF$20*O$35) -> 5.5957968
C41: 0.035 | D41: =($E$26+$E$27*(1+$C41)*($H$2-0.025)/(1.025*($H$2-$C41)))/('Deal Economics long'!$AF$20*D$35) -> 86.674254 | E41: =($E$26+$E$27*(1+$C41)*($H$2-0.025)/(1.025*($H$2-$C41)))/('Deal Economics long'!$AF$20*E$35) -> 69.339403 | F41: =($E$26+$E$27*(1+$C41)*($H$2-0.025)/(1.025*($H$2-$C41)))/('Deal Economics long'!$AF$20*F$35) -> 57.782836 | G41: =($E$26+$E$27*(1+$C41)*($H$2-0.025)/(1.025*($H$2-$C41)))/('Deal Economics long'!$AF$20*G$35) -> 49.528145 | H41: =($E$26+$E$27*(1+$C41)*($H$2-0.025)/(1.025*($H$2-$C41)))/('Deal Economics long'!$AF$20*H$35) -> 43.337127 | I41: =($E$26+$E$27*(1+$C41)*($H$2-0.025)/(1.025*($H$2-$C41)))/('Deal Economics long'!$AF$20*I$35) -> 34.669701 | J41: =($E$26+$E$27*(1+$C41)*($H$2-0.025)/(1.025*($H$2-$C41)))/('Deal Economics long'!$AF$20*J$35) -> 28.891418 | K41: =($E$26+$E$27*(1+$C41)*($H$2-0.025)/(1.025*($H$2-$C41)))/('Deal Economics long'!$AF$20*K$35) -> 21.668563 | ... O41: =($E$26+$E$27*(1+$C41)*($H$2-0.025)/(1.025*($H$2-$C41)))/('Deal Economics long'!$AF$20*O$35) -> 5.7782836
C42: 0.04 | D42: =($E$26+$E$27*(1+$C42)*($H$2-0.025)/(1.025*($H$2-$C42)))/('Deal Economics long'!$AF$20*D$35) -> 89.753719 | E42: =($E$26+$E$27*(1+$C42)*($H$2-0.025)/(1.025*($H$2-$C42)))/('Deal Economics long'!$AF$20*E$35) -> 71.802975 | F42: =($E$26+$E$27*(1+$C42)*($H$2-0.025)/(1.025*($H$2-$C42)))/('Deal Economics long'!$AF$20*F$35) -> 59.835812 | G42: =($E$26+$E$27*(1+$C42)*($H$2-0.025)/(1.025*($H$2-$C42)))/('Deal Economics long'!$AF$20*G$35) -> 51.287839 | H42: =($E$26+$E$27*(1+$C42)*($H$2-0.025)/(1.025*($H$2-$C42)))/('Deal Economics long'!$AF$20*H$35) -> 44.876859 | I42: =($E$26+$E$27*(1+$C42)*($H$2-0.025)/(1.025*($H$2-$C42)))/('Deal Economics long'!$AF$20*I$35) -> 35.901487 | J42: =($E$26+$E$27*(1+$C42)*($H$2-0.025)/(1.025*($H$2-$C42)))/('Deal Economics long'!$AF$20*J$35) -> 29.917906 | K42: =($E$26+$E$27*(1+$C42)*($H$2-0.025)/(1.025*($H$2-$C42)))/('Deal Economics long'!$AF$20*K$35) -> 22.43843 | ... O42: =($E$26+$E$27*(1+$C42)*($H$2-0.025)/(1.025*($H$2-$C42)))/('Deal Economics long'!$AF$20*O$35) -> 5.9835812
C43: 0.045 | D43: =($E$26+$E$27*(1+$C43)*($H$2-0.025)/(1.025*($H$2-$C43)))/('Deal Economics long'!$AF$20*D$35) -> 93.243779 | E43: =($E$26+$E$27*(1+$C43)*($H$2-0.025)/(1.025*($H$2-$C43)))/('Deal Economics long'!$AF$20*E$35) -> 74.595023 | F43: =($E$26+$E$27*(1+$C43)*($H$2-0.025)/(1.025*($H$2-$C43)))/('Deal Economics long'!$AF$20*F$35) -> 62.162519 | G43: =($E$26+$E$27*(1+$C43)*($H$2-0.025)/(1.025*($H$2-$C43)))/('Deal Economics long'!$AF$20*G$35) -> 53.282159 | H43: =($E$26+$E$27*(1+$C43)*($H$2-0.025)/(1.025*($H$2-$C43)))/('Deal Economics long'!$AF$20*H$35) -> 46.62189 | I43: =($E$26+$E$27*(1+$C43)*($H$2-0.025)/(1.025*($H$2-$C43)))/('Deal Economics long'!$AF$20*I$35) -> 37.297512 | J43: =($E$26+$E$27*(1+$C43)*($H$2-0.025)/(1.025*($H$2-$C43)))/('Deal Economics long'!$AF$20*J$35) -> 31.08126 | K43: =($E$26+$E$27*(1+$C43)*($H$2-0.025)/(1.025*($H$2-$C43)))/('Deal Economics long'!$AF$20*K$35) -> 23.310945 | ... O43: =($E$26+$E$27*(1+$C43)*($H$2-0.025)/(1.025*($H$2-$C43)))/('Deal Economics long'!$AF$20*O$35) -> 6.2162519
C44: 0.05 | D44: =($E$26+$E$27*(1+$C44)*($H$2-0.025)/(1.025*($H$2-$C44)))/('Deal Economics long'!$AF$20*D$35) -> 97.232419 | E44: =($E$26+$E$27*(1+$C44)*($H$2-0.025)/(1.025*($H$2-$C44)))/('Deal Economics long'!$AF$20*E$35) -> 77.785936 | F44: =($E$26+$E$27*(1+$C44)*($H$2-0.025)/(1.025*($H$2-$C44)))/('Deal Economics long'!$AF$20*F$35) -> 64.821613 | G44: =($E$26+$E$27*(1+$C44)*($H$2-0.025)/(1.025*($H$2-$C44)))/('Deal Economics long'!$AF$20*G$35) -> 55.561383 | H44: =($E$26+$E$27*(1+$C44)*($H$2-0.025)/(1.025*($H$2-$C44)))/('Deal Economics long'!$AF$20*H$35) -> 48.61621 | I44: =($E$26+$E$27*(1+$C44)*($H$2-0.025)/(1.025*($H$2-$C44)))/('Deal Economics long'!$AF$20*I$35) -> 38.892968 | J44: =($E$26+$E$27*(1+$C44)*($H$2-0.025)/(1.025*($H$2-$C44)))/('Deal Economics long'!$AF$20*J$35) -> 32.410806 | K44: =($E$26+$E$27*(1+$C44)*($H$2-0.025)/(1.025*($H$2-$C44)))/('Deal Economics long'!$AF$20*K$35) -> 24.308105 | ... O44: =($E$26+$E$27*(1+$C44)*($H$2-0.025)/(1.025*($H$2-$C44)))/('Deal Economics long'!$AF$20*O$35) -> 6.4821613
...

Sheet Deal Economics
B2: Date: | C2: 46085 | E2: Discount Rate: | G2: 0.12 | I2: Levered Discount Rate: | L2: 0.12
B4: IREN - MSFT Deal ($mm) | E4: 2026 | F4: 2027 | G4: 2028 | H4: 2029 | I4: 2030 | J4: 2031 | L4: Notes | O4: 4.5 GW | S4: Notes
B5: Revenue | E5: 485 | F5: 1940 | G5: 1940 | H5: 1940 | I5: 1940 | J5: 1455 | L5: $9.7B Total | O5: Pre Payment | Q5: =E15*22.55 -> 43747 | S5: 1920*(4510/200)
B6: OpEx ex D&A | E6: =E5-E7 -> 72.75 | F6: =F5-F7 -> 291 | G6: =G5-G7 -> 291 | H6: =H5-H7 -> 291 | I6: =I5-I7 -> 291 | J6: =J5-J7 -> 218.25 | O6: Equity | Q6: =4160*22.55 -> 93808 | S6: 4160*(4510/200)
B7: EBITDA | E7: =E5*0.85 -> 412.25 | F7: =F5*0.85 -> 1649 | G7: =G5*0.85 -> 1649 | H7: =H5*0.85 -> 1649 | I7: =I5*0.85 -> 1649 | J7: =J5*0.85 -> 1236.75 | O7: Debt | Q7: =E24*22.55 -> 81180 | S7: 3600*(4510/200)
B8: EBITDA Margin | E8: =E7/E5 -> 0.85 | F8: =F7/F5 -> 0.85 | G8: =G7/G5 -> 0.85 | H8: =H7/H5 -> 0.85 | I8: =I7/I5 -> 0.85 | J8: =J7/J5 -> 0.85 | O8: Total | Q8: =SUM(Q5:Q7) -> 218735 | T8: =Q7/Q8 -> 0.37113402
B10: GPU D&A | E10: =4640/5*0.25 -> 232 | F10: =4640/5 -> 928 | G10: =4640/5 -> 928 | H10: =4640/5 -> 928 | I10: =4640/5 -> 928 | J10: =4640/5*0.75 -> 696 | L10: 5 Year Life on 5800-1688
B11: Data Center D&A | E11: =$E$16*-0.05 -> 112.5 | F11: =$E$16*-0.05 -> 112.5 | G11: =$E$16*-0.05 -> 112.5 | H11: =$E$16*-0.05 -> 112.5 | I11: =$E$16*-0.05 -> 112.5 | J11: =$E$16*-0.05 -> 112.5
B12: EBIT | E12: =E7-E10-E11 -> 67.75 | F12: =F7-F10-F11 -> 608.5 | G12: =G7-G10-G11 -> 608.5 | H12: =H7-H10-H11 -> 608.5 | I12: =I7-I10-I11 -> 608.5 | J12: =J7-J10-J11 -> 428.25
B14: EBITDA | E14: =E7 -> 412.25 | F14: =F7 -> 1649 | G14: =G7 -> 1649 | H14: =H7 -> 1649 | I14: =I7 -> 1649 | J14: =J7 -> 1236.75
B15: MSFT Pre Payment | E15: 1940 | F15: 0 | G15: =$E$15/-4 -> -485 | H15: =$E$15/-4 -> -485 | I15: =$E$15/-4 -> -485 | J15: =$E$15/-4 -> -485
B16: Data Center CapEx | E16: =-3000*0.75 -> -2250 | F16: =-3000*0.25 -> -750 | L16: $15M/MW x 200MW
B17: GPU CapEx | E17: =-5800*0.75 -> -4350 | F17: =-5800*0.25 -> -1450 | L17: $5.8B Total
B18: Data Center Maintenance | F18: =-0.5*200 -> -100 | G18: =-0.5*200 -> -100 | H18: =-0.5*200 -> -100 | I18: =-0.5*200 -> -100 | J18: =-0.5*200 -> -100 | L18: $500k/MW
B19: GPU Residual Value | J19: =(E17+F17)*-0.2 -> 1160
B20: Data Center Residual Value | J20: =E16*-0.75 -> 1687.5
B22: Unlevered Cash Flow | E22: =E14+E15+E16+E17 -> -4247.75 | F22: =SUM(F14:F18) -> -651 | G22: =G14+G15+G18 -> 1064 | H22: =H14+H15+H18 -> 1064 | I22: =I14+I15+I18 -> 1064 | J22: =J14+J18+J15+J19+J20 -> 3499.25
B24: Debt Drawdown | E24: 3600
B25: Interest Expense | E25: =(($E$24*-0.06)*0.75) -> -162 | F25: =($E$24*-0.06) -> -216 | G25: =($E$24*-0.06) -> -216 | H25: =($E$24*-0.06) -> -216 | I25: =($E$24*-0.06) -> -216 | J25: =$E$24*-0.06*0.5 -> -108 | L25: 6% p.a.
B26: Debt Repayment | J26: =-E24 -> -3600
B28: Levered Cash Flow | E28: =E22+E24+E25 -> -809.75 | F28: =F22+F25 -> -867 | G28: =G22+G25 -> 848 | H28: =H22+H25 -> 848 | I28: =I22+I25 -> 848 | J28: =J22+J25+J26 -> -208.75
B30: PV of Unlevered Cash Flow | E30: =E22/((1+$G$2)^(E$4-YEAR($C$2)+0.5)) -> -4013.7465 | F30: =F22/((1+$G$2)^(F$4-YEAR($C$2)+0.5)) -> -549.22962 | G30: =G22/((1+$G$2)^(G$4-YEAR($C$2)+0.5)) -> 801.48716 | H30: =H22/((1+$G$2)^(H$4-YEAR($C$2)+0.5)) -> 715.61354 | I30: =I22/((1+$G$2)^(I$4-YEAR($C$2)+0.5)) -> 638.94066 | J30: =J22/((1+$G$2)^(J$4-YEAR($C$2)+0.5)) -> 1876.1858 | L30: Mid-year discounting
B31: PV of Levered Cash Flow | E31: =E28/((1+$L$2)^(E$4-YEAR($C$2)+0.5)) -> -765.14183 | F31: =F28/((1+$L$2)^(F$4-YEAR($C$2)+0.5)) -> -731.4625 | G31: =G28/((1+$L$2)^(G$4-YEAR($C$2)+0.5)) -> 638.77924 | H31: =H28/((1+$L$2)^(H$4-YEAR($C$2)+0.5)) -> 570.33861 | I31: =I28/((1+$L$2)^(I$4-YEAR($C$2)+0.5)) -> 509.2309 | J31: =J28/((1+$L$2)^(J$4-YEAR($C$2)+0.5)) -> -111.92507 | L31: Mid-year discounting
B33: NPV | E33: =SUM(E30:J30) -> -530.74893 | G33: GPU Count | J33: 77000
B34: Equity NPV | E34: =SUM(E31:J31) -> 109.81936 | G34: GPU/Hour | J34: =9700000000/(J33*43800) -> 2.8761193
B35: Unlevered IRR | E35: =IRR(E22:J22) -> 0.084059411 | G35: Unlevered CF per MW | J35: =SUM(E22:J22)/200 -> 8.9625
B36: Levered IRR | E36: =IRR(E28:J28) -> 0.15518825 | G36: Levered CF per MW | J36: =SUM(E28:J28)/200 -> 3.2925

Sheet Deal Economics long
B2: Date: | C2: 46085 | E2: Discount Rate: | G2: 0.12 | I2: Levered Discount Rate: | L2: 0.12
B4: IREN - MSFT Deal ($mm) | E4: 2026 | F4: 2027 | G4: 2028 | H4: 2029 | I4: 2030 | J4: 2031 | K4: =J4+1 -> 2032 | L4: =K4+1 -> 2033 | M4: =L4+1 -> 2034 | N4: =M4+1 -> 2035 | O4: =N4+1 -> 2036 | P4: =O4+1 -> 2037 | Q4: =P4+1 -> 2038 | R4: =Q4+1 -> 2039 | ... Y4: =X4+1 -> 2046 | Z4: 2047 | AA4: Notes | AD4: 4.5 GW | AH4: Notes | AK4: Stock Price Senstivity Table
B5: Revenue | E5: 485 | F5: 1940 | G5: 1940 | H5: 1940 | I5: 1940 | J5: 1455 | K5: 1940 | L5: 1940 | M5: 1940 | N5: 1940 | O5: 1940 | P5: 1940 | Q5: 1940 | R5: 1940 | S5: 1940 | T5: 1940 | U5: 1940 | V5: 1940 | W5: 1940 | X5: 1940 | Y5: 1940 | AA5: $9.7B Total | AD5: Pre Payment | AF5: =(E16*4)*22.55 -> 174988 | AH5: 1920*(4510/200) | AM5: Dilution
B6: OpEx ex D&A | E6: =E5-E7 -> 72.75 | F6: =F5-F7 -> 291 | G6: =G5-G7 -> 291 | H6: =H5-H7 -> 291 | I6: =I5-I7 -> 291 | J6: =J5-J7 -> 218.25 | K6: =K5-K7 -> 291 | L6: =L5-L7 -> 291 | ... Y6: =Y5-Y7 -> 291 | AD6: Equity | AF6: =(4160)+((2200)*3)*22.55 -> 152990 | AH6: 4160*(4510/200) | AM6: 1 | AN6: 1.25 | AO6: 1.5 | AP6: 1.75 | AQ6: 2 | AR6: 2.5 | AS6: 3 | AT6: 4 | AU6: 5 | AV6: 10 | AW6: 12.5 | AX6: 15 | AY6: 17.5 | AZ6: 20
B7: EBITDA | E7: =E5*0.85 -> 412.25 | F7: =F5*0.85 -> 1649 | G7: =G5*0.85 -> 1649 | H7: =H5*0.85 -> 1649 | I7: =I5*0.85 -> 1649 | J7: =J5*0.85 -> 1236.75 | K7: =K5*0.85 -> 1649 | L7: =L5*0.85 -> 1649 | ... Y7: =Y5*0.85 -> 1649 | AD7: Debt | AF7: =(E25*4)*22.55 -> 324720 | AH7: 3600*(4510/200) | AK7: Terminal Growth Rate | AL7: 0.01 | AM7: =(($AF$15+((843*(1+$AL7)/($L$2-$AL7))*22.5)/((1+$L$2)^($Z$4-YEAR($C$2)+0.5)))/($AF$20*AM$6)) -> 95.618556 | AN7: =(($AF$15+((843*(1+$AL7)/($L$2-$AL7))*22.5)/((1+$L$2)^($Z$4-YEAR($C$2)+0.5)))/($AF$20*AN$6)) -> 76.494845 | AO7: =(($AF$15+((843*(1+$AL7)/($L$2-$AL7))*22.5)/((1+$L$2)^($Z$4-YEAR($C$2)+0.5)))/($AF$20*AO$6)) -> 63.745704 | AP7: =(($AF$15+((843*(1+$AL7)/($L$2-$AL7))*22.5)/((1+$L$2)^($Z$4-YEAR($C$2)+0.5)))/($AF$20*AP$6)) -> 54.639175 | AQ7: =(($AF$15+((843*(1+$AL7)/($L$2-$AL7))*22.5)/((1+$L$2)^($Z$4-YEAR($C$2)+0.5)))/($AF$20*AQ$6)) -> 47.809278 | AR7: =(($AF$15+((843*(1+$AL7)/($L$2-$AL7))*22.5)/((1+$L$2)^($Z$4-YEAR($C$2)+0.5)))/($AF$20*AR$6)) -> 38.247422 | AS7: =(($AF$15+((843*(1+$AL7)/($L$2-$AL7))*22.5)/((1+$L$2)^($Z$4-YEAR($C$2)+0.5)))/($AF$20*AS$6)) -> 31.872852 | AT7: =(($AF$15+((843*(1+$AL7)/($L$2-$AL7))*22.5)/((1+$L$2)^($Z$4-YEAR($C$2)+0.5)))/($AF$20*AT$6)) -> 23.904639 | ... AZ7: =(($AF$15+((843*(1+$AL7)/($L$2-$AL7))*22.5)/((1+$L$2)^($Z$4-YEAR($C$2)+0.5)))/($AF$20*AZ$6)) -> 4.7809278
B8: EBITDA Margin | E8: =E7/E5 -> 0.85 | F8: =F7/F5 -> 0.85 | G8: =G7/G5 -> 0.85 | H8: =H7/H5 -> 0.85 | I8: =I7/I5 -> 0.85 | J8: =J7/J5 -> 0.85 | K8: =K7/K5 -> 0.85 | L8: =L7/L5 -> 0.85 | ... Y8: =Y7/Y5 -> 0.85 | AD8: Total | AF8: =SUM(AF5:AF7) -> 652698 | AL8: 0.015 | AM8: =(($AF$15+((843*(1+$AL8)/($L$2-$AL8))*22.5)/((1+$L$2)^($Z$4-YEAR($C$2)+0.5)))/($AF$20*AM$6)) -> 98.045299 | AN8: =(($AF$15+((843*(1+$AL8)/($L$2-$AL8))*22.5)/((1+$L$2)^($Z$4-YEAR($C$2)+0.5)))/($AF$20*AN$6)) -> 78.436239 | AO8: =(($AF$15+((843*(1+$AL8)/($L$2-$AL8))*22.5)/((1+$L$2)^($Z$4-YEAR($C$2)+0.5)))/($AF$20*AO$6)) -> 65.363532 | AP8: =(($AF$15+((843*(1+$AL8)/($L$2-$AL8))*22.5)/((1+$L$2)^($Z$4-YEAR($C$2)+0.5)))/($AF$20*AP$6)) -> 56.025885 | AQ8: =(($AF$15+((843*(1+$AL8)/($L$2-$AL8))*22.5)/((1+$L$2)^($Z$4-YEAR($C$2)+0.5)))/($AF$20*AQ$6)) -> 49.022649 | AR8: =(($AF$15+((843*(1+$AL8)/($L$2-$AL8))*22.5)/((1+$L$2)^($Z$4-YEAR($C$2)+0.5)))/($AF$20*AR$6)) -> 39.218119 | AS8: =(($AF$15+((843*(1+$AL8)/($L$2-$AL8))*22.5)/((1+$L$2)^($Z$4-YEAR($C$2)+0.5)))/($AF$20*AS$6)) -> 32.681766 | AT8: =(($AF$15+((843*(1+$AL8)/($L$2-$AL8))*22.5)/((1+$L$2)^($Z$4-YEAR($C$2)+0.5)))/($AF$20*AT$6)) -> 24.511325 | ... AZ8: =(($AF$15+((843*(1+$AL8)/($L$2-$AL8))*22.5)/((1+$L$2)^($Z$4-YEAR($C$2)+0.5)))/($AF$20*AZ$6)) -> 4.9022649
AL9: 0.02 | AM9: =(($AF$15+((843*(1+$AL9)/($L$2-$AL9))*22.5)/((1+$L$2)^($Z$4-YEAR($C$2)+0.5)))/($AF$20*AM$6)) -> 100.71472 | AN9: =(($AF$15+((843*(1+$AL9)/($L$2-$AL9))*22.5)/((1+$L$2)^($Z$4-YEAR($C$2)+0.5)))/($AF$20*AN$6)) -> 80.571772 | AO9: =(($AF$15+((843*(1+$AL9)/($L$2-$AL9))*22.5)/((1+$L$2)^($Z$4-YEAR($C$2)+0.5)))/($AF$20*AO$6)) -> 67.143144 | AP9: =(($AF$15+((843*(1+$AL9)/($L$2-$AL9))*22.5)/((1+$L$2)^($Z$4-YEAR($C$2)+0.5)))/($AF$20*AP$6)) -> 57.551266 | AQ9: =(($AF$15+((843*(1+$AL9)/($L$2-$AL9))*22.5)/((1+$L$2)^($Z$4-YEAR($C$2)+0.5)))/($AF$20*AQ$6)) -> 50.357358 | AR9: =(($AF$15+((843*(1+$AL9)/($L$2-$AL9))*22.5)/((1+$L$2)^($Z$4-YEAR($C$2)+0.5)))/($AF$20*AR$6)) -> 40.285886 | AS9: =(($AF$15+((843*(1+$AL9)/($L$2-$AL9))*22.5)/((1+$L$2)^($Z$4-YEAR($C$2)+0.5)))/($AF$20*AS$6)) -> 33.571572 | AT9: =(($AF$15+((843*(1+$AL9)/($L$2-$AL9))*22.5)/((1+$L$2)^($Z$4-YEAR($C$2)+0.5)))/($AF$20*AT$6)) -> 25.178679 | ... AZ9: =(($AF$15+((843*(1+$AL9)/($L$2-$AL9))*22.5)/((1+$L$2)^($Z$4-YEAR($C$2)+0.5)))/($AF$20*AZ$6)) -> 5.0357358
B10: GPU D&A | E10: =4640/5*0.25 -> 232 | F10: =4640/5 -> 928 | G10: =4640/5 -> 928 | H10: =4640/5 -> 928 | I10: =4640/5 -> 928 | J10: =4640/5*0.75 -> 696 | K10: =4640/5 -> 928 | L10: =4640/5 -> 928 | M10: =4640/5 -> 928 | N10: =4640/5 -> 928 | O10: =4640/5 -> 928 | P10: =4640/5 -> 928 | Q10: =4640/5 -> 928 | R10: =4640/5 -> 928 | ... Y10: =4640/5 -> 928 | AA10: 5 Year Life on 5800-1160 | AD10: Unlevered FCF | AF10: =SUM(E23:Y23)*22.5 -> 165830.06 | AL10: 0.025 | AM10: =(($AF$15+((843*(1+$AL10)/($L$2-$AL10))*22.5)/((1+$L$2)^($Z$4-YEAR($C$2)+0.5)))/($AF$20*AM$6)) -> 103.66512 | AN10: =(($AF$15+((843*(1+$AL10)/($L$2-$AL10))*22.5)/((1+$L$2)^($Z$4-YEAR($C$2)+0.5)))/($AF$20*AN$6)) -> 82.932099 | AO10: =(($AF$15+((843*(1+$AL10)/($L$2-$AL10))*22.5)/((1+$L$2)^($Z$4-YEAR($C$2)+0.5)))/($AF$20*AO$6)) -> 69.110083 | AP10: =(($AF$15+((843*(1+$AL10)/($L$2-$AL10))*22.5)/((1+$L$2)^($Z$4-YEAR($C$2)+0.5)))/($AF$20*AP$6)) -> 59.237214 | AQ10: =(($AF$15+((843*(1+$AL10)/($L$2-$AL10))*22.5)/((1+$L$2)^($Z$4-YEAR($C$2)+0.5)))/($AF$20*AQ$6)) -> 51.832562 | AR10: =(($AF$15+((843*(1+$AL10)/($L$2-$AL10))*22.5)/((1+$L$2)^($Z$4-YEAR($C$2)+0.5)))/($AF$20*AR$6)) -> 41.46605 | AS10: =(($AF$15+((843*(1+$AL10)/($L$2-$AL10))*22.5)/((1+$L$2)^($Z$4-YEAR($C$2)+0.5)))/($AF$20*AS$6)) -> 34.555041 | AT10: =(($AF$15+((843*(1+$AL10)/($L$2-$AL10))*22.5)/((1+$L$2)^($Z$4-YEAR($C$2)+0.5)))/($AF$20*AT$6)) -> 25.916281 | ... AZ10: =(($AF$15+((843*(1+$AL10)/($L$2-$AL10))*22.5)/((1+$L$2)^($Z$4-YEAR($C$2)+0.5)))/($AF$20*AZ$6)) -> 5.1832562
B11: Data Center D&A | E11: =$E$17*-0.05 -> 112.5 | F11: =$E$17*-0.05 -> 112.5 | G11: =$E$17*-0.05 -> 112.5 | H11: =$E$17*-0.05 -> 112.5 | I11: =$E$17*-0.05 -> 112.5 | J11: =$E$17*-0.05 -> 112.5 | K11: =$E$17*-0.05 -> 112.5 | L11: =$E$17*-0.05 -> 112.5 | ... Y11: =$E$17*-0.05 -> 112.5 | AD11: Levered FCF | AF11: =SUM(E29:Y29)*22.5 -> 84145.613 | AL11: 0.03 | AM11: =(($AF$15+((843*(1+$AL11)/($L$2-$AL11))*22.5)/((1+$L$2)^($Z$4-YEAR($C$2)+0.5)))/($AF$20*AM$6)) -> 106.94336 | AN11: =(($AF$15+((843*(1+$AL11)/($L$2-$AL11))*22.5)/((1+$L$2)^($Z$4-YEAR($C$2)+0.5)))/($AF$20*AN$6)) -> 85.554684 | AO11: =(($AF$15+((843*(1+$AL11)/($L$2-$AL11))*22.5)/((1+$L$2)^($Z$4-YEAR($C$2)+0.5)))/($AF$20*AO$6)) -> 71.29557 | AP11: =(($AF$15+((843*(1+$AL11)/($L$2-$AL11))*22.5)/((1+$L$2)^($Z$4-YEAR($C$2)+0.5)))/($AF$20*AP$6)) -> 61.110489 | AQ11: =(($AF$15+((843*(1+$AL11)/($L$2-$AL11))*22.5)/((1+$L$2)^($Z$4-YEAR($C$2)+0.5)))/($AF$20*AQ$6)) -> 53.471678 | AR11: =(($AF$15+((843*(1+$AL11)/($L$2-$AL11))*22.5)/((1+$L$2)^($Z$4-YEAR($C$2)+0.5)))/($AF$20*AR$6)) -> 42.777342 | AS11: =(($AF$15+((843*(1+$AL11)/($L$2-$AL11))*22.5)/((1+$L$2)^($Z$4-YEAR($C$2)+0.5)))/($AF$20*AS$6)) -> 35.647785 | AT11: =(($AF$15+((843*(1+$AL11)/($L$2-$AL11))*22.5)/((1+$L$2)^($Z$4-YEAR($C$2)+0.5)))/($AF$20*AT$6)) -> 26.735839 | ... AZ11: =(($AF$15+((843*(1+$AL11)/($L$2-$AL11))*22.5)/((1+$L$2)^($Z$4-YEAR($C$2)+0.5)))/($AF$20*AZ$6)) -> 5.3471678
B12: EBIT | E12: =E7-E10-E11 -> 67.75 | F12: =F7-F10-F11 -> 608.5 | G12: =G7-G10-G11 -> 608.5 | H12: =H7-H10-H11 -> 608.5 | I12: =I7-I10-I11 -> 608.5 | J12: =J7-J10-J11 -> 428.25 | K12: =K7-K10-K11 -> 608.5 | L12: =L7-L10-L11 -> 608.5 | ... Y12: =Y7-Y10-Y11 -> 608.5 | AL12: 0.035 | AM12: =(($AF$15+((843*(1+$AL12)/($L$2-$AL12))*22.5)/((1+$L$2)^($Z$4-YEAR($C$2)+0.5)))/($AF$20*AM$6)) -> 110.60726 | AN12: =(($AF$15+((843*(1+$AL12)/($L$2-$AL12))*22.5)/((1+$L$2)^($Z$4-YEAR($C$2)+0.5)))/($AF$20*AN$6)) -> 88.485809 | AO12: =(($AF$15+((843*(1+$AL12)/($L$2-$AL12))*22.5)/((1+$L$2)^($Z$4-YEAR($C$2)+0.5)))/($AF$20*AO$6)) -> 73.738174 | AP12: =(($AF$15+((843*(1+$AL12)/($L$2-$AL12))*22.5)/((1+$L$2)^($Z$4-YEAR($C$2)+0.5)))/($AF$20*AP$6)) -> 63.204149 | AQ12: =(($AF$15+((843*(1+$AL12)/($L$2-$AL12))*22.5)/((1+$L$2)^($Z$4-YEAR($C$2)+0.5)))/($AF$20*AQ$6)) -> 55.30363 | AR12: =(($AF$15+((843*(1+$AL12)/($L$2-$AL12))*22.5)/((1+$L$2)^($Z$4-YEAR($C$2)+0.5)))/($AF$20*AR$6)) -> 44.242904 | AS12: =(($AF$15+((843*(1+$AL12)/($L$2-$AL12))*22.5)/((1+$L$2)^($Z$4-YEAR($C$2)+0.5)))/($AF$20*AS$6)) -> 36.869087 | AT12: =(($AF$15+((843*(1+$AL12)/($L$2-$AL12))*22.5)/((1+$L$2)^($Z$4-YEAR($C$2)+0.5)))/($AF$20*AT$6)) -> 27.651815 | ... AZ12: =(($AF$15+((843*(1+$AL12)/($L$2-$AL12))*22.5)/((1+$L$2)^($Z$4-YEAR($C$2)+0.5)))/($AF$20*AZ$6)) -> 5.530363
B13: Taxes | E13: =E12*0.17 -> 11.5175 | F13: =F12*0.17 -> 103.445 | G13: =G12*0.17 -> 103.445 | H13: =H12*0.17 -> 103.445 | I13: =I12*0.17 -> 103.445 | J13: =J12*0.17 -> 72.8025 | K13: =K12*0.17 -> 103.445 | L13: =L12*0.17 -> 103.445 | ... Y13: =Y12*0.17 -> 103.445 | AL13: 0.04 | AM13: =(($AF$15+((843*(1+$AL13)/($L$2-$AL13))*22.5)/((1+$L$2)^($Z$4-YEAR($C$2)+0.5)))/($AF$20*AM$6)) -> 114.72915 | AN13: =(($AF$15+((843*(1+$AL13)/($L$2-$AL13))*22.5)/((1+$L$2)^($Z$4-YEAR($C$2)+0.5)))/($AF$20*AN$6)) -> 91.783324 | AO13: =(($AF$15+((843*(1+$AL13)/($L$2-$AL13))*22.5)/((1+$L$2)^($Z$4-YEAR($C$2)+0.5)))/($AF$20*AO$6)) -> 76.486103 | AP13: =(($AF$15+((843*(1+$AL13)/($L$2-$AL13))*22.5)/((1+$L$2)^($Z$4-YEAR($C$2)+0.5)))/($AF$20*AP$6)) -> 65.559517 | AQ13: =(($AF$15+((843*(1+$AL13)/($L$2-$AL13))*22.5)/((1+$L$2)^($Z$4-YEAR($C$2)+0.5)))/($AF$20*AQ$6)) -> 57.364577 | AR13: =(($AF$15+((843*(1+$AL13)/($L$2-$AL13))*22.5)/((1+$L$2)^($Z$4-YEAR($C$2)+0.5)))/($AF$20*AR$6)) -> 45.891662 | AS13: =(($AF$15+((843*(1+$AL13)/($L$2-$AL13))*22.5)/((1+$L$2)^($Z$4-YEAR($C$2)+0.5)))/($AF$20*AS$6)) -> 38.243052 | AT13: =(($AF$15+((843*(1+$AL13)/($L$2-$AL13))*22.5)/((1+$L$2)^($Z$4-YEAR($C$2)+0.5)))/($AF$20*AT$6)) -> 28.682289 | ... AZ13: =(($AF$15+((843*(1+$AL13)/($L$2-$AL13))*22.5)/((1+$L$2)^($Z$4-YEAR($C$2)+0.5)))/($AF$20*AZ$6)) -> 5.7364577
AD14: PV of Unlevered FCF | AF14: =E34*22.5 -> -13103.971 | AL14: 0.045 | AM14: =(($AF$15+((843*(1+$AL14)/($L$2-$AL14))*22.5)/((1+$L$2)^($Z$4-YEAR($C$2)+0.5)))/($AF$20*AM$6)) -> 119.40063 | AN14: =(($AF$15+((843*(1+$AL14)/($L$2-$AL14))*22.5)/((1+$L$2)^($Z$4-YEAR($C$2)+0.5)))/($AF$20*AN$6)) -> 95.520507 | AO14: =(($AF$15+((843*(1+$AL14)/($L$2-$AL14))*22.5)/((1+$L$2)^($Z$4-YEAR($C$2)+0.5)))/($AF$20*AO$6)) -> 79.600423 | AP14: =(($AF$15+((843*(1+$AL14)/($L$2-$AL14))*22.5)/((1+$L$2)^($Z$4-YEAR($C$2)+0.5)))/($AF$20*AP$6)) -> 68.228934 | AQ14: =(($AF$15+((843*(1+$AL14)/($L$2-$AL14))*22.5)/((1+$L$2)^($Z$4-YEAR($C$2)+0.5)))/($AF$20*AQ$6)) -> 59.700317 | AR14: =(($AF$15+((843*(1+$AL14)/($L$2-$AL14))*22.5)/((1+$L$2)^($Z$4-YEAR($C$2)+0.5)))/($AF$20*AR$6)) -> 47.760254 | AS14: =(($AF$15+((843*(1+$AL14)/($L$2-$AL14))*22.5)/((1+$L$2)^($Z$4-YEAR($C$2)+0.5)))/($AF$20*AS$6)) -> 39.800211 | AT14: =(($AF$15+((843*(1+$AL14)/($L$2-$AL14))*22.5)/((1+$L$2)^($Z$4-YEAR($C$2)+0.5)))/($AF$20*AT$6)) -> 29.850159 | ... AZ14: =(($AF$15+((843*(1+$AL14)/($L$2-$AL14))*22.5)/((1+$L$2)^($Z$4-YEAR($C$2)+0.5)))/($AF$20*AZ$6)) -> 5.9700317
B15: EBITDA | E15: =E7 -> 412.25 | F15: =F7 -> 1649 | G15: =G7 -> 1649 | H15: =H7 -> 1649 | I15: =I7 -> 1649 | J15: =J7 -> 1236.75 | K15: =K7 -> 1649 | L15: =L7 -> 1649 | ... Y15: =Y7 -> 1649 | AD15: PV of Levered FCF | AF15: =E35*22.5 -> 16460.012 | AL15: 0.05 | AM15: =(($AF$15+((843*(1+$AL15)/($L$2-$AL15))*22.5)/((1+$L$2)^($Z$4-YEAR($C$2)+0.5)))/($AF$20*AM$6)) -> 124.73947 | AN15: =(($AF$15+((843*(1+$AL15)/($L$2-$AL15))*22.5)/((1+$L$2)^($Z$4-YEAR($C$2)+0.5)))/($AF$20*AN$6)) -> 99.791574 | AO15: =(($AF$15+((843*(1+$AL15)/($L$2-$AL15))*22.5)/((1+$L$2)^($Z$4-YEAR($C$2)+0.5)))/($AF$20*AO$6)) -> 83.159645 | AP15: =(($AF$15+((843*(1+$AL15)/($L$2-$AL15))*22.5)/((1+$L$2)^($Z$4-YEAR($C$2)+0.5)))/($AF$20*AP$6)) -> 71.279696 | AQ15: =(($AF$15+((843*(1+$AL15)/($L$2-$AL15))*22.5)/((1+$L$2)^($Z$4-YEAR($C$2)+0.5)))/($AF$20*AQ$6)) -> 62.369734 | AR15: =(($AF$15+((843*(1+$AL15)/($L$2-$AL15))*22.5)/((1+$L$2)^($Z$4-YEAR($C$2)+0.5)))/($AF$20*AR$6)) -> 49.895787 | AS15: =(($AF$15+((843*(1+$AL15)/($L$2-$AL15))*22.5)/((1+$L$2)^($Z$4-YEAR($C$2)+0.5)))/($AF$20*AS$6)) -> 41.579823 | AT15: =(($AF$15+((843*(1+$AL15)/($L$2-$AL15))*22.5)/((1+$L$2)^($Z$4-YEAR($C$2)+0.5)))/($AF$20*AT$6)) -> 31.184867 | ... AZ15: =(($AF$15+((843*(1+$AL15)/($L$2-$AL15))*22.5)/((1+$L$2)^($Z$4-YEAR($C$2)+0.5)))/($AF$20*AZ$6)) -> 6.2369734
B16: MSFT Pre Payment | E16: 1940 | F16: 0 | G16: =$E$16/-4 -> -485 | H16: =$E$16/-4 -> -485 | I16: =$E$16/-4 -> -485 | J16: =$E$16/-4 -> -485 | K16: 1940 | L16: 0 | M16: =$K$16/-3 -> -646.66667 | N16: =$K$16/-3 -> -646.66667 | O16: =$K$16/-3 -> -646.66667 | P16: 1940 | Q16: 0 | R16: =$K$16/-3 -> -646.66667 | S16: =$K$16/-3 -> -646.66667 | T16: =$K$16/-3 -> -646.66667 | U16: 1940 | V16: 0 | W16: =$K$16/-3 -> -646.66667 | X16: =$K$16/-3 -> -646.66667 | Y16: =$K$16/-3 -> -646.66667 | AD16: Terminal Value | AF16: =Z32 -> 18641.884
B17: Data Center CapEx | E17: =-3000*0.75 -> -2250 | F17: =-3000*0.25 -> -750 | AA17: $15M/MW x 200MW | AD17: Levered Total | AF17: =SUM(AF15:AF16) -> 35101.896
B18: GPU CapEx | E18: =-5800*0.75 -> -4350 | F18: =-5800*0.25 -> -1450 | K18: =-5800 -> -5800 | P18: =-5800 -> -5800 | U18: =-5800 -> -5800 | AA18: $5.8B Total per deal
B19: Data Center Maintenance | F19: =-0.5*200 -> -100 | G19: =-0.5*200 -> -100 | H19: =-0.5*200 -> -100 | I19: =-0.5*200 -> -100 | J19: =-0.5*200 -> -100 | K19: =-0.5*200 -> -100 | L19: =-0.5*200 -> -100 | M19: =-0.5*200 -> -100 | ... Y19: =-0.5*200 -> -100 | AA19: $500k/MW | AD19: Stock Price | AF19: 46.15 | AM19: Dilution
B20: GPU Residual Value | J20: =(E18+F18)*-0.2 -> 1160 | O20: =K18*-0.2 -> 1160 | T20: =P18*-0.2 -> 1160 | Y20: =U18*-0.2 -> 1160 | AD20: Shares Outstanding | AF20: 331.44 | AH20: millions | AK20: Discount Rate | AM20: 1 | AN20: 1.25 | AO20: 1.5 | AP20: 1.75 | AQ20: 2 | AR20: 2.5 | AS20: 3 | AT20: 4 | AU20: 5 | AV20: 10 | AW20: 12.5 | AX20: 15 | AY20: 17.5 | AZ20: 20
AD21: Market Cap | AF21: =AF19*AF20 -> 15295.956 | AL21: 0.08 | AM21: {=(SUMPRODUCT($E$29:$Y$29/((1+$AL21)^($E$4:$Y$4-YEAR($C$2)+0.5)))*22.5+((843*1.025/($AL21-0.025))*22.5)/((1+$AL21)^($Z$4-YEAR($C$2)+0.5)))/($AF$20*AM$20)} -> 295.07858 | AN21: {=(SUMPRODUCT($E$29:$Y$29/((1+$AL21)^($E$4:$Y$4-YEAR($C$2)+0.5)))*22.5+((843*1.025/($AL21-0.025))*22.5)/((1+$AL21)^($Z$4-YEAR($C$2)+0.5)))/($AF$20*AN$20)} -> 236.06287 | AO21: {=(SUMPRODUCT($E$29:$Y$29/((1+$AL21)^($E$4:$Y$4-YEAR($C$2)+0.5)))*22.5+((843*1.025/($AL21-0.025))*22.5)/((1+$AL21)^($Z$4-YEAR($C$2)+0.5)))/($AF$20*AO$20)} -> 196.71906 | AP21: {=(SUMPRODUCT($E$29:$Y$29/((1+$AL21)^($E$4:$Y$4-YEAR($C$2)+0.5)))*22.5+((843*1.025/($AL21-0.025))*22.5)/((1+$AL21)^($Z$4-YEAR($C$2)+0.5)))/($AF$20*AP$20)} -> 168.61633 | AQ21: {=(SUMPRODUCT($E$29:$Y$29/((1+$AL21)^($E$4:$Y$4-YEAR($C$2)+0.5)))*22.5+((843*1.025/($AL21-0.025))*22.5)/((1+$AL21)^($Z$4-YEAR($C$2)+0.5)))/($AF$20*AQ$20)} -> 147.53929 | AR21: {=(SUMPRODUCT($E$29:$Y$29/((1+$AL21)^($E$4:$Y$4-YEAR($C$2)+0.5)))*22.5+((843*1.025/($AL21-0.025))*22.5)/((1+$AL21)^($Z$4-YEAR($C$2)+0.5)))/($AF$20*AR$20)} -> 118.03143 | AS21: {=(SUMPRODUCT($E$29:$Y$29/((1+$AL21)^($E$4:$Y$4-YEAR($C$2)+0.5)))*22.5+((843*1.025/($AL21-0.025))*22.5)/((1+$AL21)^($Z$4-YEAR($C$2)+0.5)))/($AF$20*AS$20)} -> 98.359528 | AT21: {=(SUMPRODUCT($E$29:$Y$29/((1+$AL21)^($E$4:$Y$4-YEAR($C$2)+0.5)))*22.5+((843*1.025/($AL21-0.025))*22.5)/((1+$AL21)^($Z$4-YEAR($C$2)+0.5)))/($AF$20*AT$20)} -> 73.769646 | ... AZ21: {=(SUMPRODUCT($E$29:$Y$29/((1+$AL21)^($E$4:$Y$4-YEAR($C$2)+0.5)))*22.5+((843*1.025/($AL21-0.025))*22.5)/((1+$AL21)^($Z$4-YEAR($C$2)+0.5)))/($AF$20*AZ$20)} -> 14.753929
AL22: 0.09 | AM22: {=(SUMPRODUCT($E$29:$Y$29/((1+$AL22)^($E$4:$Y$4-YEAR($C$2)+0.5)))*22.5+((843*1.025/($AL22-0.025))*22.5)/((1+$AL22)^($Z$4-YEAR($C$2)+0.5)))/($AF$20*AM$20)} -> 220.64151 | AN22: {=(SUMPRODUCT($E$29:$Y$29/((1+$AL22)^($E$4:$Y$4-YEAR($C$2)+0.5)))*22.5+((843*1.025/($AL22-0.025))*22.5)/((1+$AL22)^($Z$4-YEAR($C$2)+0.5)))/($AF$20*AN$20)} -> 176.51321 | AO22: {=(SUMPRODUCT($E$29:$Y$29/((1+$AL22)^($E$4:$Y$4-YEAR($C$2)+0.5)))*22.5+((843*1.025/($AL22-0.025))*22.5)/((1+$AL22)^($Z$4-YEAR($C$2)+0.5)))/($AF$20*AO$20)} -> 147.09434 | AP22: {=(SUMPRODUCT($E$29:$Y$29/((1+$AL22)^($E$4:$Y$4-YEAR($C$2)+0.5)))*22.5+((843*1.025/($AL22-0.025))*22.5)/((1+$AL22)^($Z$4-YEAR($C$2)+0.5)))/($AF$20*AP$20)} -> 126.08086 | AQ22: {=(SUMPRODUCT($E$29:$Y$29/((1+$AL22)^($E$4:$Y$4-YEAR($C$2)+0.5)))*22.5+((843*1.025/($AL22-0.025))*22.5)/((1+$AL22)^($Z$4-YEAR($C$2)+0.5)))/($AF$20*AQ$20)} -> 110.32076 | AR22: {=(SUMPRODUCT($E$29:$Y$29/((1+$AL22)^($E$4:$Y$4-YEAR($C$2)+0.5)))*22.5+((843*1.025/($AL22-0.025))*22.5)/((1+$AL22)^($Z$4-YEAR($C$2)+0.5)))/($AF$20*AR$20)} -> 88.256604 | AS22: {=(SUMPRODUCT($E$29:$Y$29/((1+$AL22)^($E$4:$Y$4-YEAR($C$2)+0.5)))*22.5+((843*1.025/($AL22-0.025))*22.5)/((1+$AL22)^($Z$4-YEAR($C$2)+0.5)))/($AF$20*AS$20)} -> 73.54717 | AT22: {=(SUMPRODUCT($E$29:$Y$29/((1+$AL22)^($E$4:$Y$4-YEAR($C$2)+0.5)))*22.5+((843*1.025/($AL22-0.025))*22.5)/((1+$AL22)^($Z$4-YEAR($C$2)+0.5)))/($AF$20*AT$20)} -> 55.160378 | ... AZ22: {=(SUMPRODUCT($E$29:$Y$29/((1+$AL22)^($E$4:$Y$4-YEAR($C$2)+0.5)))*22.5+((843*1.025/($AL22-0.025))*22.5)/((1+$AL22)^($Z$4-YEAR($C$2)+0.5)))/($AF$20*AZ$20)} -> 11.032076
B23: Unlevered Cash Flow | E23: =E15+E16+E17+E18-E13 -> -4259.2675 | F23: =SUM(F15:F19)-F13 -> -754.445 | G23: =G15+G16+G19-G13 -> 960.555 | H23: =H15+H16+H19-H13 -> 960.555 | I23: =I15+I16+I19-I13 -> 960.555 | J23: =J15+J19+J16+J20+-J13 -> 1738.9475 | K23: =K15+K16+K18+K19-K13 -> -2414.445 | L23: =L15+L16+L19-L13 -> 1445.555 | M23: =M15+M16+M19-M13 -> 798.88833 | N23: =N15+N16+N19-N13 -> 798.88833 | O23: =O15+O16+O19+O20-O13 -> 1958.8883 | P23: =P15+P16+P18+P19-P13 -> -2414.445 | Q23: =Q15+Q16+Q19-Q13 -> 1445.555 | R23: =R15+R16+R19-R13 -> 798.88833 | S23: =S15+S16+S19-S13 -> 798.88833 | T23: =T15+T16+T19+T20-T13 -> 1958.8883 | U23: =U15+U16+U18+U19-U13 -> -2414.445 | V23: =V15+V16+V19-V13 -> 1445.555 | W23: =W15+W16+W19-W13 -> 798.88833 | X23: =X15+X16+X19-X13 -> 798.88833 | Y23: =Y15+Y16+Y19+Y20-Y13 -> 1958.8883 | AD23: Equity | AF23: =AF6 -> 152990 | AL23: 0.1 | AM23: {=(SUMPRODUCT($E$29:$Y$29/((1+$AL23)^($E$4:$Y$4-YEAR($C$2)+0.5)))*22.5+((843*1.025/($AL23-0.025))*22.5)/((1+$AL23)^($Z$4-YEAR($C$2)+0.5)))/($AF$20*AM$20)} -> 169.05476 | AN23: {=(SUMPRODUCT($E$29:$Y$29/((1+$AL23)^($E$4:$Y$4-YEAR($C$2)+0.5)))*22.5+((843*1.025/($AL23-0.025))*22.5)/((1+$AL23)^($Z$4-YEAR($C$2)+0.5)))/($AF$20*AN$20)} -> 135.24381 | AO23: {=(SUMPRODUCT($E$29:$Y$29/((1+$AL23)^($E$4:$Y$4-YEAR($C$2)+0.5)))*22.5+((843*1.025/($AL23-0.025))*22.5)/((1+$AL23)^($Z$4-YEAR($C$2)+0.5)))/($AF$20*AO$20)} -> 112.70317 | AP23: {=(SUMPRODUCT($E$29:$Y$29/((1+$AL23)^($E$4:$Y$4-YEAR($C$2)+0.5)))*22.5+((843*1.025/($AL23-0.025))*22.5)/((1+$AL23)^($Z$4-YEAR($C$2)+0.5)))/($AF$20*AP$20)} -> 96.602719 | AQ23: {=(SUMPRODUCT($E$29:$Y$29/((1+$AL23)^($E$4:$Y$4-YEAR($C$2)+0.5)))*22.5+((843*1.025/($AL23-0.025))*22.5)/((1+$AL23)^($Z$4-YEAR($C$2)+0.5)))/($AF$20*AQ$20)} -> 84.52738 | AR23: {=(SUMPRODUCT($E$29:$Y$29/((1+$AL23)^($E$4:$Y$4-YEAR($C$2)+0.5)))*22.5+((843*1.025/($AL23-0.025))*22.5)/((1+$AL23)^($Z$4-YEAR($C$2)+0.5)))/($AF$20*AR$20)} -> 67.621904 | AS23: {=(SUMPRODUCT($E$29:$Y$29/((1+$AL23)^($E$4:$Y$4-YEAR($C$2)+0.5)))*22.5+((843*1.025/($AL23-0.025))*22.5)/((1+$AL23)^($Z$4-YEAR($C$2)+0.5)))/($AF$20*AS$20)} -> 56.351586 | AT23: {=(SUMPRODUCT($E$29:$Y$29/((1+$AL23)^($E$4:$Y$4-YEAR($C$2)+0.5)))*22.5+((843*1.025/($AL23-0.025))*22.5)/((1+$AL23)^($Z$4-YEAR($C$2)+0.5)))/($AF$20*AT$20)} -> 42.26369 | ... AZ23: {=(SUMPRODUCT($E$29:$Y$29/((1+$AL23)^($E$4:$Y$4-YEAR($C$2)+0.5)))*22.5+((843*1.025/($AL23-0.025))*22.5)/((1+$AL23)^($Z$4-YEAR($C$2)+0.5)))/($AF$20*AZ$20)} -> 8.452738
AD24: Dilution | AF24: 3 | AL24: 0.11 | AM24: {=(SUMPRODUCT($E$29:$Y$29/((1+$AL24)^($E$4:$Y$4-YEAR($C$2)+0.5)))*22.5+((843*1.025/($AL24-0.025))*22.5)/((1+$AL24)^($Z$4-YEAR($C$2)+0.5)))/($AF$20*AM$20)} -> 131.69031 | AN24: {=(SUMPRODUCT($E$29:$Y$29/((1+$AL24)^($E$4:$Y$4-YEAR($C$2)+0.5)))*22.5+((843*1.025/($AL24-0.025))*22.5)/((1+$AL24)^($Z$4-YEAR($C$2)+0.5)))/($AF$20*AN$20)} -> 105.35225 | AO24: {=(SUMPRODUCT($E$29:$Y$29/((1+$AL24)^($E$4:$Y$4-YEAR($C$2)+0.5)))*22.5+((843*1.025/($AL24-0.025))*22.5)/((1+$AL24)^($Z$4-YEAR($C$2)+0.5)))/($AF$20*AO$20)} -> 87.793539 | AP24: {=(SUMPRODUCT($E$29:$Y$29/((1+$AL24)^($E$4:$Y$4-YEAR($C$2)+0.5)))*22.5+((843*1.025/($AL24-0.025))*22.5)/((1+$AL24)^($Z$4-YEAR($C$2)+0.5)))/($AF$20*AP$20)} -> 75.251605 | AQ24: {=(SUMPRODUCT($E$29:$Y$29/((1+$AL24)^($E$4:$Y$4-YEAR($C$2)+0.5)))*22.5+((843*1.025/($AL24-0.025))*22.5)/((1+$AL24)^($Z$4-YEAR($C$2)+0.5)))/($AF$20*AQ$20)} -> 65.845155 | AR24: {=(SUMPRODUCT($E$29:$Y$29/((1+$AL24)^($E$4:$Y$4-YEAR($C$2)+0.5)))*22.5+((843*1.025/($AL24-0.025))*22.5)/((1+$AL24)^($Z$4-YEAR($C$2)+0.5)))/($AF$20*AR$20)} -> 52.676124 | AS24: {=(SUMPRODUCT($E$29:$Y$29/((1+$AL24)^($E$4:$Y$4-YEAR($C$2)+0.5)))*22.5+((843*1.025/($AL24-0.025))*22.5)/((1+$AL24)^($Z$4-YEAR($C$2)+0.5)))/($AF$20*AS$20)} -> 43.89677 | AT24: {=(SUMPRODUCT($E$29:$Y$29/((1+$AL24)^($E$4:$Y$4-YEAR($C$2)+0.5)))*22.5+((843*1.025/($AL24-0.025))*22.5)/((1+$AL24)^($Z$4-YEAR($C$2)+0.5)))/($AF$20*AT$20)} -> 32.922577 | ... AZ24: {=(SUMPRODUCT($E$29:$Y$29/((1+$AL24)^($E$4:$Y$4-YEAR($C$2)+0.5)))*22.5+((843*1.025/($AL24-0.025))*22.5)/((1+$AL24)^($Z$4-YEAR($C$2)+0.5)))/($AF$20*AZ$20)} -> 6.5845155
B25: Debt Drawdown | E25: 3600 | K25: 3600 | P25: 3600 | U25: 3600 | AD25: Shares Outstanding | AF25: =AF20*AF24 -> 994.32 | AH25: millions | AL25: 0.12 | AM25: {=(SUMPRODUCT($E$29:$Y$29/((1+$AL25)^($E$4:$Y$4-YEAR($C$2)+0.5)))*22.5+((843*1.025/($AL25-0.025))*22.5)/((1+$AL25)^($Z$4-YEAR($C$2)+0.5)))/($AF$20*AM$20)} -> 103.66512 | AN25: {=(SUMPRODUCT($E$29:$Y$29/((1+$AL25)^($E$4:$Y$4-YEAR($C$2)+0.5)))*22.5+((843*1.025/($AL25-0.025))*22.5)/((1+$AL25)^($Z$4-YEAR($C$2)+0.5)))/($AF$20*AN$20)} -> 82.932099 | AO25: {=(SUMPRODUCT($E$29:$Y$29/((1+$AL25)^($E$4:$Y$4-YEAR($C$2)+0.5)))*22.5+((843*1.025/($AL25-0.025))*22.5)/((1+$AL25)^($Z$4-YEAR($C$2)+0.5)))/($AF$20*AO$20)} -> 69.110083 | AP25: {=(SUMPRODUCT($E$29:$Y$29/((1+$AL25)^($E$4:$Y$4-YEAR($C$2)+0.5)))*22.5+((843*1.025/($AL25-0.025))*22.5)/((1+$AL25)^($Z$4-YEAR($C$2)+0.5)))/($AF$20*AP$20)} -> 59.237214 | AQ25: {=(SUMPRODUCT($E$29:$Y$29/((1+$AL25)^($E$4:$Y$4-YEAR($C$2)+0.5)))*22.5+((843*1.025/($AL25-0.025))*22.5)/((1+$AL25)^($Z$4-YEAR($C$2)+0.5)))/($AF$20*AQ$20)} -> 51.832562 | AR25: {=(SUMPRODUCT($E$29:$Y$29/((1+$AL25)^($E$4:$Y$4-YEAR($C$2)+0.5)))*22.5+((843*1.025/($AL25-0.025))*22.5)/((1+$AL25)^($Z$4-YEAR($C$2)+0.5)))/($AF$20*AR$20)} -> 41.46605 | AS25: {=(SUMPRODUCT($E$29:$Y$29/((1+$AL25)^($E$4:$Y$4-YEAR($C$2)+0.5)))*22.5+((843*1.025/($AL25-0.025))*22.5)/((1+$AL25)^($Z$4-YEAR($C$2)+0.5)))/($AF$20*AS$20)} -> 34.555041 | AT25: {=(SUMPRODUCT($E$29:$Y$29/((1+$AL25)^($E$4:$Y$4-YEAR($C$2)+0.5)))*22.5+((843*1.025/($AL25-0.025))*22.5)/((1+$AL25)^($Z$4-YEAR($C$2)+0.5)))/($AF$20*AT$20)} -> 25.916281 | ... AZ25: {=(SUMPRODUCT($E$29:$Y$29/((1+$AL25)^($E$4:$Y$4-YEAR($C$2)+0.5)))*22.5+((843*1.025/($AL25-0.025))*22.5)/((1+$AL25)^($Z$4-YEAR($C$2)+0.5)))/($AF$20*AZ$20)} -> 5.1832562
B26: Interest Expense | E26: =(($E$25*-0.06)*0.75)*0.83 -> -134.46 | F26: =($E$25*-0.06)*0.83 -> -179.28 | G26: =($E$25*-0.06)*0.83 -> -179.28 | H26: =($E$25*-0.06)*0.83 -> -179.28 | I26: =($E$25*-0.06)*0.83 -> -179.28 | J26: =($E$25*-0.06*0.5)*0.83 -> -89.64 | K26: =($K$25*-0.06)*0.83 -> -179.28 | L26: =($K$25*-0.06)*0.83 -> -179.28 | M26: =($K$25*-0.06)*0.83 -> -179.28 | N26: =($K$25*-0.06)*0.83 -> -179.28 | O26: =($K$25*-0.06)*0.83 -> -179.28 | P26: =($K$25*-0.06)*0.83 -> -179.28 | Q26: =($K$25*-0.06)*0.83 -> -179.28 | R26: =($K$25*-0.06)*0.83 -> -179.28 | ... Y26: =($K$25*-0.06)*0.83 -> -179.28 | AA26: 6% p.a. | AL26: 0.13 | AM26: {=(SUMPRODUCT($E$29:$Y$29/((1+$AL26)^($E$4:$Y$4-YEAR($C$2)+0.5)))*22.5+((843*1.025/($AL26-0.025))*22.5)/((1+$AL26)^($Z$4-YEAR($C$2)+0.5)))/($AF$20*AM$20)} -> 82.034952 | AN26: {=(SUMPRODUCT($E$29:$Y$29/((1+$AL26)^($E$4:$Y$4-YEAR($C$2)+0.5)))*22.5+((843*1.025/($AL26-0.025))*22.5)/((1+$AL26)^($Z$4-YEAR($C$2)+0.5)))/($AF$20*AN$20)} -> 65.627962 | AO26: {=(SUMPRODUCT($E$29:$Y$29/((1+$AL26)^($E$4:$Y$4-YEAR($C$2)+0.5)))*22.5+((843*1.025/($AL26-0.025))*22.5)/((1+$AL26)^($Z$4-YEAR($C$2)+0.5)))/($AF$20*AO$20)} -> 54.689968 | AP26: {=(SUMPRODUCT($E$29:$Y$29/((1+$AL26)^($E$4:$Y$4-YEAR($C$2)+0.5)))*22.5+((843*1.025/($AL26-0.025))*22.5)/((1+$AL26)^($Z$4-YEAR($C$2)+0.5)))/($AF$20*AP$20)} -> 46.877115 | AQ26: {=(SUMPRODUCT($E$29:$Y$29/((1+$AL26)^($E$4:$Y$4-YEAR($C$2)+0.5)))*22.5+((843*1.025/($AL26-0.025))*22.5)/((1+$AL26)^($Z$4-YEAR($C$2)+0.5)))/($AF$20*AQ$20)} -> 41.017476 | AR26: {=(SUMPRODUCT($E$29:$Y$29/((1+$AL26)^($E$4:$Y$4-YEAR($C$2)+0.5)))*22.5+((843*1.025/($AL26-0.025))*22.5)/((1+$AL26)^($Z$4-YEAR($C$2)+0.5)))/($AF$20*AR$20)} -> 32.813981 | AS26: {=(SUMPRODUCT($E$29:$Y$29/((1+$AL26)^($E$4:$Y$4-YEAR($C$2)+0.5)))*22.5+((843*1.025/($AL26-0.025))*22.5)/((1+$AL26)^($Z$4-YEAR($C$2)+0.5)))/($AF$20*AS$20)} -> 27.344984 | AT26: {=(SUMPRODUCT($E$29:$Y$29/((1+$AL26)^($E$4:$Y$4-YEAR($C$2)+0.5)))*22.5+((843*1.025/($AL26-0.025))*22.5)/((1+$AL26)^($Z$4-YEAR($C$2)+0.5)))/($AF$20*AT$20)} -> 20.508738 | ... AZ26: {=(SUMPRODUCT($E$29:$Y$29/((1+$AL26)^($E$4:$Y$4-YEAR($C$2)+0.5)))*22.5+((843*1.025/($AL26-0.025))*22.5)/((1+$AL26)^($Z$4-YEAR($C$2)+0.5)))/($AF$20*AZ$20)} -> 4.1017476
B27: Debt Repayment | J27: =-E25 -> -3600 | O27: =-K25 -> -3600 | T27: =-P25 -> -3600 | Y27: =-U25 -> -3600 | AD27: Implied Stock Price | AF27: =AF17/AF25 -> 35.302414 | AL27: 0.14 | AM27: {=(SUMPRODUCT($E$29:$Y$29/((1+$AL27)^($E$4:$Y$4-YEAR($C$2)+0.5)))*22.5+((843*1.025/($AL27-0.025))*22.5)/((1+$AL27)^($Z$4-YEAR($C$2)+0.5)))/($AF$20*AM$20)} -> 64.935272 | AN27: {=(SUMPRODUCT($E$29:$Y$29/((1+$AL27)^($E$4:$Y$4-YEAR($C$2)+0.5)))*22.5+((843*1.025/($AL27-0.025))*22.5)/((1+$AL27)^($Z$4-YEAR($C$2)+0.5)))/($AF$20*AN$20)} -> 51.948218 | AO27: {=(SUMPRODUCT($E$29:$Y$29/((1+$AL27)^($E$4:$Y$4-YEAR($C$2)+0.5)))*22.5+((843*1.025/($AL27-0.025))*22.5)/((1+$AL27)^($Z$4-YEAR($C$2)+0.5)))/($AF$20*AO$20)} -> 43.290181 | AP27: {=(SUMPRODUCT($E$29:$Y$29/((1+$AL27)^($E$4:$Y$4-YEAR($C$2)+0.5)))*22.5+((843*1.025/($AL27-0.025))*22.5)/((1+$AL27)^($Z$4-YEAR($C$2)+0.5)))/($AF$20*AP$20)} -> 37.10587 | AQ27: {=(SUMPRODUCT($E$29:$Y$29/((1+$AL27)^($E$4:$Y$4-YEAR($C$2)+0.5)))*22.5+((843*1.025/($AL27-0.025))*22.5)/((1+$AL27)^($Z$4-YEAR($C$2)+0.5)))/($AF$20*AQ$20)} -> 32.467636 | AR27: {=(SUMPRODUCT($E$29:$Y$29/((1+$AL27)^($E$4:$Y$4-YEAR($C$2)+0.5)))*22.5+((843*1.025/($AL27-0.025))*22.5)/((1+$AL27)^($Z$4-YEAR($C$2)+0.5)))/($AF$20*AR$20)} -> 25.974109 | AS27: {=(SUMPRODUCT($E$29:$Y$29/((1+$AL27)^($E$4:$Y$4-YEAR($C$2)+0.5)))*22.5+((843*1.025/($AL27-0.025))*22.5)/((1+$AL27)^($Z$4-YEAR($C$2)+0.5)))/($AF$20*AS$20)} -> 21.645091 | AT27: {=(SUMPRODUCT($E$29:$Y$29/((1+$AL27)^($E$4:$Y$4-YEAR($C$2)+0.5)))*22.5+((843*1.025/($AL27-0.025))*22.5)/((1+$AL27)^($Z$4-YEAR($C$2)+0.5)))/($AF$20*AT$20)} -> 16.233818 | ... AZ27: {=(SUMPRODUCT($E$29:$Y$29/((1+$AL27)^($E$4:$Y$4-YEAR($C$2)+0.5)))*22.5+((843*1.025/($AL27-0.025))*22.5)/((1+$AL27)^($Z$4-YEAR($C$2)+0.5)))/($AF$20*AZ$20)} -> 3.2467636
AD28: Stock Price | AF28: 46.15 | AL28: 0.15 | AM28: {=(SUMPRODUCT($E$29:$Y$29/((1+$AL28)^($E$4:$Y$4-YEAR($C$2)+0.5)))*22.5+((843*1.025/($AL28-0.025))*22.5)/((1+$AL28)^($Z$4-YEAR($C$2)+0.5)))/($AF$20*AM$20)} -> 51.137953 | AN28: {=(SUMPRODUCT($E$29:$Y$29/((1+$AL28)^($E$4:$Y$4-YEAR($C$2)+0.5)))*22.5+((843*1.025/($AL28-0.025))*22.5)/((1+$AL28)^($Z$4-YEAR($C$2)+0.5)))/($AF$20*AN$20)} -> 40.910362 | AO28: {=(SUMPRODUCT($E$29:$Y$29/((1+$AL28)^($E$4:$Y$4-YEAR($C$2)+0.5)))*22.5+((843*1.025/($AL28-0.025))*22.5)/((1+$AL28)^($Z$4-YEAR($C$2)+0.5)))/($AF$20*AO$20)} -> 34.091969 | AP28: {=(SUMPRODUCT($E$29:$Y$29/((1+$AL28)^($E$4:$Y$4-YEAR($C$2)+0.5)))*22.5+((843*1.025/($AL28-0.025))*22.5)/((1+$AL28)^($Z$4-YEAR($C$2)+0.5)))/($AF$20*AP$20)} -> 29.221687 | AQ28: {=(SUMPRODUCT($E$29:$Y$29/((1+$AL28)^($E$4:$Y$4-YEAR($C$2)+0.5)))*22.5+((843*1.025/($AL28-0.025))*22.5)/((1+$AL28)^($Z$4-YEAR($C$2)+0.5)))/($AF$20*AQ$20)} -> 25.568976 | AR28: {=(SUMPRODUCT($E$29:$Y$29/((1+$AL28)^($E$4:$Y$4-YEAR($C$2)+0.5)))*22.5+((843*1.025/($AL28-0.025))*22.5)/((1+$AL28)^($Z$4-YEAR($C$2)+0.5)))/($AF$20*AR$20)} -> 20.455181 | AS28: {=(SUMPRODUCT($E$29:$Y$29/((1+$AL28)^($E$4:$Y$4-YEAR($C$2)+0.5)))*22.5+((843*1.025/($AL28-0.025))*22.5)/((1+$AL28)^($Z$4-YEAR($C$2)+0.5)))/($AF$20*AS$20)} -> 17.045984 | AT28: {=(SUMPRODUCT($E$29:$Y$29/((1+$AL28)^($E$4:$Y$4-YEAR($C$2)+0.5)))*22.5+((843*1.025/($AL28-0.025))*22.5)/((1+$AL28)^($Z$4-YEAR($C$2)+0.5)))/($AF$20*AT$20)} -> 12.784488 | ... AZ28: {=(SUMPRODUCT($E$29:$Y$29/((1+$AL28)^($E$4:$Y$4-YEAR($C$2)+0.5)))*22.5+((843*1.025/($AL28-0.025))*22.5)/((1+$AL28)^($Z$4-YEAR($C$2)+0.5)))/($AF$20*AZ$20)} -> 2.5568976
B29: Levered Cash Flow | E29: =E23+E25+E26 -> -793.7275 | F29: =F23+F26 -> -933.725 | G29: =G23+G26 -> 781.275 | H29: =H23+H26 -> 781.275 | I29: =I23+I26 -> 781.275 | J29: =J23+J26+J27 -> -1950.6925 | K29: =K23+K25+K26 -> 1006.275 | L29: =L23+L26 -> 1266.275 | M29: =M23+M26 -> 619.60833 | N29: =N23+N26 -> 619.60833 | O29: =O23+O26+O27 -> -1820.3917 | P29: =P23+P25+P26 -> 1006.275 | Q29: =Q23+Q26 -> 1266.275 | R29: =R23+R26 -> 619.60833 | S29: =S23+S26 -> 619.60833 | T29: =T23+T26+T27 -> -1820.3917 | U29: =U23+U25+U26 -> 1006.275 | V29: =V23+V26 -> 1266.275 | W29: =W23+W26 -> 619.60833 | X29: =X23+X26 -> 619.60833 | Y29: =Y23+Y26+Y27 -> -1820.3917 | Z29: =(878*(1+0.025)/($L$2-0.025))*22.5 -> 213146.05 | AD29: Upside/(Downside) | AF29: =AF27/AF28-1 -> -0.23505062 | AL29: 0.16 | AM29: {=(SUMPRODUCT($E$29:$Y$29/((1+$AL29)^($E$4:$Y$4-YEAR($C$2)+0.5)))*22.5+((843*1.025/($AL29-0.025))*22.5)/((1+$AL29)^($Z$4-YEAR($C$2)+0.5)))/($AF$20*AM$20)} -> 39.807356 | AN29: {=(SUMPRODUCT($E$29:$Y$29/((1+$AL29)^($E$4:$Y$4-YEAR($C$2)+0.5)))*22.5+((843*1.025/($AL29-0.025))*22.5)/((1+$AL29)^($Z$4-YEAR($C$2)+0.5)))/($AF$20*AN$20)} -> 31.845885 | AO29: {=(SUMPRODUCT($E$29:$Y$29/((1+$AL29)^($E$4:$Y$4-YEAR($C$2)+0.5)))*22.5+((843*1.025/($AL29-0.025))*22.5)/((1+$AL29)^($Z$4-YEAR($C$2)+0.5)))/($AF$20*AO$20)} -> 26.538237 | AP29: {=(SUMPRODUCT($E$29:$Y$29/((1+$AL29)^($E$4:$Y$4-YEAR($C$2)+0.5)))*22.5+((843*1.025/($AL29-0.025))*22.5)/((1+$AL29)^($Z$4-YEAR($C$2)+0.5)))/($AF$20*AP$20)} -> 22.747061 | AQ29: {=(SUMPRODUCT($E$29:$Y$29/((1+$AL29)^($E$4:$Y$4-YEAR($C$2)+0.5)))*22.5+((843*1.025/($AL29-0.025))*22.5)/((1+$AL29)^($Z$4-YEAR($C$2)+0.5)))/($AF$20*AQ$20)} -> 19.903678 | AR29: {=(SUMPRODUCT($E$29:$Y$29/((1+$AL29)^($E$4:$Y$4-YEAR($C$2)+0.5)))*22.5+((843*1.025/($AL29-0.025))*22.5)/((1+$AL29)^($Z$4-YEAR($C$2)+0.5)))/($AF$20*AR$20)} -> 15.922942 | AS29: {=(SUMPRODUCT($E$29:$Y$29/((1+$AL29)^($E$4:$Y$4-YEAR($C$2)+0.5)))*22.5+((843*1.025/($AL29-0.025))*22.5)/((1+$AL29)^($Z$4-YEAR($C$2)+0.5)))/($AF$20*AS$20)} -> 13.269119 | AT29: {=(SUMPRODUCT($E$29:$Y$29/((1+$AL29)^($E$4:$Y$4-YEAR($C$2)+0.5)))*22.5+((843*1.025/($AL29-0.025))*22.5)/((1+$AL29)^($Z$4-YEAR($C$2)+0.5)))/($AF$20*AT$20)} -> 9.951839 | ... AZ29: {=(SUMPRODUCT($E$29:$Y$29/((1+$AL29)^($E$4:$Y$4-YEAR($C$2)+0.5)))*22.5+((843*1.025/($AL29-0.025))*22.5)/((1+$AL29)^($Z$4-YEAR($C$2)+0.5)))/($AF$20*AZ$20)} -> 1.9903678
AL30: 0.17 | AM30: {=(SUMPRODUCT($E$29:$Y$29/((1+$AL30)^($E$4:$Y$4-YEAR($C$2)+0.5)))*22.5+((843*1.025/($AL30-0.025))*22.5)/((1+$AL30)^($Z$4-YEAR($C$2)+0.5)))/($AF$20*AM$20)} -> 30.359081 | AN30: {=(SUMPRODUCT($E$29:$Y$29/((1+$AL30)^($E$4:$Y$4-YEAR($C$2)+0.5)))*22.5+((843*1.025/($AL30-0.025))*22.5)/((1+$AL30)^($Z$4-YEAR($C$2)+0.5)))/($AF$20*AN$20)} -> 24.287264 | AO30: {=(SUMPRODUCT($E$29:$Y$29/((1+$AL30)^($E$4:$Y$4-YEAR($C$2)+0.5)))*22.5+((843*1.025/($AL30-0.025))*22.5)/((1+$AL30)^($Z$4-YEAR($C$2)+0.5)))/($AF$20*AO$20)} -> 20.239387 | AP30: {=(SUMPRODUCT($E$29:$Y$29/((1+$AL30)^($E$4:$Y$4-YEAR($C$2)+0.5)))*22.5+((843*1.025/($AL30-0.025))*22.5)/((1+$AL30)^($Z$4-YEAR($C$2)+0.5)))/($AF$20*AP$20)} -> 17.348046 | AQ30: {=(SUMPRODUCT($E$29:$Y$29/((1+$AL30)^($E$4:$Y$4-YEAR($C$2)+0.5)))*22.5+((843*1.025/($AL30-0.025))*22.5)/((1+$AL30)^($Z$4-YEAR($C$2)+0.5)))/($AF$20*AQ$20)} -> 15.17954 | AR30: {=(SUMPRODUCT($E$29:$Y$29/((1+$AL30)^($E$4:$Y$4-YEAR($C$2)+0.5)))*22.5+((843*1.025/($AL30-0.025))*22.5)/((1+$AL30)^($Z$4-YEAR($C$2)+0.5)))/($AF$20*AR$20)} -> 12.143632 | AS30: {=(SUMPRODUCT($E$29:$Y$29/((1+$AL30)^($E$4:$Y$4-YEAR($C$2)+0.5)))*22.5+((843*1.025/($AL30-0.025))*22.5)/((1+$AL30)^($Z$4-YEAR($C$2)+0.5)))/($AF$20*AS$20)} -> 10.119694 | AT30: {=(SUMPRODUCT($E$29:$Y$29/((1+$AL30)^($E$4:$Y$4-YEAR($C$2)+0.5)))*22.5+((843*1.025/($AL30-0.025))*22.5)/((1+$AL30)^($Z$4-YEAR($C$2)+0.5)))/($AF$20*AT$20)} -> 7.5897701 | ... AZ30: {=(SUMPRODUCT($E$29:$Y$29/((1+$AL30)^($E$4:$Y$4-YEAR($C$2)+0.5)))*22.5+((843*1.025/($AL30-0.025))*22.5)/((1+$AL30)^($Z$4-YEAR($C$2)+0.5)))/($AF$20*AZ$20)} -> 1.517954
B31: PV of Unlevered Cash Flow | E31: =E23/((1+$G$2)^(E$4-YEAR($C$2)+0.5)) -> -4024.6295 | F31: =F23/((1+$G$2)^(F$4-YEAR($C$2)+0.5)) -> -636.50314 | G31: =G23/((1+$G$2)^(G$4-YEAR($C$2)+0.5)) -> 723.56438 | H31: =H23/((1+$G$2)^(H$4-YEAR($C$2)+0.5)) -> 646.03963 | I31: =I23/((1+$G$2)^(I$4-YEAR($C$2)+0.5)) -> 576.8211 | J31: =J23/((1+$G$2)^(J$4-YEAR($C$2)+0.5)) -> 932.36797 | K31: =K23/((1+$G$2)^(K$4-YEAR($C$2)+0.5)) -> -1155.8465 | L31: =L23/((1+$G$2)^(L$4-YEAR($C$2)+0.5)) -> 617.87333 | ... Y31: =Y23/((1+$G$2)^(Y$4-YEAR($C$2)+0.5)) -> 191.88464 | AA31: Mid-year discounting | AL31: 0.18 | AM31: {=(SUMPRODUCT($E$29:$Y$29/((1+$AL31)^($E$4:$Y$4-YEAR($C$2)+0.5)))*22.5+((843*1.025/($AL31-0.025))*22.5)/((1+$AL31)^($Z$4-YEAR($C$2)+0.5)))/($AF$20*AM$20)} -> 22.374629 | AN31: {=(SUMPRODUCT($E$29:$Y$29/((1+$AL31)^($E$4:$Y$4-YEAR($C$2)+0.5)))*22.5+((843*1.025/($AL31-0.025))*22.5)/((1+$AL31)^($Z$4-YEAR($C$2)+0.5)))/($AF$20*AN$20)} -> 17.899703 | AO31: {=(SUMPRODUCT($E$29:$Y$29/((1+$AL31)^($E$4:$Y$4-YEAR($C$2)+0.5)))*22.5+((843*1.025/($AL31-0.025))*22.5)/((1+$AL31)^($Z$4-YEAR($C$2)+0.5)))/($AF$20*AO$20)} -> 14.916419 | AP31: {=(SUMPRODUCT($E$29:$Y$29/((1+$AL31)^($E$4:$Y$4-YEAR($C$2)+0.5)))*22.5+((843*1.025/($AL31-0.025))*22.5)/((1+$AL31)^($Z$4-YEAR($C$2)+0.5)))/($AF$20*AP$20)} -> 12.785502 | AQ31: {=(SUMPRODUCT($E$29:$Y$29/((1+$AL31)^($E$4:$Y$4-YEAR($C$2)+0.5)))*22.5+((843*1.025/($AL31-0.025))*22.5)/((1+$AL31)^($Z$4-YEAR($C$2)+0.5)))/($AF$20*AQ$20)} -> 11.187314 | AR31: {=(SUMPRODUCT($E$29:$Y$29/((1+$AL31)^($E$4:$Y$4-YEAR($C$2)+0.5)))*22.5+((843*1.025/($AL31-0.025))*22.5)/((1+$AL31)^($Z$4-YEAR($C$2)+0.5)))/($AF$20*AR$20)} -> 8.9498514 | AS31: {=(SUMPRODUCT($E$29:$Y$29/((1+$AL31)^($E$4:$Y$4-YEAR($C$2)+0.5)))*22.5+((843*1.025/($AL31-0.025))*22.5)/((1+$AL31)^($Z$4-YEAR($C$2)+0.5)))/($AF$20*AS$20)} -> 7.4582095 | AT31: {=(SUMPRODUCT($E$29:$Y$29/((1+$AL31)^($E$4:$Y$4-YEAR($C$2)+0.5)))*22.5+((843*1.025/($AL31-0.025))*22.5)/((1+$AL31)^($Z$4-YEAR($C$2)+0.5)))/($AF$20*AT$20)} -> 5.5936572 | ... AZ31: {=(SUMPRODUCT($E$29:$Y$29/((1+$AL31)^($E$4:$Y$4-YEAR($C$2)+0.5)))*22.5+((843*1.025/($AL31-0.025))*22.5)/((1+$AL31)^($Z$4-YEAR($C$2)+0.5)))/($AF$20*AZ$20)} -> 1.1187314
B32: PV of Levered Cash Flow | E32: =E29/((1+$L$2)^(E$4-YEAR($C$2)+0.5)) -> -750.00199 | F32: =F29/((1+$L$2)^(F$4-YEAR($C$2)+0.5)) -> -787.75642 | G32: =G29/((1+$L$2)^(G$4-YEAR($C$2)+0.5)) -> 588.51681 | H32: =H29/((1+$L$2)^(H$4-YEAR($C$2)+0.5)) -> 525.46144 | I32: =I29/((1+$L$2)^(I$4-YEAR($C$2)+0.5)) -> 469.162 | J32: =J29/((1+$L$2)^(J$4-YEAR($C$2)+0.5)) -> -1045.8989 | K32: =K29/((1+$L$2)^(K$4-YEAR($C$2)+0.5)) -> 481.72539 | L32: =L29/((1+$L$2)^(L$4-YEAR($C$2)+0.5)) -> 541.24371 | ... Y32: =Y29/((1+$L$2)^(Y$4-YEAR($C$2)+0.5)) -> -178.31808 | Z32: =$Z$29/((1+$L$2)^($Z$4-YEAR($C$2)+0.5)) -> 18641.884 | AA32: Mid-year discounting | AD32: Dilution since IPO | AF32: =AF20/21 -> 15.782857 | AH32: 331.44/21 (2026/2021)
AD33: Implied Dilution | AF33: =AF6/AF21 -> 10.00199 | AH33: With Current Market Cap
B34: NPV | E34: =SUM(E31:Y31) -> -582.39872 | G34: GPU Count | J34: 77000 | L34: PV of Unlevered CF per MW | O34: =SUM(E31:Y31)/200 -> -2.9119936 | Q34: Terminal Value per MW | T34: =Z29/200/22.5 -> 47.365789 | AD34: SBC Dilution | AF34: =(AF20*(1.02)^20)/AF20 -> 1.4859474 | AH34: 2% a year
B35: Equity NPV | E35: =SUM(E32:Y32) -> 731.55608 | G35: GPU/Hour | J35: =9700000000/(J34*43800) -> 2.8761193 | L35: PV of Levered CF per MW | O35: =SUM(E32:Y32)/200 -> 3.6577804 | Q35: PV of Terminal Value per MW | T35: =Z32/200/22.5 -> 4.1426409 | AD35: Implied Dilution 5Y | AF35: ='Deal Economics'!Q6/AF21 -> 6.1328628
B36: Unlevered IRR | E36: =IRR(E23:Y23) -> 0.10008526 | G36: Unlevered CF per MW | J36: =SUM(E23:Y23)/200 -> 36.851125 | L36: Total Unlevered CF | O36: =SUM(E23:Y23) -> 7370.225
B37: Levered IRR | E37: =IRR(E29:Y29) -> 0.20792418 | G37: Levered CF per MW | J37: =SUM(E29:Y29)/200 -> 18.699025 | L37: Total Unlevered CF | O37: =SUM(E29:Y29) -> 3739.805

Sheet Cost of Equity
B2: Cost of Equity
B3: Risk Free Rate | D3: 0.04044
B4: Equity Risk Premium | D4: 0.0417
B5: Beta | D5: 1.94
B6: Cost of Equity | D6: =D3+(D5*D4) -> 0.121338

Sheet BC Deal Economics
B2: Date: | C2: 46085 | E2: Discount Rate: | G2: 0.12 | I2: Levered Discount Rate: | L2: 0.12
B4: IREN - British Columbia ($mm) | E4: 2026 | F4: 2027 | G4: 2028 | H4: 2029 | I4: 2030 | J4: 2031 | K4: =J4+1 -> 2032 | L4: =K4+1 -> 2033 | M4: =L4+1 -> 2034 | N4: =M4+1 -> 2035 | O4: =N4+1 -> 2036 | P4: =O4+1 -> 2037 | Q4: =P4+1 -> 2038 | R4: =Q4+1 -> 2039 | ... Y4: =X4+1 -> 2046 | Z4: 2047 | AA4: Notes
B5: Revenue | E5: =F5*0.25 -> 440 | F5: 1760 | G5: 1760 | H5: 1760 | I5: 1760 | J5: =I5*0.75 -> 1320 | K5: 1760 | L5: 1760 | M5: 1760 | N5: 1760 | O5: 1760 | P5: 1760 | Q5: 1760 | R5: 1760 | S5: 1760 | T5: 1760 | U5: 1760 | V5: 1760 | W5: 1760 | X5: 1760 | Y5: 1760
B6: OpEx ex D&A | E6: =E5-E7 -> 44 | F6: =F5-F7 -> 176 | G6: =G5-G7 -> 176 | H6: =H5-H7 -> 176 | I6: =I5-I7 -> 176 | J6: =J5-J7 -> 132 | K6: =K5-K7 -> 176 | L6: =L5-L7 -> 176 | ... Y6: =Y5-Y7 -> 176
B7: EBITDA | E7: =E5*E8 -> 396 | F7: =F5*F8 -> 1584 | G7: =G5*G8 -> 1584 | H7: =H5*H8 -> 1584 | I7: =I5*I8 -> 1584 | J7: =J5*J8 -> 1188 | K7: =K5*K8 -> 1584 | L7: =L5*L8 -> 1584 | ... Y7: =Y5*Y8 -> 1584
B8: EBITDA Margin | E8: 0.9 | F8: 0.9 | G8: 0.9 | H8: 0.9 | I8: 0.9 | J8: 0.9 | K8: 0.9 | L8: 0.9 | M8: 0.9 | N8: 0.9 | O8: 0.9 | P8: 0.9 | Q8: 0.9 | R8: 0.9 | S8: 0.9 | T8: 0.9 | U8: 0.9 | V8: 0.9 | W8: 0.9 | X8: 0.9 | Y8: 0.9
B10: EBITDA | E10: =E7 -> 396 | F10: =F7 -> 1584 | G10: =G7 -> 1584 | H10: =H7 -> 1584 | I10: =I7 -> 1584 | J10: =J7 -> 1188 | K10: =K7 -> 1584 | L10: =L7 -> 1584 | ... Y10: =Y7 -> 1584
B11: Data Center CapEx | E11: =4*160 -> 640
B12: GPU CapEx | E12: -2300 | K12: -3500 | P12: =-5800 -> -5800 | U12: =-5800 -> -5800
B13: Data Center Maintenance | F13: =-0.5*260 -> -130 | G13: =-0.5*260 -> -130 | H13: =-0.5*260 -> -130 | I13: =-0.5*260 -> -130 | J13: =-0.5*260 -> -130 | K13: =-0.5*260 -> -130 | L13: =-0.5*260 -> -130 | M13: =-0.5*260 -> -130 | ... O13: =-0.5*260 -> -130 | P13: =-0.5*200 -> -100 | Q13: =-0.5*200 -> -100 | R13: =-0.5*200 -> -100 | S13: =-0.5*200 -> -100 | T13: =-0.5*200 -> -100 | U13: =-0.5*200 -> -100 | V13: =-0.5*200 -> -100 | W13: =-0.5*200 -> -100 | ... Y13: =-0.5*200 -> -100
B14: GPU Residual Value | J14: =E12*-0.2 -> 460 | O14: =K12*-0.2 -> 700 | T14: =P12*-0.2 -> 1160 | Y14: =U12*-0.2 -> 1160
