Workbook
Name Slicer_Category: #N/A
Name Slicer_Metric: #N/A
Name Slicer_Year: #N/A

Sheet Main
R2: all values in millions except per share numbers
B4: Company Overview
B6: Price | G6: Key Stats | M6: Valuation | R6: Notes
B7: Ticker | E7: MSFT | G7: Employees | I7: 228000 | M7: PV of FCF | P7: =SUM(J88:N88) -> 491935.53 | R7: WACC | U7: =Main!U23 -> 0.09032765
B8: Implied Share Price | E8: =(P13+P10)/P12 -> 633.17382 | G8: Founded | I8: 27488 | M8: Terminal Value | P8: =(N65*U8) -> 6050991 | R8: EV/EBIT Multiple | U8: 22
B9: Current Share Price | E9: 475 | G9: CEO | I9: Satya Nadella | M9: PV of Terminal Value | P9: =-(PV(U7,4.5,0,P8)) -> 4100340.2
B10: Implied Upside / (Downside) | E10: =E8/E9-1 -> 0.33299752 | G10: Headquarters | I10: Redmond, WA | M10: Net Debt | P10: =J22-J21 -> 2711 | R10: WACC
G11: Primary Industry | I11: Software - Infrastructure | M11: Strategic Investment (OpenAI) | P11: =500000*0.27 -> 135000 | R11: Market Cap | T11: 3520000
B12: Last Updated | E12: 46024 | G12: Fiscal Year End | I12: 46203 | M12: Shares Outstanding | P12: 7466 | R12: % of Equity | U12: =T11/T22 -> 0.98307821
M13: Implied Market Cap | P13: =P9+P7-P10+P11 -> 4724564.7 | R13: Cost of Equity | U13: =U14+(U15*U17) -> 0.09117
R14: Risk Free Rate | U14: 0.04195
B15: Key Statistics | E15: 2021 | F15: =E15+1 -> 2022 | G15: =F15+1 -> 2023 | H15: =G15+1 -> 2024 | I15: =H15+1 -> 2025 | J15: 2026E | K15: 2027E | M15: Financial Ratios | R15: Beta | U15: 1.07
M16: PV of FCF | P16: =SUM(J97:N97) -> 0
B17: Stock Price | E17: 270.9 | F17: 256.83 | G17: 350.54 | H17: 446.95 | I17: 497.41 | J17: =NPV($U$7,K85:N85)/J18+(J21/J18)-(J22/J18)+(-((PV($U$7,4,0,$P$8))/J18))+(J85/J18)+(P11/J18) -> 661.40754 | K17: {=NPV($U$7,L85:N85)/K18+(K21/K18)-(K22/K18)+(-((PV($U$7,3,0,$P$8))/K18))+(SUM(J85:K85/K18))+(P11/K18)} -> 718.53723 | M17: Market Cap | P17: 3515070 | R17: Market Risk Premium | U17: 0.046
B18: shares outstanding diluted | E18: 7608 | F18: 7540 | G18: 7472 | H18: 7469 | I18: 7466 | J18: 7450 | K18: 7450 | M18: Enterprise Value | P18: =P17+P10 -> 3517781 | R18: Debt | U18: 60590
M19: P/E (LTM) | P19: 33.65 | R19: % of Debt | U19: =U18/T22 -> 0.016921792
B20: Market Cap | E20: =E18*E17 -> 2061007.2 | F20: =F18*F17 -> 1936498.2 | G20: =G18*G17 -> 2619234.9 | H20: =H18*H17 -> 3338269.5 | I20: =I18*I17 -> 3713663.1 | J20: =J17*J18 -> 4927486.2 | K20: =K17*K18 -> 5353102.4 | M20: P/E (NTM) | P20: 28.45 | R20: Cost of Debt | U20: 0.0511
B21: Cash | E21: 130256 | F21: 104749 | G21: 111256 | H21: 75543 | I21: 94565 | J21: 102012 | K21: 102012 | M21: P/S (LTM) | P21: 12.02 | R21: Tax Rate | U21: 0.19
B22: Debt | E22: =50084+21379 -> 71463 | F22: =47032+25331 -> 72363 | G22: =41990+28598 -> 70588 | H22: =42688+40293+6693 -> 89674 | I22: =40152+60437 -> 100589 | J22: =35376+69347 -> 104723 | K22: =35376+69347 -> 104723 | M22: EV/EBITDA (LTM) | P22: =P18/175768 -> 20.013774 | R22: Total | T22: =T11+U18 -> 3580590
B23: Enterprise Value | E23: =E20-E21+E22 -> 2002214.2 | F23: =F20-F21+F22 -> 1904112.2 | G23: =G20-G21+G22 -> 2578566.9 | H23: =H20-H21+H22 -> 3352400.5 | I23: =I20-I21+I22 -> 3719687.1 | J23: =J20-J21+J22 -> 4930197.2 | K23: =K20-K21+K22 -> 5355813.4 | R23: WACC | U23: =(U12*U13)+(U19*U20*(1-U21)) -> 0.09032765
B25: Income Statement | E25: 2021 | F25: =E25+1 -> 2022 | G25: =F25+1 -> 2023 | H25: =G25+1 -> 2024 | I25: =H25+1 -> 2025 | J25: 2026E | K25: 2027E | L25: 2028E | M25: 2029E | N25: 2030E
B27: Revenue | E27: 168088 | F27: 198270 | G27: 211915 | H27: 245122 | I27: 281724 | J27: =Segments!L24 -> 326350.34 | K27: =Segments!M24 -> 377478.46 | L27: =Segments!N24 -> 437847.37 | M27: =L27*1.155 -> 505713.71 | N27: =M27*1.145 -> 579042.2
B28: % growth | E28: =(E27-143015)/143015 -> 0.17531727 | F28: =(F27-E27)/E27 -> 0.17956071 | G28: =(G27-F27)/F27 -> 0.068820296 | H28: =(H27-G27)/G27 -> 0.15669962 | I28: =(I27-H27)/H27 -> 0.14932156 | J28: =(J27-I27)/I27 -> 0.15840447 | K28: =(K27-J27)/J27 -> 0.15666636 | L28: =(L27-K27)/K27 -> 0.15992677 | M28: =(M27-L27)/L27 -> 0.155 | N28: =(N27-M27)/M27 -> 0.145
B30: COGS | E30: 52232 | F30: 62650 | G30: 65863 | H30: 74114 | I30: 87831 | J30: =J27*0.32 -> 104432.11 | K30: =K27*0.32 -> 120793.11 | L30: =L27*0.32 -> 140111.16 | M30: =M27*0.32 -> 161828.39 | N30: =N27*0.32 -> 185293.5
B31: % of sales | E31: =E30/E27 -> 0.31074199 | F31: =F30/F27 -> 0.31598326 | G31: =G30/G27 -> 0.31079914 | H31: =H30/H27 -> 0.30235556 | I31: =I30/I27 -> 0.31176258 | J31: =J30/J27 -> 0.32 | K31: =K30/K27 -> 0.32 | L31: =L30/L27 -> 0.32 | ... N31: =N30/N27 -> 0.32
B33: Gross Income | E33: =E27-E30 -> 115856 | F33: =F27-F30 -> 135620 | G33: =G27-G30 -> 146052 | H33: =H27-H30 -> 171008 | I33: =I27-I30 -> 193893 | J33: =J27-J30 -> 221918.23 | K33: =K27-K30 -> 256685.35 | L33: =L27-L30 -> 297736.21 | ... N33: =N27-N30 -> 393748.7
B34: % of sales | E34: =E33/E27 -> 0.68925801 | F34: =F33/F27 -> 0.68401674 | G34: =G33/G27 -> 0.68920086 | H34: =H33/H27 -> 0.69764444 | I34: =I33/I27 -> 0.68823742 | J34: =J33/J27 -> 0.68 | K34: =K33/K27 -> 0.68 | L34: =L33/L27 -> 0.68 | ... N34: =N33/N27 -> 0.68
B36: SG&A | E36: 25224 | F36: 27725 | G36: 30334 | H36: 32065 | I36: 32877 | J36: =J27*0.12 -> 39162.041 | K36: =K27*0.11 -> 41522.631 | L36: =L27*0.105 -> 45973.974 | M36: =M27*0.105 -> 53099.94 | N36: =N27*0.105 -> 60799.431
B37: % of sales | E37: =E36/E27 -> 0.15006425 | F37: =F36/F27 -> 0.13983457 | G37: =G36/G27 -> 0.1431423 | H37: =H36/H27 -> 0.13081241 | I37: =I36/I27 -> 0.11669932 | J37: =J36/J27 -> 0.12 | K37: =K36/K27 -> 0.11 | L37: =L36/L27 -> 0.105 | ... N37: =N36/N27 -> 0.105
B39: R&D | E39: 20716 | F39: 24512 | G39: 27195 | H39: 29510 | I39: 32488 | J39: =J27*0.109 -> 35572.187 | K39: =K27*0.1055 -> 39823.978 | L39: =L27*0.104 -> 45536.127 | M39: =M27*0.1 -> 50571.371 | N39: =N27*0.1 -> 57904.22
B40: % of sales | E40: =E39/E27 -> 0.12324497 | F40: =F39/F27 -> 0.12362939 | G40: =G39/G27 -> 0.12832975 | H40: =H39/H27 -> 0.12038903 | I40: =I39/I27 -> 0.11531854 | J40: =J39/J27 -> 0.109 | K40: =K39/K27 -> 0.1055 | L40: =L39/L27 -> 0.104 | ... N40: =N39/N27 -> 0.1
B42: EBIT | E42: =E33-E36-E39 -> 69916 | F42: =F33-F36-F39 -> 83383 | G42: =G33-G36-G39 -> 88523 | H42: =H33-H36-H39 -> 109433 | I42: =I33-I36-I39 -> 128528 | J42: =J33-J36-J39 -> 147184 | K42: =K33-K36-K39 -> 175338.75 | L42: =L33-L36-L39 -> 206226.11 | ... N42: =N33-N36-N39 -> 275045.05
B43: % of sales | E43: =E42/E27 -> 0.41594879 | F43: =F42/F27 -> 0.42055278 | G43: =G42/G27 -> 0.41772881 | H43: =H42/H27 -> 0.446443 | I43: =I42/I27 -> 0.45621956 | J43: =J42/J27 -> 0.451 | K43: =K42/K27 -> 0.4645 | L43: =L42/L27 -> 0.471 | ... N43: =N42/N27 -> 0.475
B45: Taxes | E45: 9831 | F45: 10978 | G45: 16950 | H45: 19651 | I45: 21795 | J45: =J42*0.185 -> 27229.041 | K45: =K42*0.185 -> 32437.668 | L45: =L42*0.19 -> 39182.961 | M45: =M42*0.2 -> 48042.803 | N45: =N42*0.21 -> 57759.46
B46: Tax rate | E46: =E45/E42 -> 0.14061159 | F46: =F45/F42 -> 0.13165753 | G46: =G45/G42 -> 0.19147566 | H46: =H45/H42 -> 0.17957106 | I46: =I45/I42 -> 0.16957394 | J46: =J45/J42 -> 0.185 | K46: =K45/K42 -> 0.185 | L46: =L45/L42 -> 0.19 | ... N46: =N45/N42 -> 0.21
B48: Cash Flow Items | E48: 2021 | F48: =E48+1 -> 2022 | G48: =F48+1 -> 2023 | H48: =G48+1 -> 2024 | I48: =H48+1 -> 2025 | J48: 2026E | K48: 2027E | L48: 2028E | M48: 2029E | N48: 2030E
B50: D&A | E50: 11686 | F50: 14460 | G50: 13861 | H50: 22287 | I50: 34153 | J50: =J54*0.481 -> 47295.768 | K50: =K54*0.472 -> 54921.448 | L50: =L54*0.4785 -> 59575.226 | M50: =M54*0.4785 -> 57787.969 | N50: =N54*0.4785 -> 56632.21
B51: % of sales | E51: =E50/E27 -> 0.069523107 | F51: =F50/F27 -> 0.072930852 | G51: =G50/G27 -> 0.0654083 | H51: =H50/H27 -> 0.090922071 | I51: =I50/I27 -> 0.12122858 | J51: =J50/J27 -> 0.1449233 | K51: =K50/K27 -> 0.14549558 | L51: =L50/L27 -> 0.13606391 | ... N51: =N50/N27 -> 0.097803251
B52: % of capex | E52: =E50/E54 -> 0.56667637 | F52: =F50/F54 -> 0.60537553 | G52: =G50/G54 -> 0.49315117 | H52: =H50/H54 -> 0.50109045 | I52: =I50/I54 -> 0.52908553 | J52: =J50/J54 -> 0.481 | K52: =K50/K54 -> 0.472 | L52: =L50/L54 -> 0.4785 | ... N52: =N50/N54 -> 0.4785
B54: CapEx | E54: 20622 | F54: 23886 | G54: 28107 | H54: 44477 | I54: 64551 | J54: 98328 | K54: 116359 | L54: =K54*1.07 -> 124504.13 | M54: =L54*0.97 -> 120769.01 | N54: =M54*0.98 -> 118353.63
...

Sheet Segments
B2: Notes: | C2: Segments were reorganized in FY25, Metrics before 2023 may be unreliable
B4: Product Segments | G4: 2021 | H4: =G4+1 -> 2022 | I4: =H4+1 -> 2023 | J4: =I4+1 -> 2024 | K4: =J4+1 -> 2025 | L4: 2026E | M4: 2027E | N4: 2028E | O4: 2029E | P4: 2030E
A6: x | B6: Productivity and Business Processes | G6: 53915 | H6: 63364 | I6: 94151 | J6: 106820 | K6: 120810 | L6: =K6*1.132 -> 136756.92 | M6: =M8+M9+M10+M11 -> 153673.59 | N6: =M6*1.11 -> 170577.69
B7: % growth | G7: =(G6-46398)/46398 -> 0.16201129 | H7: =(H6-G6)/G6 -> 0.17525735 | I7: =(I6-H6)/H6 -> 0.48587526 | J7: =(J6-I6)/I6 -> 0.13456044 | K7: =(K6-J6)/J6 -> 0.13096798 | L7: =(L6-K6)/K6 -> 0.132 | M7: =(M6-L6)/L6 -> 0.12369884 | N7: =(N6-M6)/M6 -> 0.11
B8: - Microsoft 365 Commercial Products and Cloud Services | G8: =(39872)*0.91 -> 36283.52 | H8: =(44862)*0.91 -> 40824.42 | I8: 66949 | J8: 79969 | K8: 87767 | L8: =K8*1.1 -> 96543.7 | M8: =L8*1.16 -> 111990.69 | N8: =M8*1.125 -> 125989.53
B9: - Microsoft 365 Consumer Products and Cloud Services | G9: =(39872)*0.09 -> 3588.48 | H9: =(44862)*0.09 -> 4037.58 | I9: 6417 | J9: 6648 | K9: 7404 | L9: 8284.33 | M9: 10179
B10: - Dynamics Products and Cloud Services | G10: 3754 | H10: 4687 | I10: 5796 | J10: 6831 | K10: 7827 | L10: 8992.5 | M10: 10489.7
B11: - LinkedIn | G11: 10289 | H11: 13816 | I11: 14989 | J11: 16372 | K11: 17812 | L11: 19492.4 | M11: 21014.2 | N11: =M11*1.01 -> 21224.342
A13: x | B13: Intelligent Cloud | G13: 60080 | H13: 74965 | I13: 72944 | J13: =J15+J16+42 -> 87464 | K13: =K15+K16+70 -> 106265 | L13: =134294+495 -> 134789 | M13: 168062 | N13: =M13*1.25 -> 210077.5
B14: % growth | G14: =(G13-51700)/51700 -> 0.16208897 | H14: =(H13-G13)/G13 -> 0.247753 | I14: =(I13-H13)/H13 -> -0.026959248 | J14: =(J13-I13)/I13 -> 0.19905681 | K14: =(K13-J13)/J13 -> 0.21495701 | L14: =(L13-K13)/K13 -> 0.26842328 | M14: =(M13-L13)/L13 -> 0.24685249 | N14: =(N13-M13)/M13 -> 0.25
B15: - Server Products and Cloud Services | G15: 52589 | H15: 67350 | I15: 65007 | J15: 79828 | K15: 98435 | L15: 126629 | M15: 162267 | N15: 208714
B16: - Enterprise and partner services | G16: 6943 | H16: 7407 | I16: 7722 | J16: 7594 | K16: 7760 | L16: 8096 | M16: 8358.33
B18: More Personal Computing | G18: 54093 | H18: 59941 | I18: 44820 | J18: =J20+J21+J22+3 -> 50838 | K18: =K20+K21+K22+2 -> 54649 | L18: =SUM(L20:L22) -> 54804.42 | M18: =SUM(M20:M22) -> 55742.869 | N18: =M18*1.026 -> 57192.184
A19: x | B19: % growth | G19: =(G18-48251)/48251 -> 0.12107521 | H19: =(H18-G18)/G18 -> 0.10811011 | I19: =(I18-H18)/H18 -> -0.25226473 | J19: =(J18-I18)/I18 -> 0.13427041 | K19: =(K18-J18)/J18 -> 0.07496361 | L19: =(L18-K18)/K18 -> 0.0028439679 | M19: =(M18-L18)/L18 -> 0.017123604 | N19: =(N18-M18)/M18 -> 0.026
B20: - Windows and Devices | G20: =22488+7143 -> 29631 | H20: =24732+4687 -> 29419 | I20: 17147 | J20: 17026 | K20: 17314 | L20: =K20*0.94 -> 16275.16 | M20: =L20*0.99 -> 16112.408
B21: - Search and News Advertising | G21: 7407 | H21: 7722 | I21: 12125 | J21: 12306 | K21: 13878 | L21: =K21*1.12 -> 15543.36 | M21: =L21*1.13 -> 17563.997
B22: - Gaming | G22: 15370 | H22: 16230 | I22: 15466 | J22: 21503 | K22: 23455 | L22: =K22*0.98 -> 22985.9 | M22: =L22*0.96 -> 22066.464
B24: Total Sales | G24: =G18+G13+G6 -> 168088 | H24: =H18+H13+H6 -> 198270 | I24: =I18+I13+I6 -> 211915 | J24: =J18+J13+J6 -> 245122 | K24: =K18+K13+K6 -> 281724 | L24: =L18+L13+L6 -> 326350.34 | M24: =M18+M13+M6 -> 377478.46 | N24: =N18+N13+N6 -> 437847.37
B26: Operating Income by Segment | G26: 2021 | H26: =G26+1 -> 2022 | I26: =H26+1 -> 2023 | J26: =I26+1 -> 2024 | K26: =J26+1 -> 2025 | L26: 2026E | M26: 2027E | N26: 2028E | O26: 2029E | P26: 2030E
B28: Productivity and Business Processes | G28: 24351 | H28: 29690 | I28: 50074 | J28: 59661 | K28: 69773 | L28: =L6*0.5758 -> 78744.635 | M28: =M6*0.5555 -> 85365.68 | N28: =N6*0.58 -> 98935.059
B29: % of Sales | G29: =G28/G6 -> 0.45165538 | H29: =H28/H6 -> 0.46856259 | I29: =I28/I6 -> 0.53184778 | J29: =J28/J6 -> 0.558519 | K29: =K28/K6 -> 0.57754325 | L29: =L28/L6 -> 0.5758 | M29: =M28/M6 -> 0.5555 | N29: =N28/N6 -> 0.58
B31: Intelligent Cloud | G31: 26126 | H31: 33203 | I31: 28411 | J31: 37813 | K31: 44589 | L31: =L13*0.435 -> 58633.215 | M31: =M13*0.44925 -> 75501.853 | N31: =N13*0.447 -> 93904.643
B32: % of Sales | G32: =G31/G13 -> 0.43485353 | H32: =H31/H13 -> 0.44291336 | I32: =I31/I13 -> 0.38949057 | J32: =J31/J13 -> 0.43232644 | K32: =K31/K13 -> 0.41960194 | L32: =L31/L13 -> 0.435 | M32: =M31/M13 -> 0.44925 | N32: =N31/N13 -> 0.447
B34: More Personal Computing | G34: 19439 | H34: 20490 | I34: 10038 | J34: 11959 | K34: 14166 | L34: =L18*0.2623 -> 14375.199 | M34: =M18*0.263 -> 14660.375 | N34: =N18*0.265 -> 15155.929
B35: % of Sales | G35: =G34/G18 -> 0.35936258 | H35: =H34/H18 -> 0.34183614 | I35: =I34/I18 -> 0.22396252 | J35: =J34/J18 -> 0.23523742 | K35: =K34/K18 -> 0.25921792 | L35: =L34/L18 -> 0.2623 | M35: =M34/M18 -> 0.263 | N35: =N34/N18 -> 0.265
B37: Total Operating Income | G37: =G28+G31+G34 -> 69916 | H37: =H28+H31+H34 -> 83383 | I37: =I28+I31+I34 -> 88523 | J37: =J28+J31+J34 -> 109433 | K37: =K28+K31+K34 -> 128528 | L37: =L28+L31+L34 -> 151753.05 | M37: =M28+M31+M34 -> 175527.91 | N37: =N28+N31+N34 -> 207995.63
B39: Revenue Segments by Country | G39: 2021 | H39: =G39+1 -> 2022 | I39: =H39+1 -> 2023 | J39: =I39+1 -> 2024 | K39: =J39+1 -> 2025 | L39: 2026E | M39: 2027E | N39: 2028E | O39: 2029E | P39: 2030E
B41: United States | G41: 83953 | H41: 100218 | I41: 106744 | J41: 124704 | K41: 144546
B42: % growth | G42: =(G41-73160)/73160 -> 0.14752597 | H42: =(H41-G41)/G41 -> 0.19373935 | I42: =(I41-H41)/H41 -> 0.065118043 | J42: =(J41-I41)/I41 -> 0.16825302 | K42: =(K41-J41)/J41 -> 0.15911278
B43: Other Countries | G43: 84135 | H43: 98052 | I43: 105171 | J43: 120518 | K43: 137178
B44: % growth | G44: =(G43-69855)/69855 -> 0.20442345 | H44: =(H43-G43)/G43 -> 0.16541273 | I44: =(I43-H43)/H43 -> 0.072604332 | J44: =(J43-I43)/I43 -> 0.14592426 | K44: =(K43-J43)/J43 -> 0.13823661
B46: Industry Metrics | G46: 2021 | H46: =G46+1 -> 2022 | I46: =H46+1 -> 2023 | J46: =I46+1 -> 2024 | K46: =J46+1 -> 2025 | L46: 2026E | M46: 2027E | N46: 2028E | O46: 2029E | P46: 2030E
B48: Billings | G48: 173049 | H48: 202537 | I48: 217320 | J48: 268695 | K48: 288805 | L48: 333705 | M48: - | N48: -
B49: Total Commercial RPO | G49: 141000 | H49: 189000 | I49: 224000 | J49: 269000 | K49: 368000 | L49: 392000
B50: Azure Revenue YoY Growth % | G50: 0.498 | H50: 0.45 | I50: 0.29 | J50: 0.3 | K50: 0.342 | L50: 0.38 | M50: 0.343 | N50: 0.281
B51: Azure Constant Currency Revenue Yoy Growth % | H51: 0.47 | I51: 0.34 | J51: 0.29 | K51: 0.347 | L51: 0.375 | M51: 0.345 | N51: 0.297
B52: Capex Including Finance Leases | I52: 31900 | J52: 55700 | K52: 88200 | L52: =K52*1.62 -> 142884 | M52: =L52*1.116 -> 159458.54 | N52: =M52*1.045 -> 166634.18
B53: Recurring Revenue | L53: =Main!J27*L55 -> 246916.67 | M53: =Main!K27*M55 -> 288318.05 | N53: =Main!L27*N55 -> 336441.92
B54: Non Recurring Revenue | L54: =Main!J27-L53 -> 79433.673 | M54: =Main!K27-M53 -> 89160.413 | N54: =Main!L27-N53 -> 101405.45
B55: Recurring % of Revenue | L55: 0.7566 | M55: 0.7638 | N55: 0.7684
...

Sheet Extras
B2: Reinvestment Rate | E2: 2021 | F2: 2022 | G2: 2023 | H2: 2024 | I2: 2025 | J2: 2026E | K2: 2027E | L2: 2028E | M2: 2029E | N2: 2030E | P2: MSFT (CY) | R2: Q1 21 | S2: Q2 21 | T2: Q3 21 | U2: Q4 21 | V2: Q1 22 | W2: Q2 22 | X2: Q3 22 | Y2: Q4 22 | Z2: Q1 23 | AA2: Q2 23 | AB2: Q3 23 | AC2: Q4 23 | AD2: Q1 24 | AE2: Q2 24 | AF2: Q3 24 | AG2: Q4 24 | AH2: Q1 25 | AI2: Q2 25 | AJ2: Q3 25 | AK2: Q4 25
B3: Free Cash Flow | E3: 56118 | F3: 65149 | G3: 59475 | H3: 74071 | I3: 71611 | J3: 75264.927 | K3: 82894.544 | L3: 104408.57 | M3: 150978.85 | N3: 178723.14 | P3: Real EPS | R3: 1.95 | S3: 2.17 | T3: 2.27 | U3: 2.48 | V3: 2.22 | W3: 2.23 | X3: 2.35 | Y3: 2.32 | Z3: 2.45 | AA3: 2.69 | AB3: 2.99 | AC3: 2.93 | AD3: 2.94 | AE3: 2.95 | AF3: 3.3 | AG3: 3.23 | AH3: 3.46 | AI3: 3.65 | AJ3: 4.13
B4: CapEx | E4: =Main!E54 -> 20622 | F4: =Main!F54 -> 23886 | G4: =Main!G54 -> 28107 | H4: =Main!H54 -> 44477 | I4: =Main!I54 -> 64551 | J4: =Main!J54 -> 98328 | K4: =Main!K54 -> 116359 | L4: =Main!L54 -> 124504.13 | ... N4: =Main!N54 -> 118353.63 | P4: Consensus EPS | R4: 1.7813 | S4: 1.91802 | T4: 2.07687 | U4: 2.31896 | V4: 2.18879 | W4: 2.29224 | X4: 2.30459 | Y4: 2.29332 | Z4: 2.2391 | AA4: 2.55063 | AB4: 2.65401 | AC4: 2.77132 | AD4: 2.82464 | AE4: 2.9375 | AF4: 3.10122 | AG4: 3.11949 | AH4: 3.22222 | AI4: 3.37471 | AJ4: 3.67156
B5: Operating Cash Flow | E5: =E3+E4 -> 76740 | F5: =F3+F4 -> 89035 | G5: =G3+G4 -> 87582 | H5: =H3+H4 -> 118548 | I5: =I3+I4 -> 136162 | J5: =J3+J4 -> 173592.93 | K5: =K3+K4 -> 199253.54 | L5: =L3+L4 -> 228912.7 | ... N5: =N3+N4 -> 297076.76 | P5: Surprise % | R5: =R3/R4-1 -> 0.094706114 | S5: =S3/S4-1 -> 0.13137506 | T5: =T3/T4-1 -> 0.092990895 | U5: =U3/U4-1 -> 0.069444924 | V5: =V3/V4-1 -> 0.01425902 | W5: =W3/W4-1 -> -0.02715248 | X5: =X3/X4-1 -> 0.019704156 | Y5: =Y3/Y4-1 -> 0.011633789 | ... AJ5: =AJ3/AJ4-1 -> 0.12486246
B6: CapEx % of OCF | E6: =E4/E5 -> 0.26872557 | F6: =F4/F5 -> 0.26827652 | G6: =G4/G5 -> 0.32092211 | H6: =H4/H5 -> 0.37518136 | I6: =I4/I5 -> 0.474075 | J6: =J4/J5 -> 0.56642861 | K6: =K4/K5 -> 0.58397456 | L6: =L4/L5 -> 0.54389351 | ... N6: =N4/N5 -> 0.39839409 | P6: Real Revenue | R6: 41706 | S6: 46152 | T6: 45317 | U6: 51728 | V6: 49360 | W6: 51865 | X6: 50122 | Y6: 52747 | Z6: 52857 | AA6: 56189 | AB6: 56517 | AC6: 62020 | AD6: 61858 | AE6: 64727 | AF6: 65585 | AG6: 69632 | AH6: 70066 | AI6: 76441 | AJ6: 77673
P7: Consensus Revenue | R7: 41035.5 | S7: 44260.4 | T7: 44011.8 | U7: 50745.5 | V7: 49022.6 | W7: 52384.3 | X7: 49609.2 | Y7: 52986.7 | Z7: 51018.6 | AA7: 55485.4 | AB7: 54523.4 | AC7: 61140.9 | AD7: 60846 | AE7: 64382.3 | AF7: 64562.4 | AG7: 68816.7 | AH7: 68439.9 | AI7: 73961.1 | AJ7: 75494.7
B8: Azure | E8: Notes | J8: Management | P8: Surprise % | R8: =R6/R7-1 -> 0.016339511 | S8: =S6/S7-1 -> 0.042737978 | T8: =T6/T7-1 -> 0.029655683 | U8: =U6/U7-1 -> 0.019361323 | V8: =V6/V7-1 -> 0.0068825399 | W8: =W6/W7-1 -> -0.0099132755 | X8: =X6/X7-1 -> 0.010336792 | Y8: =Y6/Y7-1 -> -0.0045237767 | ... AJ8: =AJ6/AJ7-1 -> 0.028853681
B9: Azure Arc | E9: 36,000 customers - FY 2024 | J9: Satya Nadella | L9: CEO
B10: Azure Compute | J10: Judson Althoff | L10: CEO, Commercial Business | P10: Average Surprise EPS | S10: =AVERAGE(R5:AJ5) -> 0.061289326
B11: Azure Storage | J11: Amy Hood | L11: CFO | P11: Best Surprise EPS | S11: =MAX(R5:AJ5) -> 0.13137506
B12: Azure Networking | E12: Connects cloud and on-premise | J12: Brad Smith | L12: Vice Chair and President | P12: Worst Surprise EPS | S12: =MIN(R5:AJ5) -> -0.02715248
B13: Azure Security | E13: Sentinel, Defender, Monitor | J13: Mustafa Suleyman | L13: CEO, Microsoft AI | P13: Average Surprise Revenue | S13: =AVERAGE(R8:AJ8) -> 0.018228913
B14: Azure SQL | E14: relational database | J14: Phil Spencer | L14: CEO, Microsoft Gaming | P14: Best Surprise Revenue | S14: =MAX(R8:AJ8) -> 0.042737978
B15: OpenAI | E15: 60,000 Azure AI customers - FY 2024 | J15: Kevin Scott | L15: EVP, CTO | P15: Worst Surprise Revenue | S15: =MIN(R8:AJ8) -> -0.0099132755
B16: Intelligent Data Platform | E16: 50% YoY - FY 2024 | J16: Takeshi Numoto | L16: EVP, CMO
B17: Fabric | E17: compute, storage, governance | J17: Kathleen Hogan | L17: EVP, CPO
B18: AI Studio | E18: 25,000 paid customers - FY 2024 | J18: Alice Jolla | L18: CAO
B19: Cloud for Sustainability | J19: Keith Dolliver | L19: Deputy GC
B20: Nuance DAX ambient intelligence | E20: Ambient Clinical Intelligence | J20: Brett Iversen | L20: VP of Investor Relations
B21: DAX Express | E21: AI-powered clinical documentation
B23: Productivity | E23: Notes
B24: Github | E24: 2B ARR - Aug 2024, 100M+ devs
B25: Github Actions | E25: CI/CD automation
B26: Azure DevOps | E26: Enterprise planning and delivery
B27: .NET | E27: 5M+ active developers
B28: Visual Studio | E28: IDE - 29% professional market share
B29: Github Copilot | E29: 2.3 million paid subscribers
B30: Copilot Studio | E30: 18,000 organizations - custom agents
B31: VS Code | E31: Most Popular IDE - 76% market share
B32: Power BI | E32: 375,000 organizations - Oct 2024
B33: Power Pages | E33: No Code
... B43: OneDrive | E43: Cloud storage - tracked under M365
B44: SharePoint | F44: 200m+ MAUs
B45: Microsoft Teams | F45: 360M MAUs
B46: Teams Premium | E46: Seats gew 40% YoY - Sept 2025
B47: Teams Phone | E47: >17m users - 2024
B48: Teams Rooms | E48: Physical meeting room software
B49: Viva | E49: Viva Goals retired Dec 31, 2025
B50: LinkedIn | E50: $16.8B - FY 2025
B51: Loop | F51: Notion Alternative
...

Sheet Charts
B3: 1
B5: Charge Chart

Sheet Data
A1: Metric | B1: Category | C1: Year | D1: Value
A2: Stock Price | B2: Key Statistics | C2: 2021 | D2: 270.9 | F2: Category | G2: (Multiple Items) | I2: =NA() -> #N/A
A3: Stock Price | B3: Key Statistics | C3: 2022 | D3: 256.83
A4: Stock Price | B4: Key Statistics | C4: 2023 | D4: 350.54 | F4: Sum of Value | G4: Column Labels
A5: Stock Price | B5: Key Statistics | C5: 2024 | D5: 446.95 | F5: Row Labels | G5: CapEx | H5: CapEx % of Sales
A6: Stock Price | B6: Key Statistics | C6: 2025 | D6: 497.41 | F6: 2021 | G6: 20622 | H6: 0.1227
A7: Stock Price | B7: Key Statistics | C7: 2026E | D7: 661.41 | F7: 2022 | G7: 23886 | H7: 0.1205
A8: Stock Price | B8: Key Statistics | C8: 2027E | D8: 718.54 | F8: 2023 | G8: 28107 | H8: 0.1326
A9: Shares Outstanding | B9: Key Statistics | C9: 2021 | D9: 7608 | F9: 2024 | G9: 44477 | H9: 0.1814
A10: Shares Outstanding | B10: Key Statistics | C10: 2022 | D10: 7540 | F10: 2025 | G10: 64551 | H10: 0.2291
A11: Shares Outstanding | B11: Key Statistics | C11: 2023 | D11: 7472 | F11: 2026E | G11: 98328 | H11: 0.3013
A12: Shares Outstanding | B12: Key Statistics | C12: 2024 | D12: 7469 | F12: 2027E | G12: 116359 | H12: 0.3083
A13: Shares Outstanding | B13: Key Statistics | C13: 2025 | D13: 7466 | F13: 2028E | G13: 124504.13 | H13: 0.2844
A14: Shares Outstanding | B14: Key Statistics | C14: 2026E | D14: 7450 | F14: 2029E | G14: 120769.01 | H14: 0.2388
A15: Shares Outstanding | B15: Key Statistics | C15: 2027E | D15: 7450 | F15: 2030E | G15: 118353.63 | H15: 0.2044
A16: Market Cap | B16: Key Statistics | C16: 2021 | D16: 2061007.2
A17: Market Cap | B17: Key Statistics | C17: 2022 | D17: 1936498.2 | J17: =IF(ABS(G6)>1,G$5,IF(ABS(H6)>1,H$5,"")) -> CapEx | K17: =IF(ABS(G6)<=1,G$5,IF(ABS(H6)<=1,H$5,"")) -> CapEx % of Sales
A18: Market Cap | B18: Key Statistics | C18: 2023 | D18: 2619234.9 | I18: {=F6:F15} -> 2021 | J18: =IF(ABS(G6)>1, IF(G6=0,NA(),G6), IF(ABS(H6)>1, IF(H6=0,NA(),H6), NA() ) ) -> 20622 | K18: =IF(ABS(G6)<=1, IF(G6=0,NA(),G6), IF(ABS(H6)<=1, IF(H6=0,NA(),H6), NA() ) ) -> 0.1227
A19: Market Cap | B19: Key Statistics | C19: 2024 | D19: 3338269.5 | I19: 2022 | J19: =IF(ABS(G7)>1, IF(G7=0,NA(),G7), IF(ABS(H7)>1, IF(H7=0,NA(),H7), NA() ) ) -> 23886 | K19: =IF(ABS(G7)<=1, IF(G7=0,NA(),G7), IF(ABS(H7)<=1, IF(H7=0,NA(),H7), NA() ) ) -> 0.1205
A20: Market Cap | B20: Key Statistics | C20: 2025 | D20: 3713663.1 | I20: 2023 | J20: =IF(ABS(G8)>1, IF(G8=0,NA(),G8), IF(ABS(H8)>1, IF(H8=0,NA(),H8), NA() ) ) -> 28107 | K20: =IF(ABS(G8)<=1, IF(G8=0,NA(),G8), IF(ABS(H8)<=1, IF(H8=0,NA(),H8), NA() ) ) -> 0.1326
A21: Market Cap | B21: Key Statistics | C21: 2026E | D21: 4927486.2 | I21: 2024 | J21: =IF(ABS(G9)>1, IF(G9=0,NA(),G9), IF(ABS(H9)>1, IF(H9=0,NA(),H9), NA() ) ) -> 44477 | K21: =IF(ABS(G9)<=1, IF(G9=0,NA(),G9), IF(ABS(H9)<=1, IF(H9=0,NA(),H9), NA() ) ) -> 0.1814
A22: Market Cap | B22: Key Statistics | C22: 2027E | D22: 5353102.4 | I22: 2025 | J22: =IF(ABS(G10)>1, IF(G10=0,NA(),G10), IF(ABS(H10)>1, IF(H10=0,NA(),H10), NA() ) ) -> 64551 | K22: =IF(ABS(G10)<=1, IF(G10=0,NA(),G10), IF(ABS(H10)<=1, IF(H10=0,NA(),H10), NA() ) ) -> 0.2291
A23: Cash | B23: Key Statistics | C23: 2021 | D23: 130256 | I23: 2026E | J23: =IF(ABS(G11)>1, IF(G11=0,NA(),G11), IF(ABS(H11)>1, IF(H11=0,NA(),H11), NA() ) ) -> 98328 | K23: =IF(ABS(G11)<=1, IF(G11=0,NA(),G11), IF(ABS(H11)<=1, IF(H11=0,NA(),H11), NA() ) ) -> 0.3013
A24: Cash | B24: Key Statistics | C24: 2022 | D24: 104749 | I24: 2027E | J24: =IF(ABS(G12)>1, IF(G12=0,NA(),G12), IF(ABS(H12)>1, IF(H12=0,NA(),H12), NA() ) ) -> 116359 | K24: =IF(ABS(G12)<=1, IF(G12=0,NA(),G12), IF(ABS(H12)<=1, IF(H12=0,NA(),H12), NA() ) ) -> 0.3083
A25: Cash | B25: Key Statistics | C25: 2023 | D25: 111256 | I25: 2028E | J25: =IF(ABS(G13)>1, IF(G13=0,NA(),G13), IF(ABS(H13)>1, IF(H13=0,NA(),H13), NA() ) ) -> 124504.13 | K25: =IF(ABS(G13)<=1, IF(G13=0,NA(),G13), IF(ABS(H13)<=1, IF(H13=0,NA(),H13), NA() ) ) -> 0.2844
A26: Cash | B26: Key Statistics | C26: 2024 | D26: 75543 | I26: 2029E | J26: =IF(ABS(G14)>1, IF(G14=0,NA(),G14), IF(ABS(H14)>1, IF(H14=0,NA(),H14), NA() ) ) -> 120769.01 | K26: =IF(ABS(G14)<=1, IF(G14=0,NA(),G14), IF(ABS(H14)<=1, IF(H14=0,NA(),H14), NA() ) ) -> 0.2388
A27: Cash | B27: Key Statistics | C27: 2025 | D27: 94565 | I27: 2030E | J27: =IF(ABS(G15)>1, IF(G15=0,NA(),G15), IF(ABS(H15)>1, IF(H15=0,NA(),H15), NA() ) ) -> 118353.63 | K27: =IF(ABS(G15)<=1, IF(G15=0,NA(),G15), IF(ABS(H15)<=1, IF(H15=0,NA(),H15), NA() ) ) -> 0.2044
A28: Cash | B28: Key Statistics | C28: 2026E | D28: 102012
A29: Cash | B29: Key Statistics | C29: 2027E | D29: 102012
A30: Debt | B30: Key Statistics | C30: 2021 | D30: 71463
A31: Debt | B31: Key Statistics | C31: 2022 | D31: 72363
A32: Debt | B32: Key Statistics | C32: 2023 | D32: 70588
A33: Debt | B33: Key Statistics | C33: 2024 | D33: 89674
A34: Debt | B34: Key Statistics | C34: 2025 | D34: 100589
A35: Debt | B35: Key Statistics | C35: 2026E | D35: 104723
A36: Debt | B36: Key Statistics | C36: 2027E | D36: 104723
A37: Enterprise Value | B37: Key Statistics | C37: 2021 | D37: 2002214.2
A38: Enterprise Value | B38: Key Statistics | C38: 2022 | D38: 1904112.2
A39: Enterprise Value | B39: Key Statistics | C39: 2023 | D39: 2578566.9
... A433: Other Countries Revenue % Growth | B433: Revenue by Country | C433: 2025 | D433: 0.1382

Sheet Data2
A1: Metric | B1: Category | C1: 2021 | D1: 2022 | E1: 2023 | F1: 2024 | G1: 2025 | H1: 2026E | I1: 2027E | J1: 2028E | K1: 2029E | L1: 2030E
A2: Stock Price | B2: Key Statistics | C2: 270.9 | D2: 256.83 | E2: 350.54 | F2: 446.95 | G2: 497.41 | H2: 661.41 | I2: 718.54
A3: Shares Outstanding | B3: Key Statistics | C3: 7608 | D3: 7540 | E3: 7472 | F3: 7469 | G3: 7466 | H3: 7450 | I3: 7450
A4: Market Cap | B4: Key Statistics | C4: 2061007.2 | D4: 1936498.2 | E4: 2619234.9 | F4: 3338269.5 | G4: 3713663.1 | H4: 4927486.2 | I4: 5353102.4
A5: Cash | B5: Key Statistics | C5: 130256 | D5: 104749 | E5: 111256 | F5: 75543 | G5: 94565 | H5: 102012 | I5: 102012
A6: Debt | B6: Key Statistics | C6: 71463 | D6: 72363 | E6: 70588 | F6: 89674 | G6: 100589 | H6: 104723 | I6: 104723
A7: Enterprise Value | B7: Key Statistics | C7: 2002214.2 | D7: 1904112.2 | E7: 2578566.9 | F7: 3352400.5 | G7: 3719687.1 | H7: 4930197.2 | I7: 5355813.4
A8: Revenue | B8: Income Statement | C8: 168088 | D8: 198270 | E8: 211915 | F8: 245122 | G8: 281724 | H8: 326350.34 | I8: 377478.46 | J8: 437847.37 | K8: 505713.71 | L8: 579042.2
A9: COGS | B9: Income Statement | C9: 52232 | D9: 62650 | E9: 65863 | F9: 74114 | G9: 87831 | H9: 104432.11 | I9: 120793.11 | J9: 140111.16 | K9: 161828.39 | L9: 185293.5
A10: Gross Income | B10: Income Statement | C10: 115856 | D10: 135620 | E10: 146052 | F10: 171008 | G10: 193893 | H10: 221918.23 | I10: 256685.35 | J10: 297736.21 | K10: 343885.33 | L10: 393748.7
A11: SG&A | B11: Income Statement | C11: 25224 | D11: 27725 | E11: 30334 | F11: 32065 | G11: 32877 | H11: 39162.04 | I11: 41522.63 | J11: 45973.97 | K11: 53099.94 | L11: 60799.43
A12: R&D | B12: Income Statement | C12: 20716 | D12: 24512 | E12: 27195 | F12: 29510 | G12: 32488 | H12: 35572.19 | I12: 39823.98 | J12: 45536.13 | K12: 50571.37 | L12: 57904.22
A13: EBIT | B13: Income Statement | C13: 69916 | D13: 83383 | E13: 88523 | F13: 109433 | G13: 128528 | H13: 147184 | I13: 175338.75 | J13: 206226.11 | K13: 240214.01 | L13: 275045.05
A14: Taxes | B14: Income Statement | C14: 9831 | D14: 10978 | E14: 16950 | F14: 19651 | G14: 21795 | H14: 27229.04 | I14: 32437.67 | J14: 39182.96 | K14: 48042.8 | L14: 57759.46
A15: D&A | B15: Cash Flow | C15: 11686 | D15: 14460 | E15: 13861 | F15: 22287 | G15: 34153 | H15: 47295.77 | I15: 54921.45 | J15: 59575.23 | K15: 57787.97 | L15: 56632.21
A16: CapEx | B16: Cash Flow | C16: 20622 | D16: 23886 | E16: 28107 | F16: 44477 | G16: 64551 | H16: 98328 | I16: 116359 | J16: 124504.13 | K16: 120769.01 | L16: 118353.63
A17: Changes in NWC | B17: Cash Flow | C17: -940 | D17: 450 | E17: -2390 | F17: 1820 | G17: -5350 | H17: -1958.1 | I17: -1509.91 | J17: -875.69 | K17: -1011.43 | L17: 579.04
A18: EBIAT | B18: DCF | C18: 60085 | D18: 72405 | E18: 71573 | F18: 89782 | G18: 106733 | H18: 119954.96 | I18: 142901.08 | J18: 167043.15 | K18: 192171.21 | L18: 217285.59
A19: Stock Based Compensation | B19: DCF | C19: 6118 | D19: 7502 | E19: 9611 | F19: 10734 | G19: 11974 | H19: 12401.31 | I19: 14344.18 | J19: 16638.2 | K19: 19217.12 | L19: 22003.6
A20: Free Cash Flow | B20: DCF | C20: 56120 | D20: 65150 | E20: 59480 | F20: 74070 | G20: 71610 | H20: 83282.15 | I20: 97317.62 | J20: 119628.14 | K20: 149418.72 | L20: 176988.73
A21: Productivity and Business Processes | B21: Product Segments | C21: 53915 | D21: 63364 | E21: 94151 | F21: 106820 | G21: 120810 | H21: 136756.92 | I21: 153673.59 | J21: 170577.69
A22: Intelligent Cloud | B22: Product Segments | C22: 60080 | D22: 74965 | E22: 72944 | F22: 87464 | G22: 106265 | H22: 134789 | I22: 168062 | J22: 210077.5
A23: More Personal Computing | B23: Product Segments | C23: 54093 | D23: 59941 | E23: 44820 | F23: 50838 | G23: 54649 | H23: 54804.42 | I23: 55742.87 | J23: 57192.18
A24: Productivity and Business Processes - Operating Income | B24: Operating Income by Segment | C24: 24351 | D24: 29690 | E24: 50074 | F24: 59661 | G24: 69773 | H24: 78744.63 | I24: 85365.68 | J24: 98935.06
A25: Intelligent Cloud - Operating Income | B25: Operating Income by Segment | C25: 26126 | D25: 33203 | E25: 28411 | F25: 37813 | G25: 44589 | H25: 58633.22 | I25: 75501.85 | J25: 93904.64
A26: More Personal Computing - Operating Income | B26: Operating Income by Segment | C26: 19439 | D26: 20490 | E26: 10038 | F26: 11959 | G26: 14166 | H26: 14375.2 | I26: 14660.37 | J26: 15155.93
A27: Total Operating Income | B27: Operating Income by Segment | C27: 69916 | D27: 83383 | E27: 88523 | F27: 109433 | G27: 128528 | H27: 151753.05 | I27: 175527.91 | J27: 207995.63
A28: United States Revenue | B28: Revenue by Country | C28: 83953 | D28: 100218 | E28: 106744 | F28: 124704 | G28: 144546
A29: Other Countries Revenue | B29: Revenue by Country | C29: 84135 | D29: 98052 | E29: 105171 | F29: 120518 | G29: 137178
A30: Billings | B30: Industry Metrics | C30: 173049 | D30: 202537 | E30: 217320 | F30: 268695 | G30: 288805 | H30: 333705
A31: Total Commercial RPO | B31: Industry Metrics | C31: 141000 | D31: 189000 | E31: 224000 | F31: 269000 | G31: 368000 | H31: 392000
A32: Azure Revenue YoY Growth % | B32: Industry Metrics | C32: 0.498 | D32: 0.45 | E32: 0.29 | F32: 0.3 | G32: 0.342 | H32: 0.38 | I32: 0.343 | J32: 0.281
A33: Capex Including Finance Leases | B33: Industry Metrics | E33: 31900 | F33: 55700 | G33: 88200 | H33: 142884 | I33: 159458.54 | J33: 166634.18
A34: Revenue % Growth | B34: Income Statement | C34: 0.1753 | D34: 0.1796 | E34: 0.0688 | F34: 0.1567 | G34: 0.1493 | H34: 0.1584 | I34: 0.1567 | J34: 0.1599 | K34: 0.155 | L34: 0.145
A35: COGS % of Sales | B35: Income Statement | C35: 0.3107 | D35: 0.316 | E35: 0.3108 | F35: 0.3024 | G35: 0.3118 | H35: 0.32 | I35: 0.32 | J35: 0.32 | K35: 0.32 | L35: 0.32
A36: Gross Income % of Sales | B36: Income Statement | C36: 0.6893 | D36: 0.684 | E36: 0.6892 | F36: 0.6976 | G36: 0.6882 | H36: 0.68 | I36: 0.68 | J36: 0.68 | K36: 0.68 | L36: 0.68
A37: SG&A % of Sales | B37: Income Statement | C37: 0.1501 | D37: 0.1398 | E37: 0.1431 | F37: 0.1308 | G37: 0.1167 | H37: 0.12 | I37: 0.11 | J37: 0.105 | K37: 0.105 | L37: 0.105
A38: R&D % of Sales | B38: Income Statement | C38: 0.1232 | D38: 0.1236 | E38: 0.1283 | F38: 0.1204 | G38: 0.1153 | H38: 0.109 | I38: 0.1055 | J38: 0.104 | K38: 0.1 | L38: 0.1
A39: EBIT % of Sales | B39: Income Statement | C39: 0.4159 | D39: 0.4206 | E39: 0.4177 | F39: 0.4464 | G39: 0.4562 | H39: 0.451 | I39: 0.4645 | J39: 0.471 | K39: 0.475 | L39: 0.475
A40: D&A % of Sales | B40: Cash Flow | C40: 0.0695 | D40: 0.0729 | E40: 0.0654 | F40: 0.0909 | G40: 0.1212 | H40: 0.1449 | I40: 0.1455 | J40: 0.1361 | K40: 0.1143 | L40: 0.0978
...
