Workbook

Sheet Main
Q2: all values in millions except per share numbers
A4: x | B4: Company Overview | W4: 10 Year DCF | Y4: 2032 | Z4: =Y4+1 -> 2033 | AA4: =Z4+1 -> 2034 | AB4: =AA4+1 -> 2035 | AC4: =AB4+1 -> 2036
B6: Price | G6: Key Stats | M6: Valuation | R6: Notes | W6: Revenue | Y6: =N101*1.24 -> 258361.47 | Z6: =Y6*1.22 -> 315200.99 | AA6: =Z6*1.18 -> 371937.17 | AB6: =AA6*1.15 -> 427727.74 | AC6: =AB6*1.1 -> 470500.52
B7: Ticker | E7: SPCE | G7: Employees | I7: 13000 | M7: PV of FCF | P7: =SUM(I113:N113) -> -60139.328 | R7: WACC | U7: 0.1 | W7: % growth | Y7: =(Y6-N101)/N101 -> 0.24 | Z7: =(Z6-Y6)/Y6 -> 0.22 | AA7: =(AA6-Z6)/Z6 -> 0.18 | AB7: =(AB6-AA6)/AA6 -> 0.15 | AC7: =(AC6-AB6)/AB6 -> 0.1
B8: Implied Share Price | E8: =AVERAGE((P13/P12),(T23)) -> 184.35501 | G8: Founded | I8: 37329 | M8: Terminal Value | P8: =(N52*U8) -> 1709898.1 | R8: EV/EBITDA Multiple | U8: 25
B9: Price | E9: =1750000/H18 -> 301.82822 | G9: CEO | I9: Elon Musk | M9: PV of Terminal Value | P9: =-(PV(U7,(DATE(2031,12,31)-$D$12)/365,0,P8)) -> 1000869.3
B10: Implied Upside / (Downside) | E10: =E8/E9-1 -> -0.38920553 | G10: Headquarters | I10: Starbase, Texas | M10: Net Debt | P10: =H22-H21 -> 14413 | W10: Free Cash Flow | Y10: =Y6*0.22 -> 56839.523 | Z10: =Z6*0.23 -> 72496.228 | AA10: =AA6*0.24 -> 89264.92 | AB10: =AB6*0.25 -> 106931.94 | AC10: =AC6*0.25 -> 117625.13
B11: IRR | E11: =(I17/E9)^(1/2)-1 -> -0.11622038 | G11: Primary Industry | I11: Aerospace / Satcom / AI | M11: Bitcoin | P11: 1293 | W11: % of sales | Y11: 0.19 | Z11: 0.22 | AA11: 0.25 | AB11: 0.27 | AC11: 0.28
B12: Last Updated | D12: 46162 | G12: Fiscal Year End | I12: 46387 | M12: Shares Outstanding | P12: 5026
M13: Implied Market Cap | P13: =P9+P7-P10+P11 -> 927609.96 | R13: Share Price | U13: =P13/P12 -> 184.56227 | W13: Present Value of FCF | Y13: =Y10/(1+$U$7)^((DATE(2032,7,1)-$D$12)/365) -> 31717.906 | Z13: =Z10/(1+$U$7)^((DATE(2033,7,1)-$D$12)/365) -> 36777.043 | AA13: =AA10/(1+$U$7)^((DATE(2034,7,1)-$D$12)/365) -> 41167.03 | AB13: =AB10/(1+$U$7)^((DATE(2035,7,1)-$D$12)/365) -> 44831.52 | AC13: =AC10/(1+$U$7)^((DATE(2036,7,1)-$D$12)/365) -> 44819.814
A15: x | B15: Key Statistics | E15: 2023 | F15: 2024 | G15: 2025 | H15: 2026E | I15: 2027E | J15: 2028E | M15: Financial Ratios | R15: Gordon Growth Method
B17: Stock Price | E17: =180000/E18 -> 65.241029 | F17: =350000/F18 -> 122.89326 | G17: =800000/G18 -> 273.4108 | H17: =AVERAGE($U$13*(1+$U$7)-I110/H18,$T$23*(1+$U$7)-I110/H18) -> 209.75669 | I17: =AVERAGE($U$13*(1+$U$7)^2-(I110/H18)*(1+$U$7)-J110/I18,$T$23*(1+$U$7)^2-(I110/H18)*(1+$U$7)-J110/I18) -> 235.74788 | M17: PV of FCF | P17: =SUM(H116:L116) -> 0 | R17: FCF Value | T17: =SUM(I112:N112)+SUM((Y13:AC13)) -> 199313.31
B18: shares outstanding | E18: =F70 -> 2759 | F18: =G70 -> 2848 | G18: =H70 -> 2926 | H18: =I120 -> 5798 | I18: =J120 -> 6029.92 | M18: Market Cap | P18: =E9*P12 -> 1516988.6 | R18: Terminal Value | T18: =(AC10*(1+0.04)/($U$7-0.04))/(1+$U$7)^((DATE(2036,12,31)-$D$12)/365) -> 740626.25
M19: Enterprise Value | P19: =P18+P10 -> 1531401.6 | R19: Net Debt | T19: =P10 -> 14413
B20: Market Cap | E20: =E17*E18 -> 180000 | F20: =F17*F18 -> 350000 | G20: =G17*G18 -> 800000 | H20: =H17*H18 -> 1216169.3 | I20: =I17*I18 -> 1421540.9 | M20: P/E (LTM) | P20: =$P$18/H67 -> -307.26932 | R20: Strategic Investments
B21: Cash | E21: 4620 | F21: 11385 | G21: 24744 | H21: 15852 | M21: P/E (NTM) | P21: =$P$18/I67 -> -216.61535 | R21: Total | T21: =T17+T18-T19+T20 -> 925526.56
B22: Debt | F22: =13421+372 -> 13793 | G22: =21968+928 -> 22896 | H22: =28727+1538 -> 30265 | M22: EV/EBITDA (LTM) | P22: =P19/(H49+H78) -> 372.42257
B23: Enterprise Value | E23: =E20-E21+E22 -> 175380 | F23: =F20-F21+F22 -> 352408 | G23: =G20-G21+G22 -> 798152 | H23: =H20-H21+H22 -> 1230582.3 | I23: =I20-I21+I22 -> 1421540.9 | M23: EV/EBITDA (NTM) | P23: =P19/(I49+I78) -> 798.49687 | R23: Share Price | T23: =T21/P12 -> 184.14774
M24: EV/EBIT (LTM) | P24: =P19/H49 -> -591.50314
A26: x | B26: Income Statement ($M) | F26: 2023 | G26: 2024 | H26: 2025 | I26: 2026E | J26: 2027E | K26: 2028E | L26: 2029E | M26: 2030E | N26: 2031E
B28: Revenue | F28: 10387 | G28: 14015 | H28: 18674 | I28: =Segments!I14 -> 31125.087 | J28: =Segments!J14 -> 50787.839 | K28: =Segments!K14 -> 78808.082 | L28: =Segments!L14 -> 117434.13 | M28: =Segments!M14 -> 161900.47 | N28: =Segments!N14 -> 208356.02
B29: % growth | G29: =(G28-F28)/F28 -> 0.34928276 | H29: =(H28-G28)/G28 -> 0.33242954 | I29: =(I28-H28)/H28 -> 0.66676056 | J29: =(J28-I28)/I28 -> 0.63173327 | K29: =(K28-J28)/J28 -> 0.55171166 | L29: =(L28-K28)/K28 -> 0.49012803 | M29: =(M28-L28)/L28 -> 0.37864921 | N29: =(N28-M28)/M28 -> 0.28693893
B31: COGS | F31: 6110 | G31: 7996 | H31: 9451 | I31: =I28*0.5 -> 15562.543 | J31: =J28*0.49 -> 24886.041 | K31: =K28*0.48 -> 37827.88 | L31: =L28*0.47 -> 55194.042 | M31: =M28*0.46 -> 74474.218 | N31: =N28*0.45 -> 93760.21
B32: % of sales | F32: =F31/F28 -> 0.58823529 | G32: =G31/G28 -> 0.57053157 | H32: =H31/H28 -> 0.50610474 | I32: =I31/I28 -> 0.5 | J32: =J31/J28 -> 0.49 | K32: =K31/K28 -> 0.48 | L32: =L31/L28 -> 0.47 | M32: =M31/M28 -> 0.46 | N32: =N31/N28 -> 0.45
B34: Gross Profit | F34: =F28-F31 -> 4277 | G34: =G28-G31 -> 6019 | H34: =H28-H31 -> 9223 | I34: =I28-I31 -> 15562.543 | J34: =J28-J31 -> 25901.798 | K34: =K28-K31 -> 40980.203 | L34: =L28-L31 -> 62240.09 | M34: =M28-M31 -> 87426.256 | N34: =N28-N31 -> 114595.81
B35: % of sales | F35: =F34/F28 -> 0.41176471 | G35: =G34/G28 -> 0.42946843 | H35: =H34/H28 -> 0.49389526 | I35: =I34/I28 -> 0.5 | J35: =J34/J28 -> 0.51 | K35: =K34/K28 -> 0.52 | L35: =L34/L28 -> 0.53 | M35: =M34/M28 -> 0.54 | N35: =N34/N28 -> 0.55
B37: Research & Development | F37: 2105 | G37: 3464 | H37: 8643 | I37: =I28*0.6 -> 18675.052 | J37: =J28*0.3 -> 15236.352 | K37: =K28*0.2 -> 15761.616 | L37: =L28*0.2 -> 23486.827 | M37: =M28*0.2 -> 32380.095 | N37: =N28*0.2 -> 41671.204
B38: % of sales | F38: =F37/F$28 -> 0.20265717 | G38: =G37/G$28 -> 0.24716375 | H38: =H37/H$28 -> 0.46283603 | I38: =I37/I$28 -> 0.6 | J38: =J37/J$28 -> 0.3 | K38: =K37/K$28 -> 0.2 | L38: =L37/L$28 -> 0.2 | M38: =M37/M$28 -> 0.2 | N38: =N37/N$28 -> 0.2
B40: SG&A | F40: 1665 | G40: 1813 | H40: 2644 | I40: =I28*0.125 -> 3890.6358 | J40: =J28*0.12 -> 6094.5407 | K40: =K28*0.115 -> 9062.9295 | L40: =L28*0.11 -> 12917.755 | M40: =M28*0.105 -> 16999.55 | N40: =N28*0.1 -> 20835.602
B41: % of sales | F41: =F40/F$28 -> 0.16029652 | G41: =G40/G$28 -> 0.1293614 | H41: =H40/H$28 -> 0.14158723 | I41: =I40/I$28 -> 0.125 | J41: =J40/J$28 -> 0.12 | K41: =K40/K$28 -> 0.115 | L41: =L40/L$28 -> 0.11 | M41: =M40/M$28 -> 0.105 | N41: =N40/N$28 -> 0.1
B43: Restructuring | F43: 237 | G43: 213 | H43: 487
B44: % of sales | F44: =F43/F$28 -> 0.022816983 | G44: =G43/G$28 -> 0.015198002 | H44: =H43/H$28 -> 0.02607904 | I44: =I43/I$28 -> 0 | J44: =J43/J$28 -> 0 | K44: =K43/K$28 -> 0 | L44: =L43/L$28 -> 0 | M44: =M43/M$28 -> 0 | N44: =N43/N$28 -> 0
B46: Impairment | F46: 3775 | G46: 63 | H46: 38 | J46: 0 | K46: 0 | L46: 0 | M46: 0 | N46: 0
B47: % of sales | F47: =F46/F$28 -> 0.36343506 | G47: =G46/G$28 -> 0.0044951837 | H47: =H46/H$28 -> 0.0020349149 | I47: =I46/I$28 -> 0 | J47: =J46/J$28 -> 0 | K47: =K46/K$28 -> 0 | L47: =L46/L$28 -> 0 | M47: =M46/M$28 -> 0 | N47: =N46/N$28 -> 0
B49: Operating Income (EBIT) | F49: =F34-F37-F40-F43-F46 -> -3505 | G49: =G34-G37-G40-G43-G46 -> 466 | H49: =H34-H37-H40-H43-H46 -> -2589 | I49: =I34-I37-I40-I43-I46 -> -7003.1445 | J49: =J34-J37-J40-J43-J46 -> 4570.9055 | K49: =K34-K37-K40-K43-K46 -> 16155.657 | L49: =L34-L37-L40-L43-L46 -> 25835.509 | M49: =M34-M37-M40-M43-M46 -> 38046.611 | N49: =N34-N37-N40-N43-N46 -> 52089.005
B50: % of sales | F50: =F49/F$28 -> -0.33744103 | G50: =G49/G$28 -> 0.033250089 | H50: =H49/H$28 -> -0.13864196 | I50: =I49/I$28 -> -0.225 | J50: =J49/J$28 -> 0.09 | K50: =K49/K$28 -> 0.205 | L50: =L49/L$28 -> 0.22 | M50: =M49/M$28 -> 0.235 | N50: =N49/N$28 -> 0.25
B52: EBITDA | F52: =F49+F78 -> -870 | G52: =G49+G78 -> 4290 | H52: =H49+H78 -> 4112 | I52: =I49+I78 -> 1917.8555 | J52: =J49+J78 -> 16837.281 | K52: =K49+K78 -> 33083.254 | L52: =L49+L78 -> 41634.6 | M52: =M49+M78 -> 53394.3 | N52: =N49+N78 -> 68395.924
B53: % of sales | F53: =F52/F$28 -> -0.083758544 | G53: =G52/G$28 -> 0.30610061 | H53: =H52/H$28 -> 0.22019921 | I53: =I52/I$28 -> 0.061617676 | J53: =J52/J$28 -> 0.33152189 | K53: =K52/K$28 -> 0.4197952 | L53: =L52/L$28 -> 0.35453577 | M53: =M52/M$28 -> 0.32979706 | N53: =N52/N$28 -> 0.32826469
B55: Interest Income (Expense) | F55: =249-1693 -> -1444 | G55: =371-1580 -> -1209 | H55: =492-1945 -> -1453
B56: % of sales | F56: =F55/F$28 -> -0.13901993 | G56: =G55/G$28 -> -0.086264716 | H56: =H55/H$28 -> -0.077808718 | I56: =I55/I$28 -> 0 | J56: =J55/J$28 -> 0 | K56: =K55/K$28 -> 0 | L56: =L55/L$28 -> 0 | M56: =M55/M$28 -> 0 | N56: =N55/N$28 -> 0
...

Sheet Segments
K2: all values in millions except per share numbers
A4: x | B4: Levers | D4: 2026 | E4: 2031 | I4: 2026 | J4: 2031
B6: Mass to Orbit | D6: 556
B7: Launches | D7: 40
B8: Starlink Subs (m) | D8: 10.3
B9: Starlink ARPU | D9: 66
B10: AI Compute GW | D10: 1
A12: x | B12: Product Segments ($M) | F12: 2023 | G12: 2024 | H12: 2025 | I12: 2026E | J12: 2027E | K12: 2028E | L12: 2029E | M12: 2030E | N12: 2031E
B14: Revenue | F14: =F17+F26+F35 -> 10387 | G14: =G17+G26+G35 -> 14015 | H14: =H17+H26+H35 -> 18674 | I14: =I17+I26+I35 -> 31125.087 | J14: =J17+J26+J35 -> 50787.839 | K14: =K17+K26+K35 -> 78808.082 | L14: =L17+L26+L35 -> 117434.13 | M14: =M17+M26+M35 -> 161900.47 | N14: =N17+N26+N35 -> 208356.02
B15: % growth | G15: =(G14-F14)/F14 -> 0.34928276 | H15: =(H14-G14)/G14 -> 0.33242954 | I15: =(I14-H14)/H14 -> 0.66676056 | J15: =(J14-I14)/I14 -> 0.63173327 | K15: =(K14-J14)/J14 -> 0.55171166 | L15: =(L14-K14)/K14 -> 0.49012803 | M15: =(M14-L14)/L14 -> 0.37864921 | N15: =(N14-M14)/M14 -> 0.28693893
B17: Space | F17: =F20+F23 -> 3557 | G17: =G20+G23 -> 3796 | H17: =H20+H23 -> 4086 | I17: =I20+I23 -> 4117.8081 | J17: =J20+J23 -> 5647.5576 | K17: =K20+K23 -> 8041.3544 | L17: =L20+L23 -> 12031.016 | M17: =M20+M23 -> 17018.093 | N17: =N20+N23 -> 24000
B18: % growth | G18: =(G17-F17)/F17 -> 0.067191453 | H18: =(H17-G17)/G17 -> 0.076396207 | I18: =(I17-H17)/H17 -> 0.0077846616 | J18: =(J17-I17)/I17 -> 0.37149605 | K18: =(K17-J17)/J17 -> 0.42386409 | L18: =(L17-K17)/K17 -> 0.49614296 | M18: =(M17-L17)/L17 -> 0.41451834 | N18: =(N17-M17)/M17 -> 0.41026381
B20: Launch Services | F20: 1964 | G20: 2584 | H20: 2576 | I20: =H20*(1+((330-566)/566)+0.4) -> 2532.3081 | J20: =$I$20+($N$20-$I$20)*0.08 -> 3529.7235 | K20: =$I$20+($N$20-$I$20)*0.2 -> 5025.8465 | L20: =$I$20+($N$20-$I$20)*0.4 -> 7519.3849 | M20: =$I$20+($N$20-$I$20)*0.65 -> 10636.308 | N20: 15000
B21: % growth | G21: =(G20-F20)/F20 -> 0.31568228 | H21: =(H20-G20)/G20 -> -0.0030959752 | I21: =(I20-H20)/H20 -> -0.016961131 | J21: =(J20-I20)/I20 -> 0.39387598 | K21: =(K20-J20)/J20 -> 0.42386409 | L21: =(L20-K20)/K20 -> 0.49614296 | M21: =(M20-L20)/L20 -> 0.41451834 | N21: =(N20-M20)/M20 -> 0.41026381
B23: Launch & Development | F23: 1593 | G23: 1212 | H23: 1510 | I23: =H23*1.05 -> 1585.5 | J23: =J20*0.6 -> 2117.8341 | K23: =K20*0.6 -> 3015.5079 | L23: =L20*0.6 -> 4511.6309 | M23: =M20*0.6 -> 6381.7847 | N23: =N20*0.6 -> 9000
B24: % growth | G24: =(G23-F23)/F23 -> -0.23917137 | H24: =(H23-G23)/G23 -> 0.24587459 | I24: =(I23-H23)/H23 -> 0.05 | J24: =(J23-I23)/I23 -> 0.33575155 | K24: =(K23-J23)/J23 -> 0.42386409 | L24: =(L23-K23)/K23 -> 0.49614296 | M24: =(M23-L23)/L23 -> 0.41451834 | N24: =(N23-M23)/M23 -> 0.41026381
B26: Connectivity | F26: =F29+F32 -> 3869 | G26: =G29+G32 -> 7599 | H26: =H29+H32 -> 11387 | I26: =I29+I32 -> 15809.901 | J26: =J29+J32 -> 21782.147 | K26: =K29+K32 -> 29801.463 | L26: =L29+L32 -> 40668.225 | M26: =M29+M32 -> 53541.144 | N26: =N29+N32 -> 69057.463
B27: % growth | G27: =(G26-F26)/F26 -> 0.9640734 | H27: =(H26-G26)/G26 -> 0.49848664 | I27: =(I26-H26)/H26 -> 0.38841671 | J27: =(J26-I26)/I26 -> 0.37775354 | K27: =(K26-J26)/J26 -> 0.36816001 | L27: =(L26-K26)/K26 -> 0.36463855 | M27: =(M26-L26)/L26 -> 0.31653506 | N27: =(N26-M26)/M26 -> 0.28980178
B29: Consumer | F29: 2817 | G29: 4830 | H29: 7208 | I29: =H29*(1+((2148-1492)/1492)) -> 10377.201 | J29: =I29*(1+J30) -> 14448.002 | K29: =J29*(1+K30) -> 19533.66 | L29: =K29*(1+L30) -> 25779.911 | M29: =L29*(1+M30) -> 33441.92 | N29: =M29*(1+N30) -> 42928.471
B30: % growth | G30: =(G29-F29)/F29 -> 0.71458999 | H30: =(H29-G29)/G29 -> 0.49233954 | I30: =(I29-H29)/H29 -> 0.43967828 | J30: =I30+(I30-H30)*0.9 -> 0.39228315 | K30: =J30+(J30-I30)*0.85 -> 0.35199729 | L30: =K30+(K30-J30)*0.8 -> 0.31976859 | M30: =L30+(L30-K30)*0.7 -> 0.29720851 | N30: =M30+(M30-L30)*0.6 -> 0.28367246
B32: Enterprise & Government | F32: 1052 | G32: 2769 | H32: 4179 | I32: =H32*(1.3) -> 5432.7 | J32: =I32*1.35 -> 7334.145 | K32: =J32*1.4 -> 10267.803 | L32: =K32*1.45 -> 14888.314 | M32: =L32*1.35 -> 20099.224 | N32: =M32*1.3 -> 26128.992
B33: % growth | G33: =(G32-F32)/F32 -> 1.6321293 | H33: =(H32-G32)/G32 -> 0.5092091 | I33: =(I32-H32)/H32 -> 0.3 | J33: =(J32-I32)/I32 -> 0.35 | K33: =(K32-J32)/J32 -> 0.4 | L33: =(L32-K32)/K32 -> 0.45 | M33: =(M32-L32)/L32 -> 0.35 | N33: =(N32-M32)/M32 -> 0.3
B35: AI | F35: =F38+F41 -> 2961 | G35: =G38+G41 -> 2620 | H35: =H38+H41 -> 3201 | I35: =I38+I41 -> 11197.377 | J35: =J38+J41 -> 23358.135 | K35: =K38+K41 -> 40965.265 | L35: =L38+L41 -> 64734.892 | M35: =M38+M41 -> 91341.237 | N35: =N38+N41 -> 115298.56
B36: % growth | G36: =(G35-F35)/F35 -> -0.1151638 | H36: =(H35-G35)/G35 -> 0.22175573 | I36: =(I35-H35)/H35 -> 2.4980873 | J36: =(J35-I35)/I35 -> 1.0860362 | K36: =(K35-J35)/J35 -> 0.75379011 | L36: =(L35-K35)/K35 -> 0.58023856 | M36: =(M35-L35)/L35 -> 0.41100471 | N36: =(N35-M35)/M35 -> 0.26228374
B38: Advertising | F38: 2323 | G38: 1728 | H38: 1844 | I38: =H38*((1+(343-443)/443)) -> 1427.7472 | J38: =I38*1.05 -> 1499.1345 | K38: =J38*1.08 -> 1619.0653 | L38: =K38*1.1 -> 1780.9718 | M38: =L38*1.8 -> 3205.7493 | N38: =M38*1.6 -> 5129.1989
B39: % growth | G39: =(G38-F38)/F38 -> -0.25613431 | H39: =(H38-G38)/G38 -> 0.06712963 | I39: =(I38-H38)/H38 -> -0.22573363 | J39: =(J38-I38)/I38 -> 0.05 | K39: =(K38-J38)/J38 -> 0.08 | L39: =(L38-K38)/K38 -> 0.1 | M39: =(M38-L38)/L38 -> 0.8 | N39: =(N38-M38)/M38 -> 0.6
B41: AI Solutions & Infrastructure | F41: 638 | G41: 892 | H41: 1357 | I41: =H41*(1+(475-284)/284)+(1250*6) -> 9769.6303 | J41: =(2270*1.7)+(1500*12) -> 21859 | K41: =J41*1.8 -> 39346.2 | L41: =K41*1.6 -> 62953.92 | M41: =L41*1.4 -> 88135.488 | N41: =M41*1.25 -> 110169.36
B42: % growth | G42: =(G41-F41)/F41 -> 0.39811912 | H42: =(H41-G41)/G41 -> 0.52130045 | I42: =(I41-H41)/H41 -> 6.1994328 | J42: =(J41-I41)/I41 -> 1.2374439 | K42: =(K41-J41)/J41 -> 0.8 | L42: =(L41-K41)/K41 -> 0.6 | M42: =(M41-L41)/L41 -> 0.4 | N42: =(N41-M41)/M41 -> 0.25
A44: x | B44: Operating Income by Segment | F44: 2023 | G44: 2024 | H44: 2025 | I44: 2026E | J44: 2027E | K44: 2028E | L44: 2029E | M44: 2030E | N44: 2031E
B46: Operating Income | F46: =SUM(F49,F52,F55) -> -3505 | G46: =SUM(G49,G52,G55) -> 466 | H46: =SUM(H49,H52,H55) -> -2589 | I46: =SUM(I49,I52,I55) -> -10469
B47: % of sales | F47: =F46/F$14 -> -0.33744103 | G47: =G46/G$14 -> 0.033250089 | H47: =H46/H$14 -> -0.13864196 | I47: =I46/I$14 -> -0.33635248
B49: Space | F49: -1 | G49: 21 | H49: -657 | I49: =H49+4*(-662-(-70)) -> -3025
B50: % of sales | F50: =F49/F$14 -> -9.6274189e-05 | G50: =G49/G$14 -> 0.0014983946 | H50: =H49/H$14 -> -0.035182607 | I50: =I49/I$14 -> -0.097188484
B52: Connectivity | F52: 469 | G52: 2006 | H52: 4423 | I52: =H52+4*(1188-1033) -> 5043
B53: % of sales | F53: =F52/F$14 -> 0.045152595 | G53: =G52/G$14 -> 0.14313236 | H53: =H52/H$14 -> 0.23685338 | I53: =I52/I$14 -> 0.16202365
B55: AI | F55: -3973 | G55: -1561 | H55: -6355 | I55: =H55+4*(-2469-(-936)) -> -12487
B56: % of sales | F56: =F55/F$14 -> -0.38249735 | G56: =G55/G$14 -> -0.11138066 | H56: =H55/H$14 -> -0.34031273 | I56: =I55/I$14 -> -0.40118764
B58: EBITDA | F58: =SUM(F61,F64,F67) -> 2599 | G58: =SUM(G61,G64,G67) -> 5350 | H58: =SUM(H61,H64,H67) -> 6584 | I58: =SUM(I61,I64,I67) -> 4172
B59: % of sales | F59: =F58/F$14 -> 0.25021662 | G59: =G58/G$14 -> 0.38173386 | H59: =H58/H$14 -> 0.35257577 | I59: =I58/I$14 -> 0.13403979
B61: Space | F61: 997 | G61: 1154 | H61: 653 | I61: =H61+4*(-351-224) -> -1647
...
