Workbook

Sheet Main
R2: all values in millions except per share numbers
B4: Company Overview
B6: Price | G6: Key Stats | M6: Valuation | R6: Notes
B7: Ticker | E7: TEM | G7: Employees | I7: 2400 | M7: PV of FCF | R7: WACC
B8: Implied Share Price | G8: Founded | I8: 42217 | M8: Terminal Value | R8: EV/EBIT Multiple
B9: Current Share Price | E9: 70.33 | G9: CEO | I9: Eric Paul Lefkofsky | M9: PV of Terminal Value
B10: Implied Upside / (Downside) | G10: Headquarters | I10: Chicago, Illinois | M10: Net Debt | R10: WACC
G11: Primary Industry | I11: Healthcare Equipment | M11: Shares Outstanding | R11: Market Cap
B12: Last Updated | E12: 46041 | G12: Fiscal Year End | I12: 46004 | M12: Implied Market Cap | R12: % of Equity
R13: Cost of Equity
R14: Risk Free Rate
B15: Key Statistics | E15: 2024 | F15: =E15+1 -> 2025 | G15: 2026E | H15: 2027E | M15: Financial Ratios | R15: Beta
M16: PV of FCF | P16: =SUM(J97:N97) -> 0
B17: Stock Price | M17: Market Cap | R17: Market Risk Premium
B18: shares outstanding diluted | M18: Enterprise Value | R18: Debt
M19: P/E (LTM) | R19: % of Debt
B20: Market Cap | M20: P/E (NTM) | R20: Cost of Debt
B21: Cash | M21: P/S (LTM) | R21: Tax Rate
B22: Debt | M22: EV/EBITDA (LTM) | R22: Total
B23: Enterprise Value | R23: WACC
B25: Income Statement | E25: 2024 | F25: =E25+1 -> 2025 | G25: 2026E | H25: 2027E | I25: 2028E | J25: 2029E | K25: 2030E
B27: Revenue | E27: =Segments!E4 -> 693.349 | F27: =Segments!F4 -> 1265.242 | G27: =Segments!G4 -> 1576.964 | H27: =Segments!H4 -> 1964.67 | I27: =Segments!I4 -> 2399.72 | J27: =Segments!J4 -> 2952 | K27: =Segments!K4 -> 3531.3
B28: % growth | F28: =(F27-E27)/E27 -> 0.82482704 | G28: =(G27-F27)/F27 -> 0.24637342 | H28: =(H27-G27)/G27 -> 0.24585596 | I28: =(I27-H27)/H27 -> 0.22143668 | J28: =(J27-I27)/I27 -> 0.23014352 | K28: =(K27-J27)/J27 -> 0.19623984
B30: COGS | E30: 289.7 | F30: 470.956 | G30: 575.488 | H30: 697.51 | I30: 842.867 | J30: 1036.53 | K30: 1247.9
B31: % of sales | E31: =E30/E27 -> 0.4178271 | F31: =F30/F27 -> 0.37222602 | G31: =G30/G27 -> 0.36493414 | H31: =H30/H27 -> 0.35502654 | I31: =I30/I27 -> 0.35123556 | J31: =J30/J27 -> 0.35112805 | K31: =K30/K27 -> 0.35338261
B33: Gross Income | E33: =E27-E30 -> 403.649 | F33: =F27-F30 -> 794.286 | G33: =G27-G30 -> 1001.476 | H33: =H27-H30 -> 1267.16 | I33: =I27-I30 -> 1556.853 | J33: =J27-J30 -> 1915.47 | K33: =K27-K30 -> 2283.4
B34: % of sales | E34: =E33/E27 -> 0.5821729 | F34: =F33/F27 -> 0.62777398 | G34: =G33/G27 -> 0.63506586 | H34: =H33/H27 -> 0.64497346 | I34: =I33/I27 -> 0.64876444 | J34: =J33/J27 -> 0.64887195 | K34: =K33/K27 -> 0.64661739
B36: SG&A | E36: 755.4 | F36: 656.463 | G36: 729.924 | H36: 794.091 | I36: 905.267 | J36: 1056 | K36: 1257.7
B37: % of sales | E37: =E36/E$27 -> 1.0894946 | F37: =F36/F$27 -> 0.51884383 | G37: =G36/G$27 -> 0.46286662 | H37: =H36/H$27 -> 0.40418544 | I37: =I36/I$27 -> 0.37723859 | J37: =J36/J$27 -> 0.35772358 | K37: =K36/K$27 -> 0.35615779
B39: R&D | E39: 100.1 | F39: 163.921 | G39: 195.604 | H39: 221.24 | I39: 257.5 | J39: 289.25 | K39: 322.25
B40: % of sales | E40: =E39/E$27 -> 0.14437174 | F40: =F39/F$27 -> 0.12955703 | G40: =G39/G$27 -> 0.12403834 | H40: =H39/H$27 -> 0.11260924 | I40: =I39/I$27 -> 0.10730419 | J40: =J39/J$27 -> 0.097984417 | K40: =K39/K$27 -> 0.091255345
B42: EBIT | E42: =E33-E36-E39 -> -451.851 | F42: =F33-F36-F39 -> -26.098 | G42: =G33-G36-G39 -> 75.948 | H42: =H33-H36-H39 -> 251.829 | I42: =I33-I36-I39 -> 394.086 | J42: =J33-J36-J39 -> 570.22 | K42: =K33-K36-K39 -> 703.45
B43: % of sales | E43: =E42/E$27 -> -0.65169345 | F43: =F42/F$27 -> -0.020626884 | G43: =G42/G$27 -> 0.048160897 | H43: =H42/H$27 -> 0.12817878 | I43: =I42/I$27 -> 0.16422166 | J43: =J42/J$27 -> 0.19316396 | K43: =K42/K$27 -> 0.19920426
B45: Taxes | E45: 0.3 | F45: -45.6316 | G45: 0.070624 | H45: 1.52966 | I45: 12.1833 | J45: 17.3667 | K45: 0.55
B46: Tax rate | E46: =E45/E42 -> -0.00066393568 | F46: =F45/F42 -> 1.7484711 | G46: =G45/G42 -> 0.0009298994 | H46: =H45/H42 -> 0.0060742011 | I46: =I45/I42 -> 0.030915333 | J46: =J45/J42 -> 0.03045614 | K46: =K45/K42 -> 0.00078186083
B48: Cash Flow Items | E48: 2024 | F48: =E48+1 -> 2025 | G48: 2026E | H48: 2027E | I48: 2028E | J48: 2029E | K48: 2030E
B50: D&A | E50: 33.1 | F50: 72.1578 | G50: 79.188 | H50: 68.5031 | I50: 74.55 | J50: 95.0333 | K50: 96.45
B51: % of sales | E51: =E50/E27 -> 0.047739306 | F51: =F50/F27 -> 0.057030829 | G51: =G50/G27 -> 0.050215477 | H51: =H50/H27 -> 0.034867484 | I51: =I50/I27 -> 0.031066124 | J51: =J50/J27 -> 0.032192852 | K51: =K50/K27 -> 0.027312888
B52: % of capex | E52: =E50/E54 -> 1.5045455 | F52: =F50/F54 -> 3.1372957 | G52: =G50/G54 -> 1.9797 | H52: =H50/H54 -> 1.3980224 | I52: =I50/I54 -> 1.3554545 | J52: =J50/J54 -> 1.0329707 | K52: =K50/K54 -> 1.0152632
B54: CapEx | E54: 22 | F54: 23 | G54: 40 | H54: 49 | I54: 55 | J54: 92 | K54: 95
...

Sheet Segments
B2: Product Segments | E2: 2024 | F2: =E2+1 -> 2025 | G2: 2026E | H2: 2027E | I2: 2028E | J2: 2029E | K2: 2030E
B4: Sales | E4: =E7+E19 -> 693.349 | F4: =F7+F19 -> 1265.242 | G4: =G7+G19 -> 1576.964 | H4: =H7+H19 -> 1964.67 | I4: =I7+I19 -> 2399.72 | J4: =J7+J19 -> 2952 | K4: =K7+K19 -> 3531.3
B5: % growth | F5: =(F4-E4)/E4 -> 0.82482704 | G5: =(G4-F4)/F4 -> 0.24637342 | H5: =(H4-G4)/G4 -> 0.24585596 | I5: =(I4-H4)/H4 -> 0.22143668 | J5: =(J4-I4)/I4 -> 0.23014352 | K5: =(K4-J4)/J4 -> 0.19623984
B7: Genomics | E7: =E11+E15 -> 451.7 | F7: 950.092 | G7: 1171.12 | H7: 1444.57 | I7: 1758.62 | J7: 2176.75 | K7: 2585.6
B8: % growth | F8: =(F7-E7)/E7 -> 1.1033695 | G8: =(G7-F7)/F7 -> 0.23263852 | H8: =(H7-G7)/G7 -> 0.23349443 | I8: =(I7-H7)/H7 -> 0.21740033 | J8: =(J7-I7)/I7 -> 0.23776029 | K8: =(K7-J7)/J7 -> 0.18782589
B9: % of sales | E9: =E7/E4 -> 0.65147566 | F9: =F7/F4 -> 0.75091722 | G9: =G7/G4 -> 0.74264219 | H9: =H7/H4 -> 0.73527361 | I9: =I7/I4 -> 0.73284383 | J9: =J7/J4 -> 0.73738144 | K9: =K7/K4 -> 0.73219494
B11: - Clinical Oncology | E11: 403.1 | F11: 537.733 | G11: 681.567 | H11: 882.467 | I11: 1082.83 | J11: 1340 | K11: 1590.35
B12: % growth | F12: =(F11-E11)/E11 -> 0.33399405 | G12: =(G11-F11)/F11 -> 0.26748219 | H12: =(H11-G11)/G11 -> 0.29476192 | I12: =(I11-H11)/H11 -> 0.22704872 | J12: =(J11-I11)/I11 -> 0.23749804 | K12: =(K11-J11)/J11 -> 0.18682836
B13: % of sales | E13: =E11/E7 -> 0.89240646 | F13: =F11/F7 -> 0.56597993 | G13: =G11/G7 -> 0.58197879 | H13: =H11/H7 -> 0.61088559 | I13: =I11/I7 -> 0.6157271 | J13: =J11/J7 -> 0.61559665 | K13: =K11/K7 -> 0.61507967
B15: - Other Genomics | E15: 48.6 | F15: 44.925 | G15: 47.15 | H15: 50.35 | I15: 47.7 | J15: 47.1 | K15: 48.3
B16: % growth | F16: =(F15-E15)/E15 -> -0.075617284 | G16: =(G15-F15)/F15 -> 0.049526989 | H16: =(H15-G15)/G15 -> 0.067868505 | I16: =(I15-H15)/H15 -> -0.052631579 | J16: =(J15-I15)/I15 -> -0.012578616 | K16: =(K15-J15)/J15 -> 0.025477707
B17: % of sales | E17: =E15/E7 -> 0.10759354 | F17: =F15/F7 -> 0.047284895 | G17: =G15/G7 -> 0.040260605 | H17: =H15/H7 -> 0.034854663 | I17: =I15/I7 -> 0.02712354 | J17: =J15/J7 -> 0.021637763 | K17: =K15/K7 -> 0.018680384
B19: Data and Other | E19: 241.649 | F19: 315.15 | G19: 405.844 | H19: 520.1 | I19: 641.1 | J19: 775.25 | K19: 945.7
B20: % growth | F20: =(F19-E19)/E19 -> 0.3041643 | G20: =(G19-F19)/F19 -> 0.28778042 | H20: =(H19-G19)/G19 -> 0.28152689 | I20: =(I19-H19)/H19 -> 0.23264757 | J20: =(J19-I19)/I19 -> 0.20924973 | K20: =(K19-J19)/J19 -> 0.21986456
B24: Income by Segment | E24: 2024 | F24: =E24+1 -> 2025 | G24: 2026E | H24: 2027E | I24: 2028E | J24: 2029E | K24: 2030E
B26: Gross Income | E26: 404 | F26: 795.623 | G26: 1003.52 | H26: 1248.92 | I26: 1536.18 | J26: 1837.1 | K26: 2297.5
B27: % of sales | E27: =E26/E7 -> 0.89439894 | F27: =F26/F7 -> 0.8374168 | G27: =G26/G7 -> 0.85688913 | H27: =H26/H7 -> 0.86456177 | I27: =I26/I7 -> 0.87351446 | J27: =J26/J7 -> 0.84396463 | K27: =K26/K7 -> 0.88857519
B29: - Genomics | E29: 222.4 | F29: 562.2 | G29: 659.6
B30: % of sales | E30: =E29/E7 -> 0.49236219 | F30: =F29/F7 -> 0.59173217 | G30: =G29/G7 -> 0.56322153
B32: - Data and Other | E32: 181.7 | F32: 233 | G32: 315
B33: % of sales | E33: =E32/E19 -> 0.75191704 | F33: =F32/F19 -> 0.73933048 | G33: =G32/G19 -> 0.7761603
B35: Cost of Sales | E35: 289.7 | F35: 470.956 | G35: 575.488 | H35: 697.51 | I35: 842.867 | J35: 1036.53 | K35: 1247.9
B36: % of sales | E36: =E35/E4 -> 0.4178271 | F36: =F35/F4 -> 0.37222602 | G36: =G35/G4 -> 0.36493414 | H36: =H35/H4 -> 0.35502654 | I36: =I35/I4 -> 0.35123556 | J36: =J35/J4 -> 0.35112805 | K36: =K35/K4 -> 0.35338261
B38: Genomics | E38: 229.8 | F38: 389.087 | G38: 472.799 | H38: 564.66 | I38: 685.067 | J38: 876 | K38: 1062.3
B39: % of sales | E39: =E38/E19 -> 0.95096607 | F39: =F38/F7 -> 0.4095256 | G39: =G38/G19 -> 1.1649772 | H39: =H38/H19 -> 1.0856758 | I39: =I38/I19 -> 1.0685806 | J39: =J38/J19 -> 1.1299581 | K39: =K38/K19 -> 1.1232949
B41: - Clinical Oncology | E41: - | F41: 278.1 | G41: 352.4 | H41: 450.6 | I41: 572.4 | J41: 712.9 | K41: 881
B42: % of sales | F42: =F41/F11 -> 0.51717116 | G42: =G41/G11 -> 0.51704381 | H42: =H41/H11 -> 0.51061399 | I42: =I41/I11 -> 0.52861483 | J42: =J41/J11 -> 0.53201493 | K42: =K41/K11 -> 0.55396611
B44: - Other Genomics | E44: - | F44: 19.6 | G44: 18.4 | H44: 18.4 | I44: 18.4 | J44: 18.4 | K44: 18.4
B45: % of sales | F45: =F44/F15 -> 0.43628269 | G45: =G44/G15 -> 0.3902439 | H45: =H44/H15 -> 0.36544191 | I45: =I44/I15 -> 0.38574423 | J45: =J44/J15 -> 0.39065817 | K45: =K44/K15 -> 0.38095238
B47: Data and Other | E47: 60.3 | F47: 84.7766 | G47: 110.091 | H47: 136.68 | I47: 165.1 | J47: 200.7 | K47: 242.2
B48: % of sales | E48: =E47/E19 -> 0.24953548 | F48: =F47/F19 -> 0.26900397 | G48: =G47/G19 -> 0.27126433 | H48: =H47/H19 -> 0.26279562 | I48: =I47/I19 -> 0.25752613 | J48: =J47/J19 -> 0.25888423 | K48: =K47/K19 -> 0.25610659

Sheet Extras
B2: Eric Paul Lefkofsky (CEO) Previous Ventures
B3: Company Name | D3: Ticker | E3: Outcome | H3: Controversies
B5: InnerWorkings | D5: INWK | E5: IPO in 2006, delisted in 2021 | H5: Faced financial restatement and disclosed "material weakness" in internal controls shortly after Lefkofsky left.
B8: Echo Global Logistics | D8: ECHO | E8: IPO in 2009, taken private in 2021 | H8: One of his more stable ventures, lackluster long-term returns for retail investors.
B11: Groupon | D11: GRPN | E11: $12.7B IPO in 2011, Stock crashed over 95% | H11: Criticized for "fuzzy math" (using a metric called Adjusted Consolidated Segment Operating Income) and investigated by the SEC for accounting irregularities
B16: Other Notes
B18: History of cashing out early. Him and his family cashed out roughly $398 million through private share sales in Groupon before the crash
B22: Tempus AI Controversies
B24: "AI-Washing" Allegations: In mid-2025, a short-seller report from Spruce Point Capital alleged that Tempus overstates its AI capabilities, generating most of its revenue from traditional genomic testing and data licensing rather than actual AI solutions.
B28: Securities Class Action: A lawsuit was filed in June 2025 alleging that Tempus misled investors by inflating contract values and failing to disclose that many agreements were with "related parties" or were non-binding.
